Workbook
Name \0: #REF!
Name \0: #REF!
Name \0: #REF!
Name \A: #REF!
Name \A: #REF!
Name \A: #REF!
Name \b: #REF!
Name \b: #REF!
Name \b: #REF!
Name \c: #REF!
Name \c: #REF!
Name \c: #REF!
Name \F: #REF!
Name \F: #REF!
Name \G: #REF!
Name \G: #REF!
Name \h: #REF!
Name \h: #REF!
Name \L: #REF!
Name \L: #REF!
Name \n: #REF!
Name \n: #REF!
Name \O: #REF!
Name \O: #REF!
Name \P: #REF!
Name \P: #REF!
Name \Q: #REF!
Name \Q: #REF!
Name \R: #REF!
Name \R: #REF!
Name \s: #REF!
Name \s: #REF!
Name \t: #REF!
Name \t: #REF!
Name \V: #REF!
Name \V: #REF!
Name \w: #REF!
Name \w: #REF!
Name \x: #N/A
Name \y: #REF!
Name \y: #REF!
Name \z: #N/A
Name _________________________________mm1: #REF!
Name _________________________________mm1: QQP!_________________________________mm1
Name _________________________________mm1: #REF!
Name ________________________________mm1: #REF!
Name ________________________________mm1: QQP!________________________________mm1
Name ________________________________mm1: #REF!
Name _______________________________mm1: #REF!
Name _______________________________mm1: QQP!_______________________________mm1
Name _______________________________mm1: #REF!
Name ______________________________mm1: #REF!
Name ______________________________mm1: QQP!______________________________mm1
Name ______________________________mm1: #REF!
Name _____________________________mm1: #REF!
Name _____________________________mm1: QQP!_____________________________mm1
Name _____________________________mm1: #REF!
Name ____________________________mm1: #REF!
Name ____________________________mm1: QQP!____________________________mm1
Name ____________________________mm1: #REF!

Sheet APR
C1: ANÁLISE DE RISCO | R1: PRO-009-25
R2: DATA: | S2: 45701
B4: 1ª ETAPA - ANÁLISE PRELIMINAR DE RISCO
B5: Nome do Contrato: | C5: CSS00206 - RDC 4598275 - CONTRATAÇÃO DE SERVIÇO PARA MONTAGEM E SERVIÇOS ELETROMECÂNICOS - SUBSTITUIÇÃO DA TALHA ELÉTRICA 161-TL-01 | M5: Dono do Risco: | O5: WELLINGTON DE SOUZA | Q5: Cliente: | R5: ALUMAR
B6: Missão do Contrato: | C6: CSS00206 - RDC 4598275 - CONTRATAÇÃO DE SERVIÇO PARA MONTAGEM E SERVIÇOS ELETROMECÂNICOS - SUBSTITUIÇÃO DA TALHA ELÉTRICA 161-TL-01 | M6: Prazo (dias): | N6: 0 | O6: Prazo pgto (dd): | P6: 0 | Q6: Local: | R6: SÃO LUÍS (MA)
B7: ESTIMATIVA FINANCEIRAS
B8: Valor Estimado | C8: =R8*T8 -> 733060.98 | D8: Nr. De Pessoas | F8: Custo M.obra | G8: =CHECK!I126 -> 224123.35 | I8: Custo Equipam. | J8: =CHECK!I127 -> 197996.86 | M8: Custo Consumiveis | N8: =CHECK!I128 -> 25222.816 | O8: Outros | P8: =CHECK!I129 -> 47224.356 | Q8: Custo Total | R8: =G8+J8+N8+P8 -> 494567.39 | S8: K | T8: =CHECK!I151 -> 1.4822267
B9: OBSERVAÇÕES
B10: 1 - A OBRA OCORRERÁ NA ÁREA DO PRÉDIO 161Z 2 - O ESCOPO SERÁ IMPRETERIVELMENTE A TROCA DA TALHA ELÉTRICA, COM AQUISIÇÃO DE CABOS E ACESSÓRIOS 3 - A MOBILIZAÇÃO OCORRERÁ COM A EQUIPE COMPOSTA POR ENGENHEIRO ELETRICISTA, ELETRICISTA DE FORÇA E CONTROLE E AUXILIAR.
B12: 2ª ETAPA - ANÁLISE DE RISCO
B14: Riscos a Verificar
C17: Criterio de Avaliação do Nivel do Risco | AF17: Nota | AG17: Probabilidade | AH17: NR | AI17: NR
C18: Probabilidade do Risco Acontecer | E18: NR | G18: Nota | AF18: 1 | AG18: QUASE CERTO | AH18: Risco Alto | AI18: Alto | AK18: GRÁFICO | AQ18: VERMELHO | AT18: AMARELO | AW18: VERDE
C19: QUASE CERTO | E19: Alto | G19: 1 a 2,5 | AF19: 2 | AG19: QUASE CERTO | AH19: Risco Alto | AI19: Alto | AK19: =B26 -> Tipo de Riscos | AL19: Nivel | AM19: Vermelho | AN19: Amarelo | AO19: Verde | AQ19: =AK19 -> Tipo de Riscos | AR19: =" " | AT19: =AK19 -> Tipo de Riscos | AU19: =" " | AW19: =AK19 -> Tipo de Riscos | AX19: =" "
C20: MUITO PROVÁVEL | E20: Alto | G20: 2,6 a 4,9 | AF20: 2.5 | AG20: QUASE CERTO | AH20: Risco Alto | AI20: Alto | AJ20: 1 | AK20: =B27 -> 1-FINANCEIRO (Fluxo de caixa) | AL20: =F27 -> 8.6 | AM20: =IF(AL20<=4.9,AL20,"") | AN20: =IF(AND(AL20>4.9,AL20<=8.5),AL20,"") | AO20: =IF(AL20>=8.6,AL20,"") -> 8.6 | AQ20: =AK20 -> 1-FINANCEIRO (Fluxo de caixa) | AR20: =AM20 | AT20: =AK20 -> 1-FINANCEIRO (Fluxo de caixa) | AU20: =AN20 | AW20: =AK20 -> 1-FINANCEIRO (Fluxo de caixa) | AX20: =AO20 -> 8.6
C21: PROVÁVEL | E21: Médio | G21: 5 a 7,4 | AF21: 2.6 | AG21: MUITO PROVÁVEL | AH21: Risco Alto | AI21: Alto | AJ21: 2 | AK21: =B29 -> 2-CALOTE (SERASA) | AL21: =F29 -> 8.6 | AM21: =IF(AL21<=4.9,AL21,"") | AN21: =IF(AND(AL21>4.9,AL21<=8.5),AL21,"") | AO21: =IF(AL21>=8.6,AL21,"") -> 8.6 | AQ21: =AK21 -> 2-CALOTE (SERASA) | AR21: =AM21 | AT21: =AK21 -> 2-CALOTE (SERASA) | AU21: =AN21 | AW21: =AK21 -> 2-CALOTE (SERASA) | AX21: =AO21 -> 8.6
C22: POUCO PROVÁVEL | E22: Médio | G22: 7,5 a 8,5 | AF22: 3 | AG22: MUITO PROVÁVEL | AH22: Risco Alto | AI22: Alto | AJ22: 3 | AK22: =B31 -> 3-NIVEL DE COMPLEXIDADE | AL22: =F31 -> 7 | AM22: =IF(AL22<=4.9,AL22,"") | AN22: =IF(AND(AL22>4.9,AL22<=8.5),AL22,"") -> 7 | AO22: =IF(AL22>=8.6,AL22,"") | AQ22: =AK22 -> 3-NIVEL DE COMPLEXIDADE | AR22: =AM22 | AT22: =AK22 -> 3-NIVEL DE COMPLEXIDADE | AU22: =AN22 -> 7 | AW22: =AK22 -> 3-NIVEL DE COMPLEXIDADE | AX22: =AO22
C23: IMPROVÁVEL | E23: Baixo | G23: 8,6 a 9,3 | AF23: 4 | AG23: MUITO PROVÁVEL | AH23: Risco Alto | AI23: Alto | AJ23: 4 | AK23: =B33 -> 4-CAPACIDADE TÉCNICA | AL23: =F33 -> 7 | AM23: =IF(AL23<=4.9,AL23,"") | AN23: =IF(AND(AL23>4.9,AL23<=8.5),AL23,"") -> 7 | AO23: =IF(AL23>=8.6,AL23,"") | AQ23: =AK23 -> 4-CAPACIDADE TÉCNICA | AR23: =AM23 | AT23: =AK23 -> 4-CAPACIDADE TÉCNICA | AU23: =AN23 -> 7 | AW23: =AK23 -> 4-CAPACIDADE TÉCNICA | AX23: =AO23
C24: RARO | E24: Baixo | G24: 9,4 a 10 | AF24: 4.9 | AG24: MUITO PROVÁVEL | AH24: Risco Alto | AI24: Alto | AJ24: 5 | AK24: =B35 -> 5-SSMA | AL24: =F35 -> 8.9 | AM24: =IF(AL24<=4.9,AL24,"") | AN24: =IF(AND(AL24>4.9,AL24<=8.5),AL24,"") | AO24: =IF(AL24>=8.6,AL24,"") -> 8.9 | AQ24: =AK24 -> 5-SSMA | AR24: =AM24 | AT24: =AK24 -> 5-SSMA | AU24: =AN24 | AW24: =AK24 -> 5-SSMA | AX24: =AO24 -> 8.9
B25: Quanto maior a probabilidade do risco, menor a Nota atribuída e vice versa. | AF25: 5 | AG25: PROVÁVEL | AH25: Risco Médio | AI25: Médio | AJ25: 6 | AK25: =B37 -> 6-RISCO DE NÃO ACONTECER | AL25: =F37 -> 8.6 | AM25: =IF(AL25<=4.9,AL25,"") | AN25: =IF(AND(AL25>4.9,AL25<=8.5),AL25,"") | AO25: =IF(AL25>=8.6,AL25,"") -> 8.6 | AQ25: =AK25 -> 6-RISCO DE NÃO ACONTECER | AR25: =AM25 | AT25: =AK25 -> 6-RISCO DE NÃO ACONTECER | AU25: =AN25 | AW25: =AK25 -> 6-RISCO DE NÃO ACONTECER | AX25: =AO25 -> 8.6
B26: Tipo de Riscos | D26: Peso da Consequencia | E26: Nivel de Risco | I26: Yeld | AF26: 6 | AG26: PROVÁVEL | AH26: Risco Médio | AI26: Médio | AJ26: 7 | AK26: =B39 -> 7-DISPONIBILIDADE DE RECURSOS (Mercado) | AL26: =F39 -> 8.9 | AM26: =IF(AL26<=4.9,AL26,"") | AN26: =IF(AND(AL26>4.9,AL26<=8.5),AL26,"") | AO26: =IF(AL26>=8.6,AL26,"") -> 8.9 | AQ26: =AK26 -> 7-DISPONIBILIDADE DE RECURSOS (Mercado) | AR26: =AM26 | AT26: =AK26 -> 7-DISPONIBILIDADE DE RECURSOS (Mercado) | AU26: =AN26 | AW26: =AK26 -> 7-DISPONIBILIDADE DE RECURSOS (Mercado) | AX26: =AO26 -> 8.9
B27: 1-FINANCEIRO (Fluxo de caixa) | D27: 2.5 | F27: 8.6 | H27: =VLOOKUP(F27,$AF$18:$AI$36,3,TRUE) -> Risco Baixo | M27: Observações gerais a serem contempladas na APR | AF27: 7 | AG27: PROVÁVEL | AH27: Risco Médio | AI27: Médio | AJ27: 8 | AK27: =B41 -> 8-COMPETITIVIDADE (Concorrentes) | AL27: =F41 -> 9 | AM27: =IF(AL27<=4.9,AL27,"") | AN27: =IF(AND(AL27>4.9,AL27<=8.5),AL27,"") | AO27: =IF(AL27>=8.6,AL27,"") -> 9 | AQ27: =AK27 -> 8-COMPETITIVIDADE (Concorrentes) | AR27: =AM27 | AT27: =AK27 -> 8-COMPETITIVIDADE (Concorrentes) | AU27: =AN27 | AW27: =AK27 -> 8-COMPETITIVIDADE (Concorrentes) | AX27: =AO27 -> 9
AF28: 7.4 | AG28: PROVÁVEL | AH28: Risco Médio | AI28: Médio | AJ28: 9 | AK28: =B43 -> 9-HH PARADO/EQUIPAMENTO | AL28: =F43 -> 8.4 | AM28: =IF(AL28<=4.9,AL28,"") | AN28: =IF(AND(AL28>4.9,AL28<=8.5),AL28,"") -> 8.4 | AO28: =IF(AL28>=8.6,AL28,"") | AQ28: =AK28 -> 9-HH PARADO/EQUIPAMENTO | AR28: =AM28 | AT28: =AK28 -> 9-HH PARADO/EQUIPAMENTO | AU28: =AN28 -> 8.4 | AW28: =AK28 -> 9-HH PARADO/EQUIPAMENTO | AX28: =AO28
B29: 2-CALOTE (SERASA) | D29: 2 | F29: 8.6 | H29: =VLOOKUP(F29,$AF$18:$AI$36,3,TRUE) -> Risco Baixo | I29: =ROUND((D27*F27+D29*F29+D31*F31+D33*F33+D35*F35+D37*F37+D41*F41+D43*F43+D45*F45+D47*F47+D39*F39+D51*F51+D53*F53+D49*F49)/D56,1) -> 8.3 | AF29: 7.5 | AG29: POUCO PROVÁVEL | AH29: Risco Médio | AI29: Médio | AJ29: 10 | AK29: =B45 -> 10-LOGISTICA | AL29: =F45 -> 7 | AM29: =IF(AL29<=4.9,AL29,"") | AN29: =IF(AND(AL29>4.9,AL29<=8.5),AL29,"") -> 7 | AO29: =IF(AL29>=8.6,AL29,"") | AQ29: =AK29 -> 10-LOGISTICA | AR29: =AM29 | AT29: =AK29 -> 10-LOGISTICA | AU29: =AN29 -> 7 | AW29: =AK29 -> 10-LOGISTICA | AX29: =AO29
AF30: 8 | AG30: POUCO PROVÁVEL | AH30: Risco Médio | AI30: Médio | AJ30: 11 | AK30: =B47 -> 11-NOTIFICAÇÕES E MULTAS | AL30: =F47 -> 8 | AM30: =IF(AL30<=4.9,AL30,"") | AN30: =IF(AND(AL30>4.9,AL30<=8.5),AL30,"") -> 8 | AO30: =IF(AL30>=8.6,AL30,"") | AQ30: =AK30 -> 11-NOTIFICAÇÕES E MULTAS | AR30: =AM30 | AT30: =AK30 -> 11-NOTIFICAÇÕES E MULTAS | AU30: =AN30 -> 8 | AW30: =AK30 -> 11-NOTIFICAÇÕES E MULTAS | AX30: =AO30
B31: 3-NIVEL DE COMPLEXIDADE | D31: 0.5 | F31: 7 | H31: =VLOOKUP(F31,$AF$18:$AI$36,3,TRUE) -> Risco Médio | AF31: 8.5 | AG31: POUCO PROVÁVEL | AH31: Risco Médio | AI31: Médio | AJ31: 12 | AK31: =B49 -> 12-PRAZO DE ELABORAÇÃO PROPOSTA | AL31: =F49 -> 8 | AM31: =IF(AL31<=4.9,AL31,"") | AN31: =IF(AND(AL31>4.9,AL31<=8.5),AL31,"") -> 8 | AO31: =IF(AL31>=8.6,AL31,"") | AQ31: =AK31 -> 12-PRAZO DE ELABORAÇÃO PROPOSTA | AR31: =AM31 | AT31: =AK31 -> 12-PRAZO DE ELABORAÇÃO PROPOSTA | AU31: =AN31 -> 8 | AW31: =AK31 -> 12-PRAZO DE ELABORAÇÃO PROPOSTA | AX31: =AO31
AF32: 8.6 | AG32: IMPROVÁVEL | AH32: Risco Baixo | AI32: Baixo | AJ32: 13 | AK32: =B51 -> 13-PRAZO DE EXECUÇÃO | AL32: =F51 -> 8.6 | AM32: =IF(AL32<=4.9,AL32,"") | AN32: =IF(AND(AL32>4.9,AL32<=8.5),AL32,"") | AO32: =IF(AL32>=8.6,AL32,"") -> 8.6 | AQ32: =AK32 -> 13-PRAZO DE EXECUÇÃO | AR32: =AM32 | AT32: =AK32 -> 13-PRAZO DE EXECUÇÃO | AU32: =AN32 | AW32: =AK32 -> 13-PRAZO DE EXECUÇÃO | AX32: =AO32 -> 8.6
B33: 4-CAPACIDADE TÉCNICA | D33: 0.5 | F33: 7 | H33: =VLOOKUP(F33,$AF$18:$AI$36,3,TRUE) -> Risco Médio | AF33: 9 | AG33: IMPROVÁVEL | AH33: Risco Baixo | AI33: Baixo | AJ33: 14 | AK33: =B53 -> 14-LEILÃO | AL33: =F53 -> 8.6 | AM33: =IF(AL33<=4.9,AL33,"") | AN33: =IF(AND(AL33>4.9,AL33<=8.5),AL33,"") | AO33: =IF(AL33>=8.6,AL33,"") -> 8.6 | AQ33: =AK33 -> 14-LEILÃO | AR33: =AM33 | AT33: =AK33 -> 14-LEILÃO | AU33: =AN33 | AW33: =AK33 -> 14-LEILÃO | AX33: =AO33 -> 8.6
AF34: 9.3 | AG34: IMPROVÁVEL | AH34: Risco Baixo | AI34: Baixo
B35: 5-SSMA | D35: 0.5 | F35: 8.9 | H35: =VLOOKUP(F35,$AF$18:$AI$36,3,TRUE) -> Risco Baixo | AF35: 9.4 | AG35: RARO | AH35: Risco Baixo | AI35: Baixo
AF36: 10 | AG36: RARO | AH36: Risco Baixo | AI36: Baixo
B37: 6-RISCO DE NÃO ACONTECER | D37: 0.3 | F37: 8.6 | H37: =VLOOKUP(F37,$AF$18:$AI$36,3,TRUE) -> Risco Baixo
B39: 7-DISPONIBILIDADE DE RECURSOS (Mercado) | D39: 0.5 | F39: 8.9 | H39: =VLOOKUP(F39,$AF$18:$AI$36,3,TRUE) -> Risco Baixo
B41: 8-COMPETITIVIDADE (Concorrentes) | D41: 0.5 | F41: 9 | H41: =VLOOKUP(F41,$AF$18:$AI$36,3,TRUE) -> Risco Baixo | I41: Nível de Risco:
B43: 9-HH PARADO/EQUIPAMENTO | D43: 0.5 | F43: 8.4 | H43: =VLOOKUP(F43,$AF$18:$AI$36,3,TRUE) -> Risco Médio | I43: =VLOOKUP(I29,AF18:AI36,4,TRUE) -> Médio
B45: 10-LOGISTICA | D45: 0.5 | F45: 7 | H45: =VLOOKUP(F45,$AF$18:$AI$36,3,TRUE) -> Risco Médio
B47: 11-NOTIFICAÇÕES E MULTAS | D47: 0.5 | F47: 8 | H47: =VLOOKUP(F47,$AF$18:$AI$36,3,TRUE) -> Risco Médio
B49: 12-PRAZO DE ELABORAÇÃO PROPOSTA | D49: 0.5 | F49: 8 | H49: =VLOOKUP(F49,$AF$18:$AI$36,3,TRUE) -> Risco Médio
B51: 13-PRAZO DE EXECUÇÃO | D51: 0.5 | F51: 8.6 | H51: =VLOOKUP(F51,$AF$18:$AI$36,3,TRUE) -> Risco Baixo
B53: 14-LEILÃO | D53: 0.2 | F53: 8.6 | H53: =VLOOKUP(F53,$AF$18:$AI$36,3,TRUE) -> Risco Baixo
...

Sheet CHECK
B1: =QQP!G55 -> 733060.91
G2: CHECK
B5: A - Mão de Obra + Encargos
B6: Cód. | C6: Discriminação | D6: Unid | E6: P.Unit | G6: Quant | H6: F.utiliz | I6: Custo
B7: ='CPU 1 '!B7 -> P01 | C7: ='CPU 1 '!C7 -> Técnico SSMA | D7: ='CPU 1 '!D7 -> hh | E7: ='CPU 1 '!E7 -> 30.027273 | I7: ='CPU 1 '!DS7 -> 17472.87 | J7: =I7/$I$130 -> 0.035329604
B8: ='CPU 1 '!B8 -> P02 | C8: ='CPU 1 '!C8 -> Eletricista de força e controle | D8: ='CPU 1 '!D8 -> hh | E8: ='CPU 1 '!E8 -> 35.63937 | I8: ='CPU 1 '!DS8 -> 17459.727 | J8: =I8/$I$130 -> 0.03530303
B9: ='CPU 1 '!B9 -> P03 | C9: ='CPU 1 '!C9 -> Ajudante de elétrica | D9: ='CPU 1 '!D9 -> hh | E9: ='CPU 1 '!E9 -> 21.211866 | I9: ='CPU 1 '!DS9 -> 15482.541 | J9: =I9/$I$130 -> 0.03130522
B10: ='CPU 1 '!B10 -> P04 | C10: ='CPU 1 '!C10 -> Engenheiro eletricista | D10: ='CPU 1 '!D10 -> hh | E10: ='CPU 1 '!E10 -> 122.13093 | I10: ='CPU 1 '!DS10 -> 36706.45 | J10: =I10/$I$130 -> 0.07421931
B11: ='CPU 1 '!B11 -> P05 | C11: ='CPU 1 '!C11 -> Engenheiro mecânico - Especialista em estruturas metálicas | D11: ='CPU 1 '!D11 -> hh | E11: ='CPU 1 '!E11 -> 122.13093 | I11: ='CPU 1 '!DS11 -> 19803.53 | J11: =I11/$I$130 -> 0.040042126
B12: ='CPU 1 '!B12 -> P06 | C12: ='CPU 1 '!C12 -> Projetista (Cadista) | D12: ='CPU 1 '!D12 -> hh | E12: ='CPU 1 '!E12 -> 28.525909 | I12: ='CPU 1 '!DS12 -> 5253.0462 | J12: =I12/$I$130 -> 0.010621497
B13: ='CPU 1 '!B13 -> P07 | C13: ='CPU 1 '!C13 -> Alpinista industrial (Montador de andaime) | D13: ='CPU 1 '!D13 -> hh | E13: ='CPU 1 '!E13 -> 34.667187 | I13: ='CPU 1 '!DS13 -> 13728.206 | J13: =I13/$I$130 -> 0.027758009
B14: ='CPU 1 '!B14 -> P08 | C14: ='CPU 1 '!C14 -> Encarregado de elétrica ou andaimes | D14: ='CPU 1 '!D14 -> hh | E14: ='CPU 1 '!E14 -> 42.538636 | I14: ='CPU 1 '!DS14 -> 24189.17 | J14: =I14/$I$130 -> 0.048909756
B15: ='CPU 1 '!B15 -> P09 | C15: ='CPU 1 '!C15 -> Montador de estruturas metálicas | D15: ='CPU 1 '!D15 -> hh | E15: ='CPU 1 '!E15 -> 30.14538 | I15: ='CPU 1 '!DS15 -> 11937.57 | J15: =I15/$I$130 -> 0.024137399
B16: ='CPU 1 '!B16 -> P10 | C16: ='CPU 1 '!C16 -> Topógrafo | D16: ='CPU 1 '!D16 -> hh | E16: ='CPU 1 '!E16 -> 31.028182 | I16: ='CPU 1 '!DS16 -> 4468.0582 | J16: =I16/$I$130 -> 0.0090342758
B17: ='CPU 1 '!B17 -> P11 | C17: ='CPU 1 '!C17 -> Auxiliar de topografia | D17: ='CPU 1 '!D17 -> hh | E17: ='CPU 1 '!E17 -> 16.515 | I17: ='CPU 1 '!DS17 -> 2378.16 | J17: =I17/$I$130 -> 0.0048085662
B18: ='CPU 1 '!B18 -> P12 | C18: ='CPU 1 '!C18 -> Sinaleiro de rigger | D18: ='CPU 1 '!D18 -> hh | E18: ='CPU 1 '!E18 -> 21.88788 | I18: ='CPU 1 '!DS18 -> 10418.631 | J18: =I18/$I$130 -> 0.02106615
... B20: ='CPU 1 '!B20 -> P14 | C20: ='CPU 1 '!C20 -> Supervisor de obras | D20: ='CPU 1 '!D20 -> hh | E20: ='CPU 1 '!E20 -> 52.047273 | I20: ='CPU 1 '!DS20 -> 29596.161 | J20: =I20/$I$130 -> 0.059842525
B21: A - Custo Total de Mão de Obra: | G21: =SUM(G7:G12) -> 0 | H21: =SUM(H7:H12) -> 0 | I21: =SUM(I7:I20) -> 224123.35
B22: B – Equipamentos e Ferramentas
B23: Cód. | C23: Discriminação | D23: Unid | E23: P.Unit | G23: Quant | H23: F.utiliz | I23: Custo
B24: ='CPU 1 '!B24 -> E01 | C24: ='CPU 1 '!C24 -> Conteiner escritório | D24: ='CPU 1 '!D24 -> Vb/mês | E24: ='CPU 1 '!E24 -> 1700 | I24: ='CPU 1 '!DS24 -> 2240.9091 | J24: =I24/$I$130 -> 0.0045310491
B25: ='CPU 1 '!B25 -> E02 | C25: ='CPU 1 '!C25 -> Banheiro químico | D25: ='CPU 1 '!D25 -> Vb/mês | E25: ='CPU 1 '!E25 -> 1200 | I25: ='CPU 1 '!DS25 -> 1581.8182 | J25: =I25/$I$130 -> 0.0031983876
B26: ='CPU 1 '!B26 -> E03 | C26: ='CPU 1 '!C26 -> Tenda lonada 6 x 6 m, piramidal - AQUISIÇÃO | D26: ='CPU 1 '!D26 -> Vb | E26: ='CPU 1 '!E26 -> 4500 | I26: ='CPU 1 '!DS26 -> 4500 | J26: =I26/$I$130 -> 0.0090988612
B27: ='CPU 1 '!B27 -> E04 | C27: ='CPU 1 '!C27 -> Mobiliário (Cadeiras e mesas plásticas) | D27: ='CPU 1 '!D27 -> Vb | E27: ='CPU 1 '!E27 -> 852.46 | I27: ='CPU 1 '!DS27 -> 852.46 | J27: =I27/$I$130 -> 0.0017236478
B28: ='CPU 1 '!B28 -> E05 | C28: ='CPU 1 '!C28 -> Veículo de Locação - Fiat Ducato Minibus Luxo 2025 - 16 lugares | D28: ='CPU 1 '!D28 -> Vb/mês | E28: ='CPU 1 '!E28 -> 15852.96 | I28: ='CPU 1 '!DS28 -> 16985.541 | J28: =I28/$I$130 -> 0.03434424
B29: ='CPU 1 '!B29 -> E06 | C29: ='CPU 1 '!C29 -> Nível DSZ automático com bolha | D29: ='CPU 1 '!D29 -> Vb/Mês | E29: ='CPU 1 '!E29 -> 275 | I29: ='CPU 1 '!DS29 -> 125 | J29: =I29/$I$130 -> 0.00025274614
B30: ='CPU 1 '!B30 -> E07 | C30: ='CPU 1 '!C30 -> Estação total Kit GD2i-8 | D30: ='CPU 1 '!D30 -> Vb/Mês | E30: ='CPU 1 '!E30 -> 1250 | I30: ='CPU 1 '!DS30 -> 568.18182 | J30: =I30/$I$130 -> 0.0011488461
B31: ='CPU 1 '!B31 -> E08 | C31: ='CPU 1 '!C31 -> Receptor GNSS RTKCHC i50 | D31: ='CPU 1 '!D31 -> Vb/Mês | E31: ='CPU 1 '!E31 -> 1750 | I31: ='CPU 1 '!DS31 -> 795.45455 | J31: =I31/$I$130 -> 0.0016083846
B32: ='CPU 1 '!B32 -> E09 | C32: ='CPU 1 '!C32 -> Guindaste c/operador 30 ton | D32: ='CPU 1 '!D32 -> Diária | E32: ='CPU 1 '!E32 -> 7852.5 | I32: ='CPU 1 '!DS32 -> 117787.5 | J32: =I32/$I$130 -> 0.23816269
B33: ='CPU 1 '!B33 -> E10 | C33: ='CPU 1 '!C33 -> Plano de rigging | D33: ='CPU 1 '!D33 -> Vb | E33: ='CPU 1 '!E33 -> 15000 | I33: ='CPU 1 '!DS33 -> 45000 | J33: =I33/$I$130 -> 0.090988612
B34: ='CPU 1 '!B34 -> E11 | C34: ='CPU 1 '!C34 -> Linha de vida | D34: ='CPU 1 '!D34 -> Vb | E34: ='CPU 1 '!E34 -> 2520 | I34: ='CPU 1 '!DS34 -> 7560 | J34: =I34/$I$130 -> 0.015286087
B35: ='CPU 1 '!B35 -> E12 | C35: ='CPU 1 '!C35 -> 0 | D35: ='CPU 1 '!D35 -> 0 | E35: ='CPU 1 '!E35 -> 0 | I35: ='CPU 1 '!DS35 -> 0 | J35: =I35/$I$130 -> 0
... B77: ='CPU 1 '!B77 -> E54 | C77: ='CPU 1 '!C77 -> 0 | D77: ='CPU 1 '!D77 -> 0 | E77: ='CPU 1 '!E77 -> 0 | I77: ='CPU 1 '!DS77 -> 0 | J77: =I77/$I$130 -> 0
B78: B - Custo Total de Equipamentos e Ferramentas: | E78: =SUM(#REF!) -> #REF! | I78: =SUM(I24:I77) -> 197996.86
B79: C – Materiais
B80: Cód. | C80: Discriminação | D80: Unid | E80: P.Unit | G80: Quant | H80: F.utiliz | I80: Custo
B81: ='CPU 1 '!B81 -> M01 | C81: ='CPU 1 '!C81 -> Cabo múltiplo de energia (tetrapolar), condutores flexíveis de cobre (classe 5), classe de tensão de 0.6/1kV, isolamento de PVC 70ºC - Seção 1x4/c # 10.0mm². | D81: ='CPU 1 '!D81 -> M | E81: ='CPU 1 '!E81 -> 45.2 | I81: ='CPU 1 '!DS81 -> 4746 | J81: =I81/$I$130 -> 0.0095962656
B82: ='CPU 1 '!B82 -> M02 | C82: ='CPU 1 '!C82 -> Chave seccionadora 30A TYPE 3R/4/12 CLAS S H 600V, NCM:8536.50.90 CF:5102 MR:ROCKWELL | D82: ='CPU 1 '!D82 -> UND | E82: ='CPU 1 '!E82 -> 230.22 | I82: ='CPU 1 '!DS82 -> 230.22 | J82: =I82/$I$130 -> 0.00046549774
B83: ='CPU 1 '!B83 -> M03 | C83: ='CPU 1 '!C83 -> Terminal olhal de cobre à compressão #10mm² com furo M8, TM-10-8 da Intelli ou similar. | D83: ='CPU 1 '!D83 -> UND | E83: ='CPU 1 '!E83 -> 5.66 | I83: ='CPU 1 '!DS83 -> 45.28 | J83: =I83/$I$130 -> 9.1554763e-05
B84: ='CPU 1 '!B84 -> M04 | C84: ='CPU 1 '!C84 -> Fusível NH Sitor Ultra Rápido Gr 32A 1000V 100Ka T-0, Indicador Frontal 3NE4 101 da Siemens ou similar | D84: ='CPU 1 '!D84 -> UND | E84: ='CPU 1 '!E84 -> 84.66 | I84: ='CPU 1 '!DS84 -> 507.96 | J84: =I84/$I$130 -> 0.0010270794
...

Sheet QQP
C1: PROJETA CONSULTORIA E SERVIÇOS LTDA | E1: PRO-009-25 | H1: =G55 -> 733060.91 | K1: MOBILIZAÇÃO | L1: =SUM(G14) -> 9351.77 | M1: =L1/$H$1 -> 0.012757153 | N1: 0.1 | O1: =$H$1*N1 -> 73306.091 | P1: =L1-O1 -> -63954.321 | Q1: =$H$2*N1 -> 0 | R1: =L1-Q1 -> 9351.77
C2: PROPOSTA COMERCIAL | E2: CLIENTE: | F2: ALUMAR | K2: FORNECIMENTO DE MATERIAL | L2: =SUM(G23:G28) -> 14818.19 | M2: =L2/$H$1 -> 0.020214132 | N2: 0.1 | O2: =$H$1*N2 -> 73306.091 | P2: =L2-O2 -> -58487.901 | Q2: =$H$2*N2 -> 0 | R2: =L2-Q2 -> 14818.19
C3: PLANILHA DE QUANTIDADES E PREÇOS | E3: REV. 1 | F3: DATA: | G3: 45763 | K3: DESMONTAGEM | L3: =SUM(G30:G35) -> 192526.45 | M3: =L3/$H$1 -> 0.26263363 | N3: 0.2 | O3: =$H$1*N3 -> 146612.18 | P3: =L3-O3 -> 45914.268 | Q3: =$H$2*N3 -> 0 | R3: =L3-Q3 -> 192526.45
B4: OBJETO: | C4: CSS00206 - RDC 4598275 - CONTRATAÇÃO DE SERVIÇO PARA MONTAGEM E SERVIÇOS ELETROMECÂNICOS - SUBSTITUIÇÃO DA TALHA ELÉTRICA 161-TL-01 | K4: MONTAGEM | L4: =SUM(G37:G42) -> 178353.04 | M4: =L4/$H$1 -> 0.24329907 | N4: 0.3 | O4: =$H$1*N4 -> 219918.27 | P4: =L4-O4 -> -41565.233 | Q4: =$H$2*N4 -> 0 | R4: =L4-Q4 -> 178353.04
P5: =L5-O5 -> 0 | R5: =L5-Q5 -> 0
B6: ITEM | C6: DESCRIÇÃO | D6: UNID. | E6: QUANT. | F6: P.UNITARIO | G6: P.TOTAL | K6: COMISSIONAMENTO | L6: =SUM(G19) -> 7903.57 | M6: =L6/$H$1 -> 0.010781601 | N6: 0.1 | O6: =$H$1*N6 -> 73306.091 | P6: =L6-O6 -> -65402.521 | Q6: =$H$2*N6 -> 0 | R6: =L6-Q6 -> 7903.57
A7: CPU 1 | B7: 1 | C7: GERAL | G7: =SUM(G8:G12) -> 215280.63 | K7: DATA BOOK E ENTREGA FINAL E DESMOBILIZAÇÃO | L7: =G12 -> 13167.76 | M7: =L7/$H$1 -> 0.017962709 | N7: 0.1 | O7: =$H$1*N7 -> 73306.091 | P7: =L7-O7 -> -60138.331 | Q7: =$H$2*N7 -> 0 | R7: =L7-Q7 -> 13167.76
B8: 1.1 | C8: Mobilização | D8: VB | E8: 1 | F8: =_xlfn.XLOOKUP(B8,'CPU 1 '!$F$1:$FU$1,'CPU 1 '!$F$150:$FU$150) -> 106622.07 | G8: =F8*E8 -> 106622.07 | H8: =G8/$G$55 -> 0.14544776 | N8: DIVISÃO | O8: IDEAL | Q8: MELHOR CENÁRIO
B9: 1.2 | C9: Desmobilização | D9: VB | E9: 1 | F9: =_xlfn.XLOOKUP(B9,'CPU 1 '!$F$1:$FU$1,'CPU 1 '!$F$150:$FU$150) -> 51826.93 | G9: =F9*E9 -> 51826.93 | H9: =G9/$G$55 -> 0.07069935
B10: 1.3 | C10: Canteiro de Obras | D10: VB | E10: 1 | F10: =_xlfn.XLOOKUP(B10,'CPU 1 '!$F$1:$FU$1,'CPU 1 '!$F$150:$FU$150) -> 17990.88 | G10: =F10*E10 -> 17990.88 | H10: =G10/$G$55 -> 0.024542135
B11: 1.4 | C11: Comissionamento e Start Up | D11: VB | E11: 1 | F11: =_xlfn.XLOOKUP(B11,'CPU 1 '!$F$1:$FU$1,'CPU 1 '!$F$150:$FU$150) -> 25672.99 | G11: =F11*E11 -> 25672.99 | H11: =G11/$G$55 -> 0.035021633
B12: 1.5 | C12: Databook | D12: VB | E12: 1 | F12: =_xlfn.XLOOKUP(B12,'CPU 1 '!$F$1:$FU$1,'CPU 1 '!$F$150:$FU$150) -> 13167.76 | G12: =F12*E12 -> 13167.76 | H12: =G12/$G$55 -> 0.017962709
A13: CPU 2 | B13: 2 | C13: ENGENHARIA/DOCUMENTOS | G13: =SUM(G14:G20) -> 63094.74 | K13: DATA BOOK E ENTREGA FINAL E DESMOBILIZAÇÃO | L13: =G20 -> 12924.69 | M13: =L13/$H$1 -> 0.017631127 | N13: 0.1 | O13: =$H$1*N13 -> 73306.091 | P13: =L13-O13 -> -60381.401 | Q13: =$H$2*N13 -> 0 | R13: =L13-Q13 -> 12924.69
B14: 2.1 | C14: Levantamento de Campo | D14: VB | E14: 1 | F14: =_xlfn.XLOOKUP(B14,'CPU 1 '!$F$1:$FU$1,'CPU 1 '!$F$150:$FU$150) -> 9351.77 | G14: =F14*E14 -> 9351.77 | H14: =G14/$G$55 -> 0.012757153 | L14: =SUM(E8:E12,E14:E20,E23:E28,E30:E35,E37:E42,E45:E48,E50:E51,E53:E54) -> 352 | N14: DIVISÃO | O14: IDEAL | Q14: MELHOR CENÁRIO
B15: 2.2 | C15: Topografia | D15: VB | E15: 1 | F15: =_xlfn.XLOOKUP(B15,'CPU 1 '!$F$1:$FU$1,'CPU 1 '!$F$150:$FU$150) -> 9204 | G15: =F15*E15 -> 9204 | H15: =G15/$G$55 -> 0.012555573 | L15: 0.028195865
B16: 2.3 | C16: Lista de Desenhos e Documentos (LDD) | D16: VB | E16: 1 | F16: =_xlfn.XLOOKUP(B16,'CPU 1 '!$F$1:$FU$1,'CPU 1 '!$F$150:$FU$150) -> 7903.57 | G16: =F16*E16 -> 7903.57 | H16: =G16/$G$55 -> 0.010781601
B17: 2.4 | C17: Memorial de Cálculo | D17: VB | E17: 1 | F17: =_xlfn.XLOOKUP(B17,'CPU 1 '!$F$1:$FU$1,'CPU 1 '!$F$150:$FU$150) -> 7903.57 | G17: =F17*E17 -> 7903.57 | H17: =G17/$G$55 -> 0.010781601
B18: 2.5 | C18: Especificação Técnica dos Perfis | D18: VB | E18: 1 | F18: =_xlfn.XLOOKUP(B18,'CPU 1 '!$F$1:$FU$1,'CPU 1 '!$F$150:$FU$150) -> 7903.57 | G18: =F18*E18 -> 7903.57 | H18: =G18/$G$55 -> 0.010781601
B19: 2.6 | C19: Planilha de Quantidades (PQ) | D19: VB | E19: 1 | F19: =_xlfn.XLOOKUP(B19,'CPU 1 '!$F$1:$FU$1,'CPU 1 '!$F$150:$FU$150) -> 7903.57 | G19: =F19*E19 -> 7903.57 | H19: =G19/$G$55 -> 0.010781601
B20: 2.7 | C20: As-Built | D20: VB | E20: 1 | F20: =_xlfn.XLOOKUP(B20,'CPU 1 '!$F$1:$FU$1,'CPU 1 '!$F$150:$FU$150) -> 12924.69 | G20: =F20*E20 -> 12924.69 | H20: =G20/$G$55 -> 0.017631127
A21: CPU 3 | B21: 3 | C21: ELÉTRICA | G21: =SUM(G22,G29,G36) -> 385697.68
B22: 3.1 | C22: FORNECIMENTO | G22: =SUM(G23:G28) -> 14818.19
B23: 3.1.1 | C23: Cabo múltiplo de energia (tetrapolar), condutores flexíveis de cobre (classe 5), classe de tensão de 0.6/1kV, isolamento de PVC 70ºC, nas cores preto, vermelho e azul e verde, condutor flexível de cobre nú, capa externa de PVC na cor laranja, retardante à chama, imune a radiação ultravioleta, Seção 1x4/c # 10.0mm². | D23: M | E23: 100 | F23: =_xlfn.XLOOKUP(B23,'CPU 1 '!$F$1:$FU$1,'CPU 1 '!$F$150:$FU$150) -> 76.97 | G23: =F23*E23 -> 7697 | H23: =G23/$G$55 -> 0.01049981
B24: 3.1.2 | C24: Chave seccionadora 30A TYPE 3R/4/12 CLAS S H 600V, NCM:8536.50.90 CF:5102 MR:ROCKWELL | D24: UND | E24: 1 | F24: =_xlfn.XLOOKUP(B24,'CPU 1 '!$F$1:$FU$1,'CPU 1 '!$F$150:$FU$150) -> 1003.78 | G24: =F24*E24 -> 1003.78 | H24: =G24/$G$55 -> 0.0013692996
B25: 3.1.3 | C25: Terminal olhal de cobre à compressão #10mm² com furo M8, TM-10-8 da Intelli ou similar. | D25: UND | E25: 8 | F25: =_xlfn.XLOOKUP(B25,'CPU 1 '!$F$1:$FU$1,'CPU 1 '!$F$150:$FU$150) -> 91.21 | G25: =F25*E25 -> 729.68 | H25: =G25/$G$55 -> 0.00099538795
B26: 3.1.4 | C26: Fusível NH Sitor Ultra Rápido Gr 32A 1000V 100Ka T-0, Indicador Frontal 3NE4 101 da Siemens ou similar | D26: UND | E26: 6 | F26: =_xlfn.XLOOKUP(B26,'CPU 1 '!$F$1:$FU$1,'CPU 1 '!$F$150:$FU$150) -> 235.91 | G26: =F26*E26 -> 1415.46 | H26: =G26/$G$55 -> 0.00193089
B27: 3.1.5 | C27: Base para Fusível NH Sitor Ultra Rápido Gr 32A 1000V 100Ka, T-0 tipo: 3NH3 230- 0RC da Siemens ou similar | D27: UND | E27: 6 | F27: =_xlfn.XLOOKUP(B27,'CPU 1 '!$F$1:$FU$1,'CPU 1 '!$F$150:$FU$150) -> 205.77 | G27: =F27*E27 -> 1234.62 | H27: =G27/$G$55 -> 0.0016841984
B28: 3.1.6 | C28: Miscelâneas | D28: VB | E28: 1 | F28: =_xlfn.XLOOKUP(B28,'CPU 1 '!$F$1:$FU$1,'CPU 1 '!$F$150:$FU$150) -> 2737.65 | G28: =F28*E28 -> 2737.65 | H28: =G28/$G$55 -> 0.0037345464
A29: CPU 4 | B29: 3.2 | C29: SERVIÇO (DESMONTAGEM) | G29: =SUM(G30:G35) -> 192526.45
B30: 3.2.1 | C30: Desmontagem do Cabo de Alimentação do Quadro de Distribuição QD-161T-11 até a Chave Seccionadora 440V no Campo | D30: M | E30: 100 | F30: =_xlfn.XLOOKUP(B30,'CPU 1 '!$F$1:$FU$1,'CPU 1 '!$F$150:$FU$150) -> 25.93 | G30: =F30*E30 -> 2593 | H30: =G30/$G$55 -> 0.0035372231
B31: 3.2.2 | C31: Desmontagem da Caixa da Chave Seccionadora 440V no Campo | D31: UND | E31: 1 | F31: =_xlfn.XLOOKUP(B31,'CPU 1 '!$F$1:$FU$1,'CPU 1 '!$F$150:$FU$150) -> 865.19 | G31: =F31*E31 -> 865.19 | H31: =G31/$G$55 -> 0.001180243
B32: 3.2.3 | C32: Desmontagem da Cortina de Cabos Existente com Trole no Campo | D32: UND | E32: 1 | F32: =_xlfn.XLOOKUP(B32,'CPU 1 '!$F$1:$FU$1,'CPU 1 '!$F$150:$FU$150) -> 59715.97 | G32: =F32*E32 -> 59715.97 | H32: =G32/$G$55 -> 0.08146113
B33: 3.2.4 | C33: Desmontagem da Talha Elétrica 1 Tonelada no Campo | D33: UND | E33: 1 | F33: =_xlfn.XLOOKUP(B33,'CPU 1 '!$F$1:$FU$1,'CPU 1 '!$F$150:$FU$150) -> 125689.24 | G33: =F33*E33 -> 125689.24 | H33: =G33/$G$55 -> 0.17145811
B34: 3.2.5 | C34: Desmontagem dos Componentes Internos do Quadro de distribuição QD-161T-11 | D34: UND | E34: 1 | F34: =_xlfn.XLOOKUP(B34,'CPU 1 '!$F$1:$FU$1,'CPU 1 '!$F$150:$FU$150) -> 2088.13 | G34: =F34*E34 -> 2088.13 | H34: =G34/$G$55 -> 0.0028485082
B35: 3.2.6 | C35: Desmontagem do Suporte Existente da Chave Seccionadora no Campo | D35: UND | E35: 1 | F35: =_xlfn.XLOOKUP(B35,'CPU 1 '!$F$1:$FU$1,'CPU 1 '!$F$150:$FU$150) -> 1574.92 | G35: =F35*E35 -> 1574.92 | H35: =G35/$G$55 -> 0.0021484163
A36: CPU 5 | B36: 3.3 | C36: SERVIÇO (MONTAGEM) | G36: =SUM(G37:G42) -> 178353.04
B37: 3.3.1 | C37: Montagem dos Componentes Internos do Quadro de distribuição QD-161T-11 | D37: UND | E37: 1 | F37: =_xlfn.XLOOKUP(B37,'CPU 1 '!$F$1:$FU$1,'CPU 1 '!$F$150:$FU$150) -> 2259.2 | G37: =F37*E37 -> 2259.2 | H37: =G37/$G$55 -> 0.0030818721
B38: 3.3.2 | C38: Montagem do Cabo de Alimentação do Quadro de Distribuição QD-161T-11 até a Chave Seccionadora 440V no Campo | D38: M | E38: 100 | F38: =_xlfn.XLOOKUP(B38,'CPU 1 '!$F$1:$FU$1,'CPU 1 '!$F$150:$FU$150) -> 291.74 | G38: =F38*E38 -> 29174 | H38: =G38/$G$55 -> 0.039797512
B39: 3.3.3 | C39: Montagem do Suporte Existente da Chave Seccionadora no Campo | D39: UND | E39: 1 | F39: =_xlfn.XLOOKUP(B39,'CPU 1 '!$F$1:$FU$1,'CPU 1 '!$F$150:$FU$150) -> 1090.21 | G39: =F39*E39 -> 1090.21 | H39: =G39/$G$55 -> 0.0014872025
B40: 3.3.4 | C40: Montagem da Caixa da Chave Seccionadora no Campo | D40: UND | E40: 1 | F40: =_xlfn.XLOOKUP(B40,'CPU 1 '!$F$1:$FU$1,'CPU 1 '!$F$150:$FU$150) -> 805.1 | G40: =F40*E40 -> 805.1 | H40: =G40/$G$55 -> 0.0010982716
...

Sheet CPU  1 
B1: =QQP!G55 -> 733060.91 | D1: CPU | E1: 1 | F1: =QQP!B8 -> 1.1 | G1: =H150 -> 106622.07 | I1: =QQP!B9 -> 1.2 | J1: =K150 -> 51826.933 | L1: =QQP!B10 -> 1.3 | M1: =N150 -> 17990.882 | O1: =QQP!B11 -> 1.4 | P1: =Q150 -> 25672.987 | R1: =QQP!B12 -> 1.5 | S1: =T150 -> 13167.762 | U1: =QQP!B14 -> 2.1 | V1: =W150 -> 9351.772 | X1: =QQP!B15 -> 2.2 | Y1: =Z150 -> 9204.0035 | AA1: =QQP!B16 -> 2.3 | AB1: =AC150 -> 7903.5663 | AD1: =QQP!B17 -> 2.4 | AE1: =AF150 -> 7903.5663 | AG1: =QQP!B18 -> 2.5 | AH1: =AI150 -> 7903.5663 | AJ1: =QQP!B19 -> 2.6 | AK1: =AL150 -> 7903.5663 | AM1: =QQP!B20 -> 2.7 | AN1: =AO150 -> 12924.693 | AP1: =QQP!B23 -> 3.1.1 | AQ1: =AR150 -> 76.971853 | AS1: =QQP!B24 -> 3.1.2 | AT1: =AU150 -> 1003.7757 | AV1: =QQP!B25 -> 3.1.3 | AW1: =AX150 -> 91.206582 | AY1: =QQP!B26 -> 3.1.4 | AZ1: =BA150 -> 235.90822 | BB1: =QQP!B27 -> 3.1.5 | BC1: =BD150 -> 205.77455 | BE1: =QQP!B28 -> 3.1.6 | BF1: =BG150 -> 2737.6548 | BH1: =QQP!B30 -> 3.2.1 | BI1: =BJ150 -> 25.92554 | BK1: =QQP!B31 -> 3.2.2 | BL1: =BM150 -> 865.18917 | BN1: =QQP!B32 -> 3.2.3 | BO1: =BP150 -> 59715.973 | BQ1: =QQP!B33 -> 3.2.4 | BR1: =BS150 -> 125689.24 | BT1: =QQP!B34 -> 3.2.5 | BU1: =BV150 -> 2088.1275 | BW1: =QQP!B35 -> 3.2.6 | BX1: =BY150 -> 1574.9151 | BZ1: =QQP!B37 -> 3.3.1 | CA1: =CB150 -> 2259.1983 | CC1: =QQP!B38 -> 3.3.2 | CD1: =CE150 -> 291.74339 | CF1: =QQP!B39 -> 3.3.3 | CG1: =CH150 -> 1090.2145 | CI1: =QQP!B40 -> 3.3.4 | CJ1: =CK150 -> 805.09644 | CL1: =QQP!B41 -> 3.3.5 | CM1: =CN150 -> 134773.34 | CO1: =QQP!B42 -> 3.3.6 | CP1: =CQ150 -> 10251.194 | CR1: =QQP!B45 -> 4.1.1 | CS1: =CT150 -> 6506.1806 | CU1: =QQP!B46 -> 4.1.2 | CV1: =CW150 -> 10951.444 | CX1: =QQP!B47 -> 4.1.3 | CY1: =CZ150 -> 6225.1563 | DA1: =QQP!B48 -> 4.1.4 | DB1: =DC150 -> 4812.7722 | DD1: =QQP!B50 -> 4.2.1 | DE1: =DF150 -> 7243.7829 | DG1: =QQP!B51 -> 4.2.2 | DH1: =DI150 -> 5598.4716 | DJ1: =QQP!B53 -> 4.3.1 | DK1: =DL150 -> 17115.651 | DM1: =QQP!B54 -> 4.3.2 | DN1: =DO150 -> 10534.406
B2: Composição de Preços Unitários | F2: =_xlfn.XLOOKUP(F1,QQP!$B$8:$B$54,QQP!$C$8:$C$54) -> Mobilização | I2: =_xlfn.XLOOKUP(I1,QQP!$B$8:$B$54,QQP!$C$8:$C$54) -> Desmobilização | L2: =_xlfn.XLOOKUP(L1,QQP!$B$8:$B$54,QQP!$C$8:$C$54) -> Canteiro de Obras | O2: =_xlfn.XLOOKUP(O1,QQP!$B$8:$B$54,QQP!$C$8:$C$54) -> Comissionamento e Start Up | R2: =_xlfn.XLOOKUP(R1,QQP!$B$8:$B$54,QQP!$C$8:$C$54) -> Databook | U2: =_xlfn.XLOOKUP(U1,QQP!$B$8:$B$54,QQP!$C$8:$C$54) -> Levantamento de Campo | X2: =_xlfn.XLOOKUP(X1,QQP!$B$8:$B$54,QQP!$C$8:$C$54) -> Topografia | AA2: =_xlfn.XLOOKUP(AA1,QQP!$B$8:$B$54,QQP!$C$8:$C$54) -> Lista de Desenhos e Documentos (LDD) | AD2: =_xlfn.XLOOKUP(AD1,QQP!$B$8:$B$54,QQP!$C$8:$C$54) -> Memorial de Cálculo | AG2: =_xlfn.XLOOKUP(AG1,QQP!$B$8:$B$54,QQP!$C$8:$C$54) -> Especificação Técnica dos Perfis | AJ2: =_xlfn.XLOOKUP(AJ1,QQP!$B$8:$B$54,QQP!$C$8:$C$54) -> Planilha de Quantidades (PQ) | AM2: =_xlfn.XLOOKUP(AM1,QQP!$B$8:$B$54,QQP!$C$8:$C$54) -> As-Built | AP2: =_xlfn.XLOOKUP(AP1,QQP!$B$8:$B$54,QQP!$C$8:$C$54) -> Cabo múltiplo de energia (tetrapolar), condutores flexíveis de cobre (classe 5), classe de tensão de 0.6/1kV, isolamento de PVC 70ºC, nas cores preto, vermelho e azul e verde, condutor flexível de cobre nú, capa externa de PVC na cor laranja, retardante à chama, imune a radiação ultravioleta, Seção 1x4/c # 10.0mm². | AS2: =_xlfn.XLOOKUP(AS1,QQP!$B$8:$B$54,QQP!$C$8:$C$54) -> Chave seccionadora 30A TYPE 3R/4/12 CLAS S H 600V, NCM:8536.50.90 CF:5102 MR:ROCKWELL | AV2: =_xlfn.XLOOKUP(AV1,QQP!$B$8:$B$54,QQP!$C$8:$C$54) -> Terminal olhal de cobre à compressão #10mm² com furo M8, TM-10-8 da Intelli ou similar. | AY2: =_xlfn.XLOOKUP(AY1,QQP!$B$8:$B$54,QQP!$C$8:$C$54) -> Fusível NH Sitor Ultra Rápido Gr 32A 1000V 100Ka T-0, Indicador Frontal 3NE4 101 da Siemens ou similar | BB2: =_xlfn.XLOOKUP(BB1,QQP!$B$8:$B$54,QQP!$C$8:$C$54) -> Base para Fusível NH Sitor Ultra Rápido Gr 32A 1000V 100Ka, T-0 tipo: 3NH3 230- 0RC da Siemens ou similar | BE2: =_xlfn.XLOOKUP(BE1,QQP!$B$8:$B$54,QQP!$C$8:$C$54) -> Miscelâneas | BH2: =_xlfn.XLOOKUP(BH1,QQP!$B$8:$B$54,QQP!$C$8:$C$54) -> Desmontagem do Cabo de Alimentação do Quadro de Distribuição QD-161T-11 até a Chave Seccionadora 440V no Campo | BK2: =_xlfn.XLOOKUP(BK1,QQP!$B$8:$B$54,QQP!$C$8:$C$54) -> Desmontagem da Caixa da Chave Seccionadora 440V no Campo | BN2: =_xlfn.XLOOKUP(BN1,QQP!$B$8:$B$54,QQP!$C$8:$C$54) -> Desmontagem da Cortina de Cabos Existente com Trole no Campo | BQ2: =_xlfn.XLOOKUP(BQ1,QQP!$B$8:$B$54,QQP!$C$8:$C$54) -> Desmontagem da Talha Elétrica 1 Tonelada no Campo | BT2: =_xlfn.XLOOKUP(BT1,QQP!$B$8:$B$54,QQP!$C$8:$C$54) -> Desmontagem dos Componentes Internos do Quadro de distribuição QD-161T-11 | BW2: =_xlfn.XLOOKUP(BW1,QQP!$B$8:$B$54,QQP!$C$8:$C$54) -> Desmontagem do Suporte Existente da Chave Seccionadora no Campo | BZ2: =_xlfn.XLOOKUP(BZ1,QQP!$B$8:$B$54,QQP!$C$8:$C$54) -> Montagem dos Componentes Internos do Quadro de distribuição QD-161T-11 | CC2: =_xlfn.XLOOKUP(CC1,QQP!$B$8:$B$54,QQP!$C$8:$C$54) -> Montagem do Cabo de Alimentação do Quadro de Distribuição QD-161T-11 até a Chave Seccionadora 440V no Campo | CF2: =_xlfn.XLOOKUP(CF1,QQP!$B$8:$B$54,QQP!$C$8:$C$54) -> Montagem do Suporte Existente da Chave Seccionadora no Campo | CI2: =_xlfn.XLOOKUP(CI1,QQP!$B$8:$B$54,QQP!$C$8:$C$54) -> Montagem da Caixa da Chave Seccionadora no Campo | CL2: =_xlfn.XLOOKUP(CL1,QQP!$B$8:$B$54,QQP!$C$8:$C$54) -> Montagem da Talha Elétrica 1 Tonelada do Tipo CTX– Konecranes | CO2: =_xlfn.XLOOKUP(CO1,QQP!$B$8:$B$54,QQP!$C$8:$C$54) -> Montagem da Cortina de Cabos Completo Tipo Festoon com Troles Arrastador | CR2: =_xlfn.XLOOKUP(CR1,QQP!$B$8:$B$54,QQP!$C$8:$C$54) -> Fornecimento de perfis metálicos leve (< 25kg/m) | CU2: =_xlfn.XLOOKUP(CU1,QQP!$B$8:$B$54,QQP!$C$8:$C$54) -> Fornecimento de perfis metálicos médio (> 25kg/m < 80kg/m) | CX2: =_xlfn.XLOOKUP(CX1,QQP!$B$8:$B$54,QQP!$C$8:$C$54) -> Fornecimento de perfis metálicos médio pesado (> 80kg/m) | DA2: =_xlfn.XLOOKUP(DA1,QQP!$B$8:$B$54,QQP!$C$8:$C$54) -> Miscelâneas | DD2: =_xlfn.XLOOKUP(DD1,QQP!$B$8:$B$54,QQP!$C$8:$C$54) -> Desmontagem da monovia existente | DG2: =_xlfn.XLOOKUP(DG1,QQP!$B$8:$B$54,QQP!$C$8:$C$54) -> Desmontagem das estruturas transversais de apoio | DJ2: =_xlfn.XLOOKUP(DJ1,QQP!$B$8:$B$54,QQP!$C$8:$C$54) -> Montagem da monovia existente | DM2: =_xlfn.XLOOKUP(DM1,QQP!$B$8:$B$54,QQP!$C$8:$C$54) -> Montagem das estruturas transversais de apoio | DQ2: CHECK
G3: =_xlfn.XLOOKUP(F1,QQP!$B$8:$B$54,QQP!$D$8:$D$54) -> VB | H3: =_xlfn.XLOOKUP(F1,QQP!$B$8:$B$54,QQP!$E$8:$E$54) -> 1 | J3: =_xlfn.XLOOKUP(I1,QQP!$B$8:$B$54,QQP!$D$8:$D$54) -> VB | K3: =_xlfn.XLOOKUP(I1,QQP!$B$8:$B$54,QQP!$E$8:$E$54) -> 1 | M3: =_xlfn.XLOOKUP(L1,QQP!$B$8:$B$54,QQP!$D$8:$D$54) -> VB | N3: =_xlfn.XLOOKUP(L1,QQP!$B$8:$B$54,QQP!$E$8:$E$54) -> 1 | P3: =_xlfn.XLOOKUP(O1,QQP!$B$8:$B$54,QQP!$D$8:$D$54) -> VB | Q3: =_xlfn.XLOOKUP(O1,QQP!$B$8:$B$54,QQP!$E$8:$E$54) -> 1 | S3: =_xlfn.XLOOKUP(R1,QQP!$B$8:$B$54,QQP!$D$8:$D$54) -> VB | T3: =_xlfn.XLOOKUP(R1,QQP!$B$8:$B$54,QQP!$E$8:$E$54) -> 1 | V3: =_xlfn.XLOOKUP(U1,QQP!$B$8:$B$54,QQP!$D$8:$D$54) -> VB | W3: =_xlfn.XLOOKUP(U1,QQP!$B$8:$B$54,QQP!$E$8:$E$54) -> 1 | Y3: =_xlfn.XLOOKUP(X1,QQP!$B$8:$B$54,QQP!$D$8:$D$54) -> VB | Z3: =_xlfn.XLOOKUP(X1,QQP!$B$8:$B$54,QQP!$E$8:$E$54) -> 1 | AB3: =_xlfn.XLOOKUP(AA1,QQP!$B$8:$B$54,QQP!$D$8:$D$54) -> VB | AC3: =_xlfn.XLOOKUP(AA1,QQP!$B$8:$B$54,QQP!$E$8:$E$54) -> 1 | AE3: =_xlfn.XLOOKUP(AD1,QQP!$B$8:$B$54,QQP!$D$8:$D$54) -> VB | AF3: =_xlfn.XLOOKUP(AD1,QQP!$B$8:$B$54,QQP!$E$8:$E$54) -> 1 | AH3: =_xlfn.XLOOKUP(AG1,QQP!$B$8:$B$54,QQP!$D$8:$D$54) -> VB | AI3: =_xlfn.XLOOKUP(AG1,QQP!$B$8:$B$54,QQP!$E$8:$E$54) -> 1 | AK3: =_xlfn.XLOOKUP(AJ1,QQP!$B$8:$B$54,QQP!$D$8:$D$54) -> VB | AL3: =_xlfn.XLOOKUP(AJ1,QQP!$B$8:$B$54,QQP!$E$8:$E$54) -> 1 | AN3: =_xlfn.XLOOKUP(AM1,QQP!$B$8:$B$54,QQP!$D$8:$D$54) -> VB | AO3: =_xlfn.XLOOKUP(AM1,QQP!$B$8:$B$54,QQP!$E$8:$E$54) -> 1 | AQ3: =_xlfn.XLOOKUP(AP1,QQP!$B$8:$B$54,QQP!$D$8:$D$54) -> M | AR3: =_xlfn.XLOOKUP(AP1,QQP!$B$8:$B$54,QQP!$E$8:$E$54) -> 100 | AT3: =_xlfn.XLOOKUP(AS1,QQP!$B$8:$B$54,QQP!$D$8:$D$54) -> UND | AU3: =_xlfn.XLOOKUP(AS1,QQP!$B$8:$B$54,QQP!$E$8:$E$54) -> 1 | AW3: =_xlfn.XLOOKUP(AV1,QQP!$B$8:$B$54,QQP!$D$8:$D$54) -> UND | AX3: =_xlfn.XLOOKUP(AV1,QQP!$B$8:$B$54,QQP!$E$8:$E$54) -> 8 | AZ3: =_xlfn.XLOOKUP(AY1,QQP!$B$8:$B$54,QQP!$D$8:$D$54) -> UND | BA3: =_xlfn.XLOOKUP(AY1,QQP!$B$8:$B$54,QQP!$E$8:$E$54) -> 6 | BC3: =_xlfn.XLOOKUP(BB1,QQP!$B$8:$B$54,QQP!$D$8:$D$54) -> UND | BD3: =_xlfn.XLOOKUP(BB1,QQP!$B$8:$B$54,QQP!$E$8:$E$54) -> 6 | BF3: =_xlfn.XLOOKUP(BE1,QQP!$B$8:$B$54,QQP!$D$8:$D$54) -> VB | BG3: =_xlfn.XLOOKUP(BE1,QQP!$B$8:$B$54,QQP!$E$8:$E$54) -> 1 | BI3: =_xlfn.XLOOKUP(BH1,QQP!$B$8:$B$54,QQP!$D$8:$D$54) -> M | BJ3: =_xlfn.XLOOKUP(BH1,QQP!$B$8:$B$54,QQP!$E$8:$E$54) -> 100 | BL3: =_xlfn.XLOOKUP(BK1,QQP!$B$8:$B$54,QQP!$D$8:$D$54) -> UND | BM3: =_xlfn.XLOOKUP(BK1,QQP!$B$8:$B$54,QQP!$E$8:$E$54) -> 1 | BO3: =_xlfn.XLOOKUP(BN1,QQP!$B$8:$B$54,QQP!$D$8:$D$54) -> UND | BP3: =_xlfn.XLOOKUP(BN1,QQP!$B$8:$B$54,QQP!$E$8:$E$54) -> 1 | BR3: =_xlfn.XLOOKUP(BQ1,QQP!$B$8:$B$54,QQP!$D$8:$D$54) -> UND | BS3: =_xlfn.XLOOKUP(BQ1,QQP!$B$8:$B$54,QQP!$E$8:$E$54) -> 1 | BU3: =_xlfn.XLOOKUP(BT1,QQP!$B$8:$B$54,QQP!$D$8:$D$54) -> UND | BV3: =_xlfn.XLOOKUP(BT1,QQP!$B$8:$B$54,QQP!$E$8:$E$54) -> 1 | BX3: =_xlfn.XLOOKUP(BW1,QQP!$B$8:$B$54,QQP!$D$8:$D$54) -> UND | BY3: =_xlfn.XLOOKUP(BW1,QQP!$B$8:$B$54,QQP!$E$8:$E$54) -> 1 | CA3: =_xlfn.XLOOKUP(BZ1,QQP!$B$8:$B$54,QQP!$D$8:$D$54) -> UND | CB3: =_xlfn.XLOOKUP(BZ1,QQP!$B$8:$B$54,QQP!$E$8:$E$54) -> 1 | CD3: =_xlfn.XLOOKUP(CC1,QQP!$B$8:$B$54,QQP!$D$8:$D$54) -> M | CE3: =_xlfn.XLOOKUP(CC1,QQP!$B$8:$B$54,QQP!$E$8:$E$54) -> 100 | CG3: =_xlfn.XLOOKUP(CF1,QQP!$B$8:$B$54,QQP!$D$8:$D$54) -> UND | CH3: =_xlfn.XLOOKUP(CF1,QQP!$B$8:$B$54,QQP!$E$8:$E$54) -> 1 | CJ3: =_xlfn.XLOOKUP(CI1,QQP!$B$8:$B$54,QQP!$D$8:$D$54) -> UND | CK3: =_xlfn.XLOOKUP(CI1,QQP!$B$8:$B$54,QQP!$E$8:$E$54) -> 1 | CM3: =_xlfn.XLOOKUP(CL1,QQP!$B$8:$B$54,QQP!$D$8:$D$54) -> UND | CN3: =_xlfn.XLOOKUP(CL1,QQP!$B$8:$B$54,QQP!$E$8:$E$54) -> 1 | CP3: =_xlfn.XLOOKUP(CO1,QQP!$B$8:$B$54,QQP!$D$8:$D$54) -> UND | CQ3: =_xlfn.XLOOKUP(CO1,QQP!$B$8:$B$54,QQP!$E$8:$E$54) -> 1 | CS3: =_xlfn.XLOOKUP(CR1,QQP!$B$8:$B$54,QQP!$D$8:$D$54) -> VB | CT3: =_xlfn.XLOOKUP(CR1,QQP!$B$8:$B$54,QQP!$E$8:$E$54) -> 1 | CV3: =_xlfn.XLOOKUP(CU1,QQP!$B$8:$B$54,QQP!$D$8:$D$54) -> VB | CW3: =_xlfn.XLOOKUP(CU1,QQP!$B$8:$B$54,QQP!$E$8:$E$54) -> 1 | CY3: =_xlfn.XLOOKUP(CX1,QQP!$B$8:$B$54,QQP!$D$8:$D$54) -> VB | CZ3: =_xlfn.XLOOKUP(CX1,QQP!$B$8:$B$54,QQP!$E$8:$E$54) -> 1 | DB3: =_xlfn.XLOOKUP(DA1,QQP!$B$8:$B$54,QQP!$D$8:$D$54) -> VB | DC3: =_xlfn.XLOOKUP(DA1,QQP!$B$8:$B$54,QQP!$E$8:$E$54) -> 1 | DE3: =_xlfn.XLOOKUP(DD1,QQP!$B$8:$B$54,QQP!$D$8:$D$54) -> VB | DF3: =_xlfn.XLOOKUP(DD1,QQP!$B$8:$B$54,QQP!$E$8:$E$54) -> 1 | DH3: =_xlfn.XLOOKUP(DG1,QQP!$B$8:$B$54,QQP!$D$8:$D$54) -> VB | DI3: =_xlfn.XLOOKUP(DG1,QQP!$B$8:$B$54,QQP!$E$8:$E$54) -> 1 | DK3: =_xlfn.XLOOKUP(DJ1,QQP!$B$8:$B$54,QQP!$D$8:$D$54) -> VB | DL3: =_xlfn.XLOOKUP(DJ1,QQP!$B$8:$B$54,QQP!$E$8:$E$54) -> 1 | DN3: =_xlfn.XLOOKUP(DM1,QQP!$B$8:$B$54,QQP!$D$8:$D$54) -> VB | DO3: =_xlfn.XLOOKUP(DM1,QQP!$B$8:$B$54,QQP!$E$8:$E$54) -> 1
F4: 8 | G4: 20 | H4: diárias | I4: 8 | J4: 10 | K4: diárias | L4: 8 | M4: 10 | N4: diárias | O4: 8 | P4: 14 | Q4: diárias | R4: 8 | S4: 7 | T4: diárias | U4: 8 | V4: 3 | W4: diárias | X4: 8 | Y4: 10 | Z4: diárias | AA4: 8 | AB4: 5 | AC4: diárias | AD4: 8 | AE4: 5 | AF4: diárias | AG4: 8 | AH4: 5 | AI4: diárias | AJ4: 8 | AK4: 5 | AL4: diárias | AM4: 8 | AN4: 8 | AO4: diárias | AP4: 8.8 | AQ4: 5 | AR4: diárias | AS4: 8.8 | AT4: 5 | AU4: diárias | AV4: 8.8 | AW4: 5 | AX4: diárias | AY4: 8.8 | AZ4: 5 | BA4: diárias | BB4: 8.8 | BC4: 5 | BD4: diárias | BE4: 8.8 | BF4: 5 | BG4: diárias | BN4: 8 | BO4: 2 | BP4: diárias | BQ4: 8 | BR4: 6 | BS4: diárias | BT4: 8 | BU4: 0.5 | BV4: diária | BW4: 8 | BX4: 0.32 | BY4: diária | BZ4: 8 | CA4: 0.56 | CB4: diária | CC4: 8 | CD4: 0.1 | CE4: diária | CF4: 8 | CG4: 0.15 | CH4: diária | CI4: 8 | CJ4: 0.05 | CK4: diária | CL4: 8 | CM4: 7 | CN4: diárias | CO4: 8 | CP4: 3 | CQ4: diárias | DD4: 8 | DE4: 2 | DF4: diárias | DG4: 8 | DH4: 1.5 | DI4: diárias | DJ4: 8 | DK4: 5 | DL4: diárias | DM4: 8 | DN4: 3 | DO4: diárias
B5: A - Mão de Obra + Encargos
B6: Cód. | C6: Discriminação | D6: Unid | E6: P.Unit | F6: Quant | G6: F.utiliz | H6: Custo | I6: Quant | J6: F.utiliz | K6: Custo | L6: Quant | M6: F.utiliz | N6: Custo | O6: Quant | P6: F.utiliz | Q6: Custo | R6: Quant | S6: F.utiliz | T6: Custo | U6: Quant | V6: F.utiliz | W6: Custo | X6: Quant | Y6: F.utiliz | Z6: Custo | AA6: Quant | AB6: F.utiliz | AC6: Custo | AD6: Quant | AE6: F.utiliz | AF6: Custo | AG6: Quant | AH6: F.utiliz | AI6: Custo | AJ6: Quant | AK6: F.utiliz | AL6: Custo | AM6: Quant | AN6: F.utiliz | AO6: Custo | AP6: Quant | AQ6: F.utiliz | AR6: Custo | AS6: Quant | AT6: F.utiliz | AU6: Custo | AV6: Quant | AW6: F.utiliz | AX6: Custo | AY6: Quant | AZ6: F.utiliz | BA6: Custo | BB6: Quant | BC6: F.utiliz | BD6: Custo | BE6: Quant | BF6: F.utiliz | BG6: Custo | BH6: Quant | BI6: F.utiliz | BJ6: Custo | BK6: Quant | BL6: F.utiliz | BM6: Custo | BN6: Quant | BO6: F.utiliz | BP6: Custo | BQ6: Quant | BR6: F.utiliz | BS6: Custo | BT6: Quant | BU6: F.utiliz | BV6: Custo | BW6: Quant | BX6: F.utiliz | BY6: Custo | BZ6: Quant | CA6: F.utiliz | CB6: Custo | CC6: Quant | CD6: F.utiliz | CE6: Custo | CF6: Quant | CG6: F.utiliz | CH6: Custo | CI6: Quant | CJ6: F.utiliz | CK6: Custo | CL6: Quant | CM6: F.utiliz | CN6: Custo | CO6: Quant | CP6: F.utiliz | CQ6: Custo | CR6: Quant | CS6: F.utiliz | CT6: Custo | CU6: Quant | CV6: F.utiliz | CW6: Custo | CX6: Quant | CY6: F.utiliz | CZ6: Custo | DA6: Quant | DB6: F.utiliz | DC6: Custo | DD6: Quant | DE6: F.utiliz | DF6: Custo | DG6: Quant | DH6: F.utiliz | DI6: Custo | DJ6: Quant | DK6: F.utiliz | DL6: Custo | DM6: Quant | DN6: F.utiliz | DO6: Custo | DQ6: Quant | DR6: F.utiliz | DS6: Custo
B7: =MO!B3 -> P01 | C7: =MO!C3 -> Técnico SSMA | D7: hh | E7: =MO!I3 -> 30.027273 | F7: =$F$4*$G$4 -> 160 | G7: 1 | H7: =G7*F7*$E7 -> 4804.3636 | I7: =$I$4*$J$4 -> 80 | J7: 1 | K7: =J7*I7*$E7 -> 2402.1818 | N7: =M7*L7*$E7 -> 0 | Q7: =P7*O7*$E7 -> 0 | T7: =S7*R7*$E7 -> 0 | W7: =V7*U7*$E7 -> 0 | Z7: =Y7*X7*$E7 -> 0 | AC7: =AB7*AA7*$E7 -> 0 | AF7: =AE7*AD7*$E7 -> 0 | AI7: =AH7*AG7*$E7 -> 0 | AL7: =AK7*AJ7*$E7 -> 0 | AO7: =AN7*AM7*$E7 -> 0 | AR7: =AQ7*AP7*$E7 -> 0 | AU7: =AT7*AS7*$E7 -> 0 | AX7: =AW7*AV7*$E7 -> 0 | BA7: =AZ7*AY7*$E7 -> 0 | BD7: =BC7*BB7*$E7 -> 0 | BG7: =BF7*BE7*$E7 -> 0 | BH7: 0.12 | BI7: 1 | BJ7: =BI7*BH7*$E7 -> 3.6032727 | BK7: 1.26 | BL7: 1 | BM7: =BL7*BK7*$E7 -> 37.834364 | BN7: =$BN$4*$BO$4 -> 16 | BO7: 1 | BP7: =BO7*BN7*$E7 -> 480.43636 | BQ7: =$BQ$4*$BR$4 -> 48 | BR7: 1 | BS7: =BR7*BQ7*$E7 -> 1441.3091 | BT7: =$BT$4*$BU$4 -> 4 | BU7: 1 | BV7: =BU7*BT7*$E7 -> 120.10909 | BW7: =$BW$4*$BX$4 -> 2.56 | BX7: 1 | BY7: =BX7*BW7*$E7 -> 76.869818 | BZ7: =$BZ$4*$CA$4 -> 4.48 | CA7: 1 | CB7: =CA7*BZ7*$E7 -> 134.52218 | CC7: =$CC$4*$CD$4 -> 0.8 | CD7: 1 | CE7: =CD7*CC7*$E7 -> 24.021818 | CF7: =$CF$4*$CG$4 -> 1.2 | CG7: 1 | CH7: =CG7*CF7*$E7 -> 36.032727 | CI7: =$CI$4*$CJ$4 -> 0.4 | CJ7: 1 | CK7: =CJ7*CI7*$E7 -> 12.010909 | CL7: =$CL$4*$CM$4 -> 56 | CM7: 1 | CN7: =CM7*CL7*$E7 -> 1681.5273 | CO7: =$CO$4*$CP$4 -> 24 | CP7: 1 | CQ7: =CP7*CO7*$E7 -> 720.65455 | CT7: =CS7*CR7*$E7 -> 0 | CW7: =CV7*CU7*$E7 -> 0 | CZ7: =CY7*CX7*$E7 -> 0 | DC7: =DB7*DA7*$E7 -> 0 | DD7: =$DD$4*$DE$4 -> 16 | DE7: 1 | DF7: =DE7*DD7*$E7 -> 480.43636 | DG7: =$DG$4*$DH$4 -> 12 | DH7: 1 | DI7: =DH7*DG7*$E7 -> 360.32727 | DJ7: =$DJ$4*$DK$4 -> 40 | DK7: 1 | DL7: =DK7*DJ7*$E7 -> 1201.0909 | DM7: =$DM$4*$DN$4 -> 24 | DN7: 1 | DO7: =DN7*DM7*$E7 -> 720.65455 | DS7: =($H$3*H7+$K$3*K7+$N$3*N7+$Q$3*Q7+$T$3*T7+$W$3*W7+$Z$3*Z7+$AC$3*AC7+$AF$3*AF7+$AI$3*AI7+$AL$3*AL7+$AO$3*AO7+$AR$3*AR7+$AU$3*AU7+$AX$3*AX7+$BA$3*BA7+$BD$3*BD7+$BG$3*BG7+$BJ$3*BJ7+$BM$3*BM7+$BP$3*BP7+$BS$3*BS7+$BV$3*BV7+$BY$3*BY7+$CB$3*CB7+$CE$3*CE7+$CH$3*CH7+$CK$3*CK7+$CN$3*CN7+$CQ$3*CQ7+$CT$3*CT7+$CW$3*CW7+$CZ$3*CZ7+$DC$3*DC7+$DF$3*DF7+$DI$3*DI7+$DL$3*DL7+$DO$3*DO7) -> 17472.87 | DT7: =DS7/$DS$130 -> 0.035329604
B8: =MO!B4 -> P02 | C8: =MO!C4 -> Eletricista de força e controle | D8: hh | E8: =MO!I4 -> 35.63937 | F8: =$F$4*$G$4 -> 160 | G8: 1 | H8: =G8*F8*$E8 -> 5702.2992 | I8: =$I$4*$J$4 -> 80 | J8: 1 | K8: =J8*I8*$E8 -> 2851.1496 | N8: =M8*L8*$E8 -> 0 | Q8: =P8*O8*$E8 -> 0 | T8: =S8*R8*$E8 -> 0 | W8: =V8*U8*$E8 -> 0 | Z8: =Y8*X8*$E8 -> 0 | AC8: =AB8*AA8*$E8 -> 0 | AF8: =AE8*AD8*$E8 -> 0 | AI8: =AH8*AG8*$E8 -> 0 | AL8: =AK8*AJ8*$E8 -> 0 | AO8: =AN8*AM8*$E8 -> 0 | AR8: =AQ8*AP8*$E8 -> 0 | AU8: =AT8*AS8*$E8 -> 0 | AX8: =AW8*AV8*$E8 -> 0 | BA8: =AZ8*AY8*$E8 -> 0 | BD8: =BC8*BB8*$E8 -> 0 | BG8: =BF8*BE8*$E8 -> 0 | BH8: 0.12 | BI8: 1 | BJ8: =BI8*BH8*$E8 -> 4.2767244 | BK8: 1.26 | BL8: 1 | BM8: =BL8*BK8*$E8 -> 44.905606 | BN8: =$BN$4*$BO$4 -> 16 | BO8: 1 | BP8: =BO8*BN8*$E8 -> 570.22992 | BQ8: =$BQ$4*$BR$4 -> 48 | BR8: 1 | BS8: =BR8*BQ8*$E8 -> 1710.6898 | BT8: =$BT$4*$BU$4 -> 4 | BU8: 1 | BV8: =BU8*BT8*$E8 -> 142.55748 | BW8: =$BW$4*$BX$4 -> 2.56 | BX8: 1 | BY8: =BX8*BW8*$E8 -> 91.236787 | BZ8: =$BZ$4*$CA$4 -> 4.48 | CA8: 1 | CB8: =CA8*BZ8*$E8 -> 159.66438 | CC8: =$CC$4*$CD$4 -> 0.8 | CD8: 1 | CE8: =CD8*CC8*$E8 -> 28.511496 | CF8: =$CF$4*$CG$4 -> 1.2 | CG8: 1 | CH8: =CG8*CF8*$E8 -> 42.767244 | CI8: =$CI$4*$CJ$4 -> 0.4 | CJ8: 1 | CK8: =CJ8*CI8*$E8 -> 14.255748 | CL8: =$CL$4*$CM$4 -> 56 | CM8: 1 | CN8: =CM8*CL8*$E8 -> 1995.8047 | CO8: =$CO$4*$CP$4 -> 24 | CP8: 1 | CQ8: =CP8*CO8*$E8 -> 855.34488 | CT8: =CS8*CR8*$E8 -> 0 | CW8: =CV8*CU8*$E8 -> 0 | CZ8: =CY8*CX8*$E8 -> 0 | DC8: =DB8*DA8*$E8 -> 0 | DF8: =DE8*DD8*$E8 -> 0 | DI8: =DH8*DG8*$E8 -> 0 | DL8: =DK8*DJ8*$E8 -> 0 | DO8: =DN8*DM8*$E8 -> 0 | DS8: =($H$3*H8+$K$3*K8+$N$3*N8+$Q$3*Q8+$T$3*T8+$W$3*W8+$Z$3*Z8+$AC$3*AC8+$AF$3*AF8+$AI$3*AI8+$AL$3*AL8+$AO$3*AO8+$AR$3*AR8+$AU$3*AU8+$AX$3*AX8+$BA$3*BA8+$BD$3*BD8+$BG$3*BG8+$BJ$3*BJ8+$BM$3*BM8+$BP$3*BP8+$BS$3*BS8+$BV$3*BV8+$BY$3*BY8+$CB$3*CB8+$CE$3*CE8+$CH$3*CH8+$CK$3*CK8+$CN$3*CN8+$CQ$3*CQ8+$CT$3*CT8+$CW$3*CW8+$CZ$3*CZ8+$DC$3*DC8+$DF$3*DF8+$DI$3*DI8+$DL$3*DL8+$DO$3*DO8) -> 17459.727 | DT8: =DS8/$DS$130 -> 0.03530303
B9: =MO!B5 -> P03 | C9: =MO!C5 -> Ajudante de elétrica | D9: hh | E9: =MO!I5 -> 21.211866 | F9: =$F$4*$G$4 -> 160 | G9: 2 | H9: =G9*F9*$E9 -> 6787.7971 | I9: =$I$4*$J$4 -> 80 | J9: 2 | K9: =J9*I9*$E9 -> 3393.8986 | N9: =M9*L9*$E9 -> 0 | Q9: =P9*O9*$E9 -> 0 | T9: =S9*R9*$E9 -> 0 | W9: =V9*U9*$E9 -> 0 | Z9: =Y9*X9*$E9 -> 0 | AC9: =AB9*AA9*$E9 -> 0 | AF9: =AE9*AD9*$E9 -> 0 | AI9: =AH9*AG9*$E9 -> 0 | AL9: =AK9*AJ9*$E9 -> 0 | AO9: =AN9*AM9*$E9 -> 0 | AR9: =AQ9*AP9*$E9 -> 0 | AU9: =AT9*AS9*$E9 -> 0 | AX9: =AW9*AV9*$E9 -> 0 | BA9: =AZ9*AY9*$E9 -> 0 | BD9: =BC9*BB9*$E9 -> 0 | BG9: =BF9*BE9*$E9 -> 0 | BH9: 0.12 | BI9: 1 | BJ9: =BI9*BH9*$E9 -> 2.5454239 | BK9: 1.26 | BL9: 1 | BM9: =BL9*BK9*$E9 -> 26.726951 | BN9: =$BN$4*$BO$4 -> 16 | BO9: 1 | BP9: =BO9*BN9*$E9 -> 339.38986 | BQ9: =$BQ$4*$BR$4 -> 48 | BR9: 1 | BS9: =BR9*BQ9*$E9 -> 1018.1696 | BT9: =$BT$4*$BU$4 -> 4 | BU9: 1 | BV9: =BU9*BT9*$E9 -> 84.847464 | BW9: =$BW$4*$BX$4 -> 2.56 | BX9: 1 | BY9: =BX9*BW9*$E9 -> 54.302377 | BZ9: =$BZ$4*$CA$4 -> 4.48 | CA9: 1 | CB9: =CA9*BZ9*$E9 -> 95.02916 | CC9: =$CC$4*$CD$4 -> 0.8 | CD9: 1 | CE9: =CD9*CC9*$E9 -> 16.969493 | CF9: =$CF$4*$CG$4 -> 1.2 | CG9: 1 | CH9: =CG9*CF9*$E9 -> 25.454239 | CI9: =$CI$4*$CJ$4 -> 0.4 | CJ9: 1 | CK9: =CJ9*CI9*$E9 -> 8.4847464 | CL9: =$CL$4*$CM$4 -> 56 | CM9: 1 | CN9: =CM9*CL9*$E9 -> 1187.8645 | CO9: =$CO$4*$CP$4 -> 24 | CP9: 1 | CQ9: =CP9*CO9*$E9 -> 509.08478 | CT9: =CS9*CR9*$E9 -> 0 | CW9: =CV9*CU9*$E9 -> 0 | CZ9: =CY9*CX9*$E9 -> 0 | DC9: =DB9*DA9*$E9 -> 0 | DF9: =DE9*DD9*$E9 -> 0 | DI9: =DH9*DG9*$E9 -> 0 | DL9: =DK9*DJ9*$E9 -> 0 | DO9: =DN9*DM9*$E9 -> 0 | DS9: =($H$3*H9+$K$3*K9+$N$3*N9+$Q$3*Q9+$T$3*T9+$W$3*W9+$Z$3*Z9+$AC$3*AC9+$AF$3*AF9+$AI$3*AI9+$AL$3*AL9+$AO$3*AO9+$AR$3*AR9+$AU$3*AU9+$AX$3*AX9+$BA$3*BA9+$BD$3*BD9+$BG$3*BG9+$BJ$3*BJ9+$BM$3*BM9+$BP$3*BP9+$BS$3*BS9+$BV$3*BV9+$BY$3*BY9+$CB$3*CB9+$CE$3*CE9+$CH$3*CH9+$CK$3*CK9+$CN$3*CN9+$CQ$3*CQ9+$CT$3*CT9+$CW$3*CW9+$CZ$3*CZ9+$DC$3*DC9+$DF$3*DF9+$DI$3*DI9+$DL$3*DL9+$DO$3*DO9) -> 15482.541 | DT9: =DS9/$DS$130 -> 0.03130522
B10: =MO!B6 -> P04 | C10: =MO!C6 -> Engenheiro eletricista | D10: hh | E10: =MO!I6 -> 122.13093 | H10: =G10*F10*$E10 -> 0 | K10: =J10*I10*$E10 -> 0 | N10: =M10*L10*$E10 -> 0 | O10: =$O$4*$P$4 -> 112 | P10: 1 | Q10: =P10*O10*$E10 -> 13678.664 | R10: =$R$4*$S$4 -> 56 | S10: 1 | T10: =S10*R10*$E10 -> 6839.3319 | U10: =$U$4*$V$4 -> 24 | V10: 1 | W10: =V10*U10*$E10 -> 2931.1423 | Z10: =Y10*X10*$E10 -> 0 | AA10: =$AA$4*$AB$4 -> 40 | AB10: 0.4 | AC10: =AB10*AA10*$E10 -> 1954.0948 | AD10: =$AD$4*$AE$4 -> 40 | AE10: 0.5 | AF10: =AE10*AD10*$E10 -> 2442.6185 | AG10: =$AG$4*$AH$4 -> 40 | AH10: 0.1 | AI10: =AH10*AG10*$E10 -> 488.52371 | AJ10: =$AJ$4*$AK$4 -> 40 | AK10: 0.55 | AL10: =AK10*AJ10*$E10 -> 2686.8804 | AM10: =$AM$4*$AN$4 -> 64 | AN10: 0.55 | AO10: =AN10*AM10*$E10 -> 4299.0086 | AR10: =AQ10*AP10*$E10 -> 0 | AU10: =AT10*AS10*$E10 -> 0 | AX10: =AW10*AV10*$E10 -> 0 | BA10: =AZ10*AY10*$E10 -> 0 | BD10: =BC10*BB10*$E10 -> 0 | BG10: =BF10*BE10*$E10 -> 0 | BJ10: =BI10*BH10*$E10 -> 0 | BM10: =BL10*BK10*$E10 -> 0 | BN10: 0.15 | BO10: 1 | BP10: =BO10*BN10*$E10 -> 18.319639 | BS10: =BR10*BQ10*$E10 -> 0 | BV10: =BU10*BT10*$E10 -> 0 | BY10: =BX10*BW10*$E10 -> 0 | CB10: =CA10*BZ10*$E10 -> 0 | CE10: =CD10*CC10*$E10 -> 0 | CH10: =CG10*CF10*$E10 -> 0 | CK10: =CJ10*CI10*$E10 -> 0 | CL10: =$CL$4*$CM$4/5 -> 11.2 | CM10: 1 | CN10: =CM10*CL10*$E10 -> 1367.8664 | CQ10: =CP10*CO10*$E10 -> 0 | CT10: =CS10*CR10*$E10 -> 0 | CW10: =CV10*CU10*$E10 -> 0 | CZ10: =CY10*CX10*$E10 -> 0 | DC10: =DB10*DA10*$E10 -> 0 | DF10: =DE10*DD10*$E10 -> 0 | DI10: =DH10*DG10*$E10 -> 0 | DL10: =DK10*DJ10*$E10 -> 0 | DO10: =DN10*DM10*$E10 -> 0 | DS10: =($H$3*H10+$K$3*K10+$N$3*N10+$Q$3*Q10+$T$3*T10+$W$3*W10+$Z$3*Z10+$AC$3*AC10+$AF$3*AF10+$AI$3*AI10+$AL$3*AL10+$AO$3*AO10+$AR$3*AR10+$AU$3*AU10+$AX$3*AX10+$BA$3*BA10+$BD$3*BD10+$BG$3*BG10+$BJ$3*BJ10+$BM$3*BM10+$BP$3*BP10+$BS$3*BS10+$BV$3*BV10+$BY$3*BY10+$CB$3*CB10+$CE$3*CE10+$CH$3*CH10+$CK$3*CK10+$CN$3*CN10+$CQ$3*CQ10+$CT$3*CT10+$CW$3*CW10+$CZ$3*CZ10+$DC$3*DC10+$DF$3*DF10+$DI$3*DI10+$DL$3*DL10+$DO$3*DO10) -> 36706.45 | DT10: =DS10/$DS$130 -> 0.07421931
B11: =MO!B7 -> P05 | C11: =MO!C7 -> Engenheiro mecânico - Especialista em estruturas metálicas | D11: hh | E11: =MO!I7 -> 122.13093 | H11: =G11*F11*$E11 -> 0 | K11: =J11*I11*$E11 -> 0 | N11: =M11*L11*$E11 -> 0 | Q11: =P11*O11*$E11 -> 0 | T11: =S11*R11*$E11 -> 0 | U11: =$U$4*$V$4 -> 24 | V11: 1 | W11: =V11*U11*$E11 -> 2931.1423 | Z11: =Y11*X11*$E11 -> 0 | AA11: =$AA$4*$AB$4 -> 40 | AB11: 0.6 | AC11: =AB11*AA11*$E11 -> 2931.1423 | AD11: =$AD$4*$AE$4 -> 40 | AE11: 0.5 | AF11: =AE11*AD11*$E11 -> 2442.6185 | AG11: =$AG$4*$AH$4 -> 40 | AH11: 0.9 | AI11: =AH11*AG11*$E11 -> 4396.7134 | AJ11: =$AJ$4*$AK$4 -> 40 | AK11: 0.45 | AL11: =AK11*AJ11*$E11 -> 2198.3567 | AM11: =$AM$4*$AN$4 -> 64 | AN11: 0.45 | AO11: =AN11*AM11*$E11 -> 3517.3707 | AR11: =AQ11*AP11*$E11 -> 0 | AU11: =AT11*AS11*$E11 -> 0 | AX11: =AW11*AV11*$E11 -> 0 | BA11: =AZ11*AY11*$E11 -> 0 | BD11: =BC11*BB11*$E11 -> 0 | BG11: =BF11*BE11*$E11 -> 0 | BJ11: =BI11*BH11*$E11 -> 0 | BM11: =BL11*BK11*$E11 -> 0 | BN11: 0.15 | BO11: 1 | BP11: =BO11*BN11*$E11 -> 18.319639 | BS11: =BR11*BQ11*$E11 -> 0 | BV11: =BU11*BT11*$E11 -> 0 | BY11: =BX11*BW11*$E11 -> 0 | CB11: =CA11*BZ11*$E11 -> 0 | CE11: =CD11*CC11*$E11 -> 0 | CH11: =CG11*CF11*$E11 -> 0 | CK11: =CJ11*CI11*$E11 -> 0 | CL11: =$CL$4*$CM$4/5 -> 11.2 | CM11: 1 | CN11: =CM11*CL11*$E11 -> 1367.8664 | CQ11: =CP11*CO11*$E11 -> 0 | CT11: =CS11*CR11*$E11 -> 0 | CW11: =CV11*CU11*$E11 -> 0 | CZ11: =CY11*CX11*$E11 -> 0 | DC11: =DB11*DA11*$E11 -> 0 | DF11: =DE11*DD11*$E11 -> 0 | DI11: =DH11*DG11*$E11 -> 0 | DL11: =DK11*DJ11*$E11 -> 0 | DO11: =DN11*DM11*$E11 -> 0 | DS11: =($H$3*H11+$K$3*K11+$N$3*N11+$Q$3*Q11+$T$3*T11+$W$3*W11+$Z$3*Z11+$AC$3*AC11+$AF$3*AF11+$AI$3*AI11+$AL$3*AL11+$AO$3*AO11+$AR$3*AR11+$AU$3*AU11+$AX$3*AX11+$BA$3*BA11+$BD$3*BD11+$BG$3*BG11+$BJ$3*BJ11+$BM$3*BM11+$BP$3*BP11+$BS$3*BS11+$BV$3*BV11+$BY$3*BY11+$CB$3*CB11+$CE$3*CE11+$CH$3*CH11+$CK$3*CK11+$CN$3*CN11+$CQ$3*CQ11+$CT$3*CT11+$CW$3*CW11+$CZ$3*CZ11+$DC$3*DC11+$DF$3*DF11+$DI$3*DI11+$DL$3*DL11+$DO$3*DO11) -> 19803.53 | DT11: =DS11/$DS$130 -> 0.040042126
B12: =MO!B8 -> P06 | C12: =MO!C8 -> Projetista (Cadista) | D12: hh | E12: =MO!I8 -> 28.525909 | H12: =G12*F12*$E12 -> 0 | K12: =J12*I12*$E12 -> 0 | N12: =M12*L12*$E12 -> 0 | O12: =$O$4*$P$4 -> 112 | P12: 1 | Q12: =P12*O12*$E12 -> 3194.9018 | R12: =$R$4*$S$4 -> 56 | S12: 1 | T12: =S12*R12*$E12 -> 1597.4509 | W12: =V12*U12*$E12 -> 0 | Z12: =Y12*X12*$E12 -> 0 | AC12: =AB12*AA12*$E12 -> 0 | AF12: =AE12*AD12*$E12 -> 0 | AI12: =AH12*AG12*$E12 -> 0 | AL12: =AK12*AJ12*$E12 -> 0 | AM12: =$AM$4*$AN$4 -> 64 | AN12: 0.25 | AO12: =AN12*AM12*$E12 -> 456.41455 | AR12: =AQ12*AP12*$E12 -> 0 | AU12: =AT12*AS12*$E12 -> 0 | AX12: =AW12*AV12*$E12 -> 0 | BA12: =AZ12*AY12*$E12 -> 0 | BD12: =BC12*BB12*$E12 -> 0 | BG12: =BF12*BE12*$E12 -> 0 | BJ12: =BI12*BH12*$E12 -> 0 | BM12: =BL12*BK12*$E12 -> 0 | BN12: 0.15 | BO12: 1 | BP12: =BO12*BN12*$E12 -> 4.2788864 | BS12: =BR12*BQ12*$E12 -> 0 | BV12: =BU12*BT12*$E12 -> 0 | BY12: =BX12*BW12*$E12 -> 0 | CB12: =CA12*BZ12*$E12 -> 0 | CE12: =CD12*CC12*$E12 -> 0 | CH12: =CG12*CF12*$E12 -> 0 | CK12: =CJ12*CI12*$E12 -> 0 | CN12: =CM12*CL12*$E12 -> 0 | CQ12: =CP12*CO12*$E12 -> 0 | CT12: =CS12*CR12*$E12 -> 0 | CW12: =CV12*CU12*$E12 -> 0 | CZ12: =CY12*CX12*$E12 -> 0 | DC12: =DB12*DA12*$E12 -> 0 | DF12: =DE12*DD12*$E12 -> 0 | DI12: =DH12*DG12*$E12 -> 0 | DL12: =DK12*DJ12*$E12 -> 0 | DO12: =DN12*DM12*$E12 -> 0 | DS12: =($H$3*H12+$K$3*K12+$N$3*N12+$Q$3*Q12+$T$3*T12+$W$3*W12+$Z$3*Z12+$AC$3*AC12+$AF$3*AF12+$AI$3*AI12+$AL$3*AL12+$AO$3*AO12+$AR$3*AR12+$AU$3*AU12+$AX$3*AX12+$BA$3*BA12+$BD$3*BD12+$BG$3*BG12+$BJ$3*BJ12+$BM$3*BM12+$BP$3*BP12+$BS$3*BS12+$BV$3*BV12+$BY$3*BY12+$CB$3*CB12+$CE$3*CE12+$CH$3*CH12+$CK$3*CK12+$CN$3*CN12+$CQ$3*CQ12+$CT$3*CT12+$CW$3*CW12+$CZ$3*CZ12+$DC$3*DC12+$DF$3*DF12+$DI$3*DI12+$DL$3*DL12+$DO$3*DO12) -> 5253.0462 | DT12: =DS12/$DS$130 -> 0.010621497
B13: =MO!B9 -> P07 | C13: =MO!C9 -> Alpinista industrial (Montador de andaime) | D13: hh | E13: =MO!I9 -> 34.667187 | F13: =$F$4*$G$4 -> 160 | G13: 1 | H13: =G13*F13*$E13 -> 5546.7499 | I13: =$I$4*$J$4 -> 80 | J13: 1 | K13: =J13*I13*$E13 -> 2773.375 | N13: =M13*L13*$E13 -> 0 | Q13: =P13*O13*$E13 -> 0 | T13: =S13*R13*$E13 -> 0 | W13: =V13*U13*$E13 -> 0 | Z13: =Y13*X13*$E13 -> 0 | AC13: =AB13*AA13*$E13 -> 0 | AF13: =AE13*AD13*$E13 -> 0 | AI13: =AH13*AG13*$E13 -> 0 | AL13: =AK13*AJ13*$E13 -> 0 | AO13: =AN13*AM13*$E13 -> 0 | AR13: =AQ13*AP13*$E13 -> 0 | AU13: =AT13*AS13*$E13 -> 0 | AX13: =AW13*AV13*$E13 -> 0 | BA13: =AZ13*AY13*$E13 -> 0 | BD13: =BC13*BB13*$E13 -> 0 | BG13: =BF13*BE13*$E13 -> 0 | BJ13: =BI13*BH13*$E13 -> 0 | BM13: =BL13*BK13*$E13 -> 0 | BN13: =$BN$4*$BO$4 -> 16 | BO13: 1 | BP13: =BO13*BN13*$E13 -> 554.67499 | BQ13: =$BQ$4*$BR$4 -> 48 | BR13: 1 | BS13: =BR13*BQ13*$E13 -> 1664.025 | BV13: =BU13*BT13*$E13 -> 0 | BY13: =BX13*BW13*$E13 -> 0 | CB13: =CA13*BZ13*$E13 -> 0 | CE13: =CD13*CC13*$E13 -> 0 | CH13: =CG13*CF13*$E13 -> 0 | CK13: =CJ13*CI13*$E13 -> 0 | CN13: =CM13*CL13*$E13 -> 0 | CQ13: =CP13*CO13*$E13 -> 0 | CT13: =CS13*CR13*$E13 -> 0 | CW13: =CV13*CU13*$E13 -> 0 | CZ13: =CY13*CX13*$E13 -> 0 | DC13: =DB13*DA13*$E13 -> 0 | DD13: =$DD$4*$DE$4 -> 16 | DE13: 1 | DF13: =DE13*DD13*$E13 -> 554.67499 | DG13: =$DG$4*$DH$4 -> 12 | DH13: 1 | DI13: =DH13*DG13*$E13 -> 416.00624 | DJ13: =$DJ$4*$DK$4 -> 40 | DK13: 1 | DL13: =DK13*DJ13*$E13 -> 1386.6875 | DM13: =$DM$4*$DN$4 -> 24 | DN13: 1 | DO13: =DN13*DM13*$E13 -> 832.01249 | DS13: =($H$3*H13+$K$3*K13+$N$3*N13+$Q$3*Q13+$T$3*T13+$W$3*W13+$Z$3*Z13+$AC$3*AC13+$AF$3*AF13+$AI$3*AI13+$AL$3*AL13+$AO$3*AO13+$AR$3*AR13+$AU$3*AU13+$AX$3*AX13+$BA$3*BA13+$BD$3*BD13+$BG$3*BG13+$BJ$3*BJ13+$BM$3*BM13+$BP$3*BP13+$BS$3*BS13+$BV$3*BV13+$BY$3*BY13+$CB$3*CB13+$CE$3*CE13+$CH$3*CH13+$CK$3*CK13+$CN$3*CN13+$CQ$3*CQ13+$CT$3*CT13+$CW$3*CW13+$CZ$3*CZ13+$DC$3*DC13+$DF$3*DF13+$DI$3*DI13+$DL$3*DL13+$DO$3*DO13) -> 13728.206 | DT13: =DS13/$DS$130 -> 0.027758009
B14: =MO!B10 -> P08 | C14: =MO!C10 -> Encarregado de elétrica ou andaimes | D14: hh | E14: =MO!I10 -> 42.538636 | F14: =$F$4*$G$4 -> 160 | G14: 1 | H14: =G14*F14*$E14 -> 6806.1818 | I14: =$I$4*$J$4 -> 80 | J14: 1 | K14: =J14*I14*$E14 -> 3403.0909 | N14: =M14*L14*$E14 -> 0 | Q14: =P14*O14*$E14 -> 0 | T14: =S14*R14*$E14 -> 0 | W14: =V14*U14*$E14 -> 0 | Z14: =Y14*X14*$E14 -> 0 | AC14: =AB14*AA14*$E14 -> 0 | AF14: =AE14*AD14*$E14 -> 0 | AI14: =AH14*AG14*$E14 -> 0 | AL14: =AK14*AJ14*$E14 -> 0 | AO14: =AN14*AM14*$E14 -> 0 | AR14: =AQ14*AP14*$E14 -> 0 | AU14: =AT14*AS14*$E14 -> 0 | AX14: =AW14*AV14*$E14 -> 0 | BA14: =AZ14*AY14*$E14 -> 0 | BD14: =BC14*BB14*$E14 -> 0 | BG14: =BF14*BE14*$E14 -> 0 | BJ14: =BI14*BH14*$E14 -> 0 | BM14: =BL14*BK14*$E14 -> 0 | BN14: =$BN$4*$BO$4 -> 16 | BO14: 1 | BP14: =BO14*BN14*$E14 -> 680.61818 | BQ14: =$BQ$4*$BR$4 -> 48 | BR14: 1 | BS14: =BR14*BQ14*$E14 -> 2041.8545 | BT14: =$BT$4*$BU$4 -> 4 | BU14: 1 | BV14: =BU14*BT14*$E14 -> 170.15455 | BW14: =$BW$4*$BX$4 -> 2.56 | BX14: 1 | BY14: =BX14*BW14*$E14 -> 108.89891 | BZ14: =$BZ$4*$CA$4 -> 4.48 | CA14: 1 | CB14: =CA14*BZ14*$E14 -> 190.57309 | CC14: =$CC$4*$CD$4 -> 0.8 | CD14: 1 | CE14: =CD14*CC14*$E14 -> 34.030909 | CF14: =$CF$4*$CG$4 -> 1.2 | CG14: 1 | CH14: =CG14*CF14*$E14 -> 51.046364 | CI14: =$CI$4*$CJ$4 -> 0.4 | CJ14: 1 | CK14: =CJ14*CI14*$E14 -> 17.015455 | CL14: =$CL$4*$CM$4 -> 56 | CM14: 1 | CN14: =CM14*CL14*$E14 -> 2382.1636 | CO14: =$CO$4*$CP$4 -> 24 | CP14: 1 | CQ14: =CP14*CO14*$E14 -> 1020.9273 | CT14: =CS14*CR14*$E14 -> 0 | CW14: =CV14*CU14*$E14 -> 0 | CZ14: =CY14*CX14*$E14 -> 0 | DC14: =DB14*DA14*$E14 -> 0 | DD14: =$DD$4*$DE$4 -> 16 | DE14: 1 | DF14: =DE14*DD14*$E14 -> 680.61818 | DG14: =$DG$4*$DH$4 -> 12 | DH14: 1 | DI14: =DH14*DG14*$E14 -> 510.46364 | DJ14: =$DJ$4*$DK$4 -> 40 | DK14: 1 | DL14: =DK14*DJ14*$E14 -> 1701.5455 | DM14: =$DM$4*$DN$4 -> 24 | DN14: 1 | DO14: =DN14*DM14*$E14 -> 1020.9273 | DS14: =($H$3*H14+$K$3*K14+$N$3*N14+$Q$3*Q14+$T$3*T14+$W$3*W14+$Z$3*Z14+$AC$3*AC14+$AF$3*AF14+$AI$3*AI14+$AL$3*AL14+$AO$3*AO14+$AR$3*AR14+$AU$3*AU14+$AX$3*AX14+$BA$3*BA14+$BD$3*BD14+$BG$3*BG14+$BJ$3*BJ14+$BM$3*BM14+$BP$3*BP14+$BS$3*BS14+$BV$3*BV14+$BY$3*BY14+$CB$3*CB14+$CE$3*CE14+$CH$3*CH14+$CK$3*CK14+$CN$3*CN14+$CQ$3*CQ14+$CT$3*CT14+$CW$3*CW14+$CZ$3*CZ14+$DC$3*DC14+$DF$3*DF14+$DI$3*DI14+$DL$3*DL14+$DO$3*DO14) -> 24189.17 | DT14: =DS14/$DS$130 -> 0.048909756
