Workbook
Name \0: #REF!
Name \0: #REF!
Name \0: #REF!
Name \A: #REF!
Name \A: #REF!
Name \A: #REF!
Name \b: #REF!
Name \b: #REF!
Name \b: #REF!
Name \c: #REF!
Name \c: #REF!
Name \c: #REF!
Name \F: #REF!
Name \F: #REF!
Name \G: #REF!
Name \G: #REF!
Name \h: #REF!
Name \h: #REF!
Name \L: #REF!
Name \L: #REF!
Name \n: #REF!
Name \n: #REF!
Name \O: #REF!
Name \O: #REF!
Name \P: #REF!
Name \P: #REF!
Name \Q: #REF!
Name \Q: #REF!
Name \R: #REF!
Name \R: #REF!
Name \s: #REF!
Name \s: #REF!
Name \t: #REF!
Name \t: #REF!
Name \V: #REF!
Name \V: #REF!
Name \w: #REF!
Name \w: #REF!
Name \x: #N/A
Name \y: #REF!
Name \y: #REF!
Name \z: #N/A
Name _________________________________mm1: #REF!
Name _________________________________mm1: QQP!_________________________________mm1
Name _________________________________mm1: #REF!
Name ________________________________mm1: #REF!
Name ________________________________mm1: QQP!________________________________mm1
Name ________________________________mm1: #REF!
Name _______________________________mm1: #REF!
Name _______________________________mm1: QQP!_______________________________mm1
Name _______________________________mm1: #REF!
Name ______________________________mm1: #REF!
Name ______________________________mm1: QQP!______________________________mm1
Name ______________________________mm1: #REF!
Name _____________________________mm1: #REF!
Name _____________________________mm1: QQP!_____________________________mm1
Name _____________________________mm1: #REF!
Name ____________________________mm1: #REF!
Name ____________________________mm1: QQP!____________________________mm1
Name ____________________________mm1: #REF!

Sheet APR
C1: ANÁLISE DE RISCO | R1: PRO-000-24
R2: DATA: | S2: 45292
B4: 1ª ETAPA - ANÁLISE PRELIMINAR DE RISCO
B5: Nome do Contrato: | C5: PRO-021-24 - ALUMAR - RDC 4573033 SUBSTITUIÇÃO MÓDULO 08 CORREIA TRANSPORTADORA - 07 - O | M5: Dono do Risco: | O5: Márcio Lopes | Q5: Cliente: | R5: Tamires Paula
B6: Missão do Contrato: | C6: Contratação de empresa especializada para execução da substituição do módulo 08 da correia transportadora C-01 | M6: Prazo (dias): | N6: =30*5 -> 150 | O6: Prazo pgto (dd): | P6: 64 | Q6: Local: | R6: Porto
B7: ESTIMATIVA FINANCEIRAS
B8: Valor Estimado | C8: =R8*T8 -> 0 | D8: Nr. De Pessoas | F8: Custo M.obra | I8: Custo Equipam. | M8: Custo Consumiveis | O8: Outros | Q8: Custo Total | R8: =G8+J8+N8+P8 -> 0 | S8: K | T8: 1.72
B9: OBSERVAÇÕES
B12: 2ª ETAPA - ANÁLISE DE RISCO
B14: Riscos a Verificar
C17: Criterio de Avaliação do Nivel do Risco | AF17: Nota | AG17: Probabilidade | AH17: NR | AI17: NR
C18: Probabilidade do Risco Acontecer | E18: NR | G18: Nota | AF18: 1 | AG18: QUASE CERTO | AH18: Risco Alto | AI18: Alto | AK18: GRÁFICO | AQ18: VERMELHO | AT18: AMARELO | AW18: VERDE
C19: QUASE CERTO | E19: Alto | G19: 1 a 2,5 | AF19: 2 | AG19: QUASE CERTO | AH19: Risco Alto | AI19: Alto | AK19: =B26 -> Tipo de Riscos | AL19: Nivel | AM19: Vermelho | AN19: Amarelo | AO19: Verde | AQ19: =AK19 -> Tipo de Riscos | AR19: =" " | AT19: =AK19 -> Tipo de Riscos | AU19: =" " | AW19: =AK19 -> Tipo de Riscos | AX19: =" "
C20: MUITO PROVÁVEL | E20: Alto | G20: 2,6 a 4,9 | AF20: 2.5 | AG20: QUASE CERTO | AH20: Risco Alto | AI20: Alto | AJ20: 1 | AK20: =B27 -> 1-FINANCEIRO (Fluxo de caixa) | AL20: =F27 -> 3 | AM20: =IF(AL20<=4.9,AL20,"") -> 3 | AN20: =IF(AND(AL20>4.9,AL20<=8.5),AL20,"") | AO20: =IF(AL20>=8.6,AL20,"") | AQ20: =AK20 -> 1-FINANCEIRO (Fluxo de caixa) | AR20: =AM20 -> 3 | AT20: =AK20 -> 1-FINANCEIRO (Fluxo de caixa) | AU20: =AN20 | AW20: =AK20 -> 1-FINANCEIRO (Fluxo de caixa) | AX20: =AO20
C21: PROVÁVEL | E21: Médio | G21: 5 a 7,4 | AF21: 2.6 | AG21: MUITO PROVÁVEL | AH21: Risco Alto | AI21: Alto | AJ21: 2 | AK21: =B29 -> 2-CALOTE (SERASA) | AL21: =F29 -> 9 | AM21: =IF(AL21<=4.9,AL21,"") | AN21: =IF(AND(AL21>4.9,AL21<=8.5),AL21,"") | AO21: =IF(AL21>=8.6,AL21,"") -> 9 | AQ21: =AK21 -> 2-CALOTE (SERASA) | AR21: =AM21 | AT21: =AK21 -> 2-CALOTE (SERASA) | AU21: =AN21 | AW21: =AK21 -> 2-CALOTE (SERASA) | AX21: =AO21 -> 9
C22: POUCO PROVÁVEL | E22: Médio | G22: 7,5 a 8,5 | AF22: 3 | AG22: MUITO PROVÁVEL | AH22: Risco Alto | AI22: Alto | AJ22: 3 | AK22: =B31 -> 3-NIVEL DE COMPLEXIDADE | AL22: =F31 -> 1 | AM22: =IF(AL22<=4.9,AL22,"") -> 1 | AN22: =IF(AND(AL22>4.9,AL22<=8.5),AL22,"") | AO22: =IF(AL22>=8.6,AL22,"") | AQ22: =AK22 -> 3-NIVEL DE COMPLEXIDADE | AR22: =AM22 -> 1 | AT22: =AK22 -> 3-NIVEL DE COMPLEXIDADE | AU22: =AN22 | AW22: =AK22 -> 3-NIVEL DE COMPLEXIDADE | AX22: =AO22
C23: IMPROVÁVEL | E23: Baixo | G23: 8,6 a 9,3 | AF23: 4 | AG23: MUITO PROVÁVEL | AH23: Risco Alto | AI23: Alto | AJ23: 4 | AK23: =B33 -> 4-CAPACIDADE TÉCNICA | AL23: =F33 -> 1 | AM23: =IF(AL23<=4.9,AL23,"") -> 1 | AN23: =IF(AND(AL23>4.9,AL23<=8.5),AL23,"") | AO23: =IF(AL23>=8.6,AL23,"") | AQ23: =AK23 -> 4-CAPACIDADE TÉCNICA | AR23: =AM23 -> 1 | AT23: =AK23 -> 4-CAPACIDADE TÉCNICA | AU23: =AN23 | AW23: =AK23 -> 4-CAPACIDADE TÉCNICA | AX23: =AO23
C24: RARO | E24: Baixo | G24: 9,4 a 10 | AF24: 4.9 | AG24: MUITO PROVÁVEL | AH24: Risco Alto | AI24: Alto | AJ24: 5 | AK24: =B35 -> 5-SSMA | AL24: =F35 -> 6 | AM24: =IF(AL24<=4.9,AL24,"") | AN24: =IF(AND(AL24>4.9,AL24<=8.5),AL24,"") -> 6 | AO24: =IF(AL24>=8.6,AL24,"") | AQ24: =AK24 -> 5-SSMA | AR24: =AM24 | AT24: =AK24 -> 5-SSMA | AU24: =AN24 -> 6 | AW24: =AK24 -> 5-SSMA | AX24: =AO24
B25: Quanto maior a probabilidade do risco, menor a Nota atribuída e vice versa. | AF25: 5 | AG25: PROVÁVEL | AH25: Risco Médio | AI25: Médio | AJ25: 6 | AK25: =B37 -> 6-RISCO DE NÃO ACONTECER | AL25: =F37 -> 6 | AM25: =IF(AL25<=4.9,AL25,"") | AN25: =IF(AND(AL25>4.9,AL25<=8.5),AL25,"") -> 6 | AO25: =IF(AL25>=8.6,AL25,"") | AQ25: =AK25 -> 6-RISCO DE NÃO ACONTECER | AR25: =AM25 | AT25: =AK25 -> 6-RISCO DE NÃO ACONTECER | AU25: =AN25 -> 6 | AW25: =AK25 -> 6-RISCO DE NÃO ACONTECER | AX25: =AO25
B26: Tipo de Riscos | D26: Peso da Consequencia | E26: Nivel de Risco | I26: Yield | AF26: 6 | AG26: PROVÁVEL | AH26: Risco Médio | AI26: Médio | AJ26: 7 | AK26: =B39 -> 7-DISPONIBILIDADE DE RECURSOS (Mercado) | AL26: =F39 -> 4 | AM26: =IF(AL26<=4.9,AL26,"") -> 4 | AN26: =IF(AND(AL26>4.9,AL26<=8.5),AL26,"") | AO26: =IF(AL26>=8.6,AL26,"") | AQ26: =AK26 -> 7-DISPONIBILIDADE DE RECURSOS (Mercado) | AR26: =AM26 -> 4 | AT26: =AK26 -> 7-DISPONIBILIDADE DE RECURSOS (Mercado) | AU26: =AN26 | AW26: =AK26 -> 7-DISPONIBILIDADE DE RECURSOS (Mercado) | AX26: =AO26
B27: 1-FINANCEIRO (Fluxo de caixa) | D27: 2.5 | F27: 3 | H27: =VLOOKUP(F27,$AF$18:$AI$36,3,TRUE) -> Risco Alto | M27: Observações gerais a serem contempladas na APR | AF27: 7 | AG27: PROVÁVEL | AH27: Risco Médio | AI27: Médio | AJ27: 8 | AK27: =B41 -> 8-COMPETITIVIDADE (Concorrentes) | AL27: =F41 -> 2 | AM27: =IF(AL27<=4.9,AL27,"") -> 2 | AN27: =IF(AND(AL27>4.9,AL27<=8.5),AL27,"") | AO27: =IF(AL27>=8.6,AL27,"") | AQ27: =AK27 -> 8-COMPETITIVIDADE (Concorrentes) | AR27: =AM27 -> 2 | AT27: =AK27 -> 8-COMPETITIVIDADE (Concorrentes) | AU27: =AN27 | AW27: =AK27 -> 8-COMPETITIVIDADE (Concorrentes) | AX27: =AO27
M28: A Projeta não dispõe da expertise necessária para seguir com o processo e o nível de complexidade para o prazo requerido não possibilita a tentativa de participar do processo sem maiores riscos. | AF28: 7.4 | AG28: PROVÁVEL | AH28: Risco Médio | AI28: Médio | AJ28: 9 | AK28: =B43 -> 9-HH PARADO/EQUIPAMENTO | AL28: =F43 -> 2 | AM28: =IF(AL28<=4.9,AL28,"") -> 2 | AN28: =IF(AND(AL28>4.9,AL28<=8.5),AL28,"") | AO28: =IF(AL28>=8.6,AL28,"") | AQ28: =AK28 -> 9-HH PARADO/EQUIPAMENTO | AR28: =AM28 -> 2 | AT28: =AK28 -> 9-HH PARADO/EQUIPAMENTO | AU28: =AN28 | AW28: =AK28 -> 9-HH PARADO/EQUIPAMENTO | AX28: =AO28
B29: 2-CALOTE (SERASA) | D29: 2 | F29: 9 | H29: =VLOOKUP(F29,$AF$18:$AI$36,3,TRUE) -> Risco Baixo | I29: =ROUND((D27*F27+D29*F29+D31*F31+D33*F33+D35*F35+D37*F37+D41*F41+D43*F43+D45*F45+D47*F47+D39*F39+D51*F51+D53*F53+D49*F49)/D56,1) -> 4.7 | AF29: 7.5 | AG29: POUCO PROVÁVEL | AH29: Risco Médio | AI29: Médio | AJ29: 10 | AK29: =B45 -> 10-LOGISTICA | AL29: =F45 -> 1 | AM29: =IF(AL29<=4.9,AL29,"") -> 1 | AN29: =IF(AND(AL29>4.9,AL29<=8.5),AL29,"") | AO29: =IF(AL29>=8.6,AL29,"") | AQ29: =AK29 -> 10-LOGISTICA | AR29: =AM29 -> 1 | AT29: =AK29 -> 10-LOGISTICA | AU29: =AN29 | AW29: =AK29 -> 10-LOGISTICA | AX29: =AO29
AF30: 8 | AG30: POUCO PROVÁVEL | AH30: Risco Médio | AI30: Médio | AJ30: 11 | AK30: =B47 -> 11-NOTIFICAÇÕES E MULTAS | AL30: =F47 -> 8.6 | AM30: =IF(AL30<=4.9,AL30,"") | AN30: =IF(AND(AL30>4.9,AL30<=8.5),AL30,"") | AO30: =IF(AL30>=8.6,AL30,"") -> 8.6 | AQ30: =AK30 -> 11-NOTIFICAÇÕES E MULTAS | AR30: =AM30 | AT30: =AK30 -> 11-NOTIFICAÇÕES E MULTAS | AU30: =AN30 | AW30: =AK30 -> 11-NOTIFICAÇÕES E MULTAS | AX30: =AO30 -> 8.6
B31: 3-NIVEL DE COMPLEXIDADE | D31: 0.5 | F31: 1 | H31: =VLOOKUP(F31,$AF$18:$AI$36,3,TRUE) -> Risco Alto | AF31: 8.5 | AG31: POUCO PROVÁVEL | AH31: Risco Médio | AI31: Médio | AJ31: 12 | AK31: =B49 -> 12-PRAZO DE ELABORAÇÃO PROPOSTA | AL31: =F49 -> 3 | AM31: =IF(AL31<=4.9,AL31,"") -> 3 | AN31: =IF(AND(AL31>4.9,AL31<=8.5),AL31,"") | AO31: =IF(AL31>=8.6,AL31,"") | AQ31: =AK31 -> 12-PRAZO DE ELABORAÇÃO PROPOSTA | AR31: =AM31 -> 3 | AT31: =AK31 -> 12-PRAZO DE ELABORAÇÃO PROPOSTA | AU31: =AN31 | AW31: =AK31 -> 12-PRAZO DE ELABORAÇÃO PROPOSTA | AX31: =AO31
AF32: 8.6 | AG32: IMPROVÁVEL | AH32: Risco Baixo | AI32: Baixo | AJ32: 13 | AK32: =B51 -> 13-PRAZO DE EXECUÇÃO | AL32: =F51 -> 7 | AM32: =IF(AL32<=4.9,AL32,"") | AN32: =IF(AND(AL32>4.9,AL32<=8.5),AL32,"") -> 7 | AO32: =IF(AL32>=8.6,AL32,"") | AQ32: =AK32 -> 13-PRAZO DE EXECUÇÃO | AR32: =AM32 | AT32: =AK32 -> 13-PRAZO DE EXECUÇÃO | AU32: =AN32 -> 7 | AW32: =AK32 -> 13-PRAZO DE EXECUÇÃO | AX32: =AO32
B33: 4-CAPACIDADE TÉCNICA | D33: 0.5 | F33: 1 | H33: =VLOOKUP(F33,$AF$18:$AI$36,3,TRUE) -> Risco Alto | AF33: 9 | AG33: IMPROVÁVEL | AH33: Risco Baixo | AI33: Baixo | AJ33: 14 | AK33: =B53 -> 14-LEILÃO | AL33: =F53 -> 7 | AM33: =IF(AL33<=4.9,AL33,"") | AN33: =IF(AND(AL33>4.9,AL33<=8.5),AL33,"") -> 7 | AO33: =IF(AL33>=8.6,AL33,"") | AQ33: =AK33 -> 14-LEILÃO | AR33: =AM33 | AT33: =AK33 -> 14-LEILÃO | AU33: =AN33 -> 7 | AW33: =AK33 -> 14-LEILÃO | AX33: =AO33
AF34: 9.3 | AG34: IMPROVÁVEL | AH34: Risco Baixo | AI34: Baixo
B35: 5-SSMA | D35: 0.5 | F35: 6 | H35: =VLOOKUP(F35,$AF$18:$AI$36,3,TRUE) -> Risco Médio | AF35: 9.4 | AG35: RARO | AH35: Risco Baixo | AI35: Baixo
AF36: 10 | AG36: RARO | AH36: Risco Baixo | AI36: Baixo
B37: 6-RISCO DE NÃO ACONTECER | D37: 0.3 | F37: 6 | H37: =VLOOKUP(F37,$AF$18:$AI$36,3,TRUE) -> Risco Médio
B39: 7-DISPONIBILIDADE DE RECURSOS (Mercado) | D39: 0.5 | F39: 4 | H39: =VLOOKUP(F39,$AF$18:$AI$36,3,TRUE) -> Risco Alto
B41: 8-COMPETITIVIDADE (Concorrentes) | D41: 0.5 | F41: 2 | H41: =VLOOKUP(F41,$AF$18:$AI$36,3,TRUE) -> Risco Alto | I41: Nível de Risco:
B43: 9-HH PARADO/EQUIPAMENTO | D43: 0.5 | F43: 2 | H43: =VLOOKUP(F43,$AF$18:$AI$36,3,TRUE) -> Risco Alto | I43: =VLOOKUP(I29,AF18:AI36,4,TRUE) -> Alto
B45: 10-LOGISTICA | D45: 0.5 | F45: 1 | H45: =VLOOKUP(F45,$AF$18:$AI$36,3,TRUE) -> Risco Alto
B47: 11-NOTIFICAÇÕES E MULTAS | D47: 0.5 | F47: 8.6 | H47: =VLOOKUP(F47,$AF$18:$AI$36,3,TRUE) -> Risco Baixo
B49: 12-PRAZO DE ELABORAÇÃO PROPOSTA | D49: 0.5 | F49: 3 | H49: =VLOOKUP(F49,$AF$18:$AI$36,3,TRUE) -> Risco Alto
B51: 13-PRAZO DE EXECUÇÃO | D51: 0.5 | F51: 7 | H51: =VLOOKUP(F51,$AF$18:$AI$36,3,TRUE) -> Risco Médio
B53: 14-LEILÃO | D53: 0.2 | F53: 7 | H53: =VLOOKUP(F53,$AF$18:$AI$36,3,TRUE) -> Risco Médio
D56: =SUM(D27:D55) -> 10
...

Sheet CHECK
B1: =QQP!G44 -> 0
G2: CHECK
B5: A - Mão de Obra + Encargos
B6: Cód. | C6: Discriminação | D6: Unid | E6: P.Unit | G6: Quant | H6: F.utiliz | I6: Custo
B7: ='CPU 1'!B7 -> P01 | C7: ='CPU 1'!C7 -> Supervisor | D7: ='CPU 1'!D7 -> hh | E7: ='CPU 1'!E7 -> 75.068182 | I7: ='CPU 1'!AG7+'CPU 2'!O7+'CPU 3'!AA7+'CPU 4'!AA7+'CPU 5'!U7 -> 0 | J7: =I7/$I$162 -> #DIV/0!
B8: ='CPU 1'!B8 -> P02 | C8: ='CPU 1'!C8 -> Encarregado | D8: ='CPU 1'!D8 -> hh | E8: ='CPU 1'!E8 -> 40.036364 | I8: ='CPU 1'!AG8+'CPU 2'!O8+'CPU 3'!AA8+'CPU 4'!AA8+'CPU 5'!U8 -> 0 | J8: =I8/$I$162 -> #DIV/0!
B9: ='CPU 1'!B9 -> P03 | C9: ='CPU 1'!C9 -> Técnico SSMA | D9: ='CPU 1'!D9 -> hh | E9: ='CPU 1'!E9 -> 40.036364 | I9: ='CPU 1'!AG9+'CPU 2'!O9+'CPU 3'!AA9+'CPU 4'!AA9+'CPU 5'!U9 -> 0 | J9: =I9/$I$162 -> #DIV/0!
B10: ='CPU 1'!B10 -> P04 | C10: ='CPU 1'!C10 -> Pedreiro | D10: ='CPU 1'!D10 -> hh | E10: ='CPU 1'!E10 -> 19.767955 | I10: ='CPU 1'!AG10+'CPU 2'!O10+'CPU 3'!AA10+'CPU 4'!AA10+'CPU 5'!U10 -> 0 | J10: =I10/$I$162 -> #DIV/0!
B11: ='CPU 1'!B11 -> P05 | C11: ='CPU 1'!C11 -> Carpinteiro | D11: ='CPU 1'!D11 -> hh | E11: ='CPU 1'!E11 -> 19.767955 | I11: ='CPU 1'!AG11+'CPU 2'!O11+'CPU 3'!AA11+'CPU 4'!AA11+'CPU 5'!U11 -> 0 | J11: =I11/$I$162 -> #DIV/0!
B12: ='CPU 1'!B12 -> P06 | C12: ='CPU 1'!C12 -> Eletricista | D12: ='CPU 1'!D12 -> hh | E12: ='CPU 1'!E12 -> 26.023636 | I12: ='CPU 1'!AG12+'CPU 2'!O12+'CPU 3'!AA12+'CPU 4'!AA12+'CPU 5'!U12 -> 0 | J12: =I12/$I$162 -> #DIV/0!
B13: ='CPU 1'!B13 -> P07 | C13: ='CPU 1'!C13 -> Ajudante | D13: ='CPU 1'!D13 -> hh | E13: ='CPU 1'!E13 -> 13.962682 | I13: ='CPU 1'!AG13+'CPU 2'!O13+'CPU 3'!AA13+'CPU 4'!AA13+'CPU 5'!U13 -> 0 | J13: =I13/$I$162 -> #DIV/0!
B14: ='CPU 1'!B14 -> P08 | C14: ='CPU 1'!C14 -> Armador | D14: ='CPU 1'!D14 -> hh | E14: ='CPU 1'!E14 -> 19.767955 | I14: ='CPU 1'!AG14+'CPU 2'!O14+'CPU 3'!AA14+'CPU 4'!AA14+'CPU 5'!U14 -> 0 | J14: =I14/$I$162 -> #DIV/0!
B15: ='CPU 1'!B15 -> P09 | C15: ='CPU 1'!C15 -> Engenheiro | D15: ='CPU 1'!D15 -> hh | E15: ='CPU 1'!E15 -> 112.302 | I15: ='CPU 1'!AG15+'CPU 2'!O15+'CPU 3'!AA15+'CPU 4'!AA15+'CPU 5'!U15 -> 0 | J15: =I15/$I$162 -> #DIV/0!
B16: ='CPU 1'!B16 -> P10 | C16: ='CPU 1'!C16 -> Planejador | D16: ='CPU 1'!D16 -> hh | E16: ='CPU 1'!E16 -> 60.054545 | I16: ='CPU 1'!AG16+'CPU 2'!O16+'CPU 3'!AA16+'CPU 4'!AA16+'CPU 5'!U16 -> 0 | J16: =I16/$I$162 -> #DIV/0!
B17: ='CPU 1'!B17 -> P11 | C17: ='CPU 1'!C17 -> Tópografo | D17: ='CPU 1'!D17 -> hh | E17: ='CPU 1'!E17 -> 38.034545 | I17: ='CPU 1'!AG17+'CPU 2'!O17+'CPU 3'!AA17+'CPU 4'!AA17+'CPU 5'!U17 -> 0 | J17: =I17/$I$162 -> #DIV/0!
B18: ='CPU 1'!B18 -> P12 | C18: ='CPU 1'!C18 -> Auxiliar de Topografia | D18: ='CPU 1'!D18 -> hh | E18: ='CPU 1'!E18 -> 17.015455 | I18: ='CPU 1'!AG18+'CPU 2'!O18+'CPU 3'!AA18+'CPU 4'!AA18+'CPU 5'!U18 -> 0 | J18: =I18/$I$162 -> #DIV/0!
... B22: ='CPU 1'!B22 -> P16 | C22: ='CPU 1'!C22 -> 0 | D22: ='CPU 1'!D22 -> hh | E22: ='CPU 1'!E22 -> 0 | I22: ='CPU 1'!AG22+'CPU 2'!O22+'CPU 3'!AA22+'CPU 4'!AA22+'CPU 5'!U22 -> 0 | J22: =I22/$I$162 -> #DIV/0!
B23: A - Custo Total de Mão de Obra: | G23: =SUM(G7:G22) -> 0 | H23: =SUM(H7:H22) -> 0 | I23: =SUM(I7:I22) -> 0
B24: B – Equipamentos e Ferramentas
B25: Cód. | C25: Discriminação | D25: Unid | E25: P.Unit | G25: Quant | H25: F.utiliz | I25: Custo
B26: ='CPU 1'!B26 -> E01 | C26: ='CPU 1'!C26 -> Alavanca, picareta, enxada, cavador, pá | D26: ='CPU 1'!D26 -> vb | E26: ='CPU 1'!E26 -> 790 | I26: ='CPU 1'!AG26+'CPU 2'!O26+'CPU 3'!AA26+'CPU 4'!AA26+'CPU 5'!U26 -> 0 | J26: =I26/$I$162 -> #DIV/0!
B27: ='CPU 1'!B27 -> E02 | C27: ='CPU 1'!C27 -> Banheiro hidraulico - locação | D27: ='CPU 1'!D27 -> vb/mês | E27: ='CPU 1'!E27 -> 4000 | I27: ='CPU 1'!AG27+'CPU 2'!O27+'CPU 3'!AA27+'CPU 4'!AA27+'CPU 5'!U27 -> 0 | J27: =I27/$I$162 -> #DIV/0!
B28: ='CPU 1'!B28 -> E03 | C28: ='CPU 1'!C28 -> Barreira física metalica | D28: ='CPU 1'!D28 -> pç | E28: ='CPU 1'!E28 -> 350 | I28: ='CPU 1'!AG28+'CPU 2'!O28+'CPU 3'!AA28+'CPU 4'!AA28+'CPU 5'!U28 -> 0 | J28: =I28/$I$162 -> #DIV/0!
B29: ='CPU 1'!B29 -> E04 | C29: ='CPU 1'!C29 -> Bebedouro 4 torneiras 50L | D29: ='CPU 1'!D29 -> unid | E29: ='CPU 1'!E29 -> 3500 | I29: ='CPU 1'!AG29+'CPU 2'!O29+'CPU 3'!AA29+'CPU 4'!AA29+'CPU 5'!U29 -> 0 | J29: =I29/$I$162 -> #DIV/0!
B30: ='CPU 1'!B30 -> E05 | C30: ='CPU 1'!C30 -> Caçamba de entulho 4m³ | D30: ='CPU 1'!D30 -> Vb/mês | E30: ='CPU 1'!E30 -> 800 | I30: ='CPU 1'!AG30+'CPU 2'!O30+'CPU 3'!AA30+'CPU 4'!AA30+'CPU 5'!U30 -> 0 | J30: =I30/$I$162 -> #DIV/0!
B31: ='CPU 1'!B31 -> E06 | C31: ='CPU 1'!C31 -> Cadinho solda exotermica | D31: ='CPU 1'!D31 -> pç | E31: ='CPU 1'!E31 -> 420 | I31: ='CPU 1'!AG31+'CPU 2'!O31+'CPU 3'!AA31+'CPU 4'!AA31+'CPU 5'!U31 -> 0 | J31: =I31/$I$162 -> #DIV/0!
B32: ='CPU 1'!B32 -> E07 | C32: ='CPU 1'!C32 -> Caixa dágua 1000L | D32: ='CPU 1'!D32 -> pç | E32: ='CPU 1'!E32 -> 480 | I32: ='CPU 1'!AG32+'CPU 2'!O32+'CPU 3'!AA32+'CPU 4'!AA32+'CPU 5'!U32 -> 0 | J32: =I32/$I$162 -> #DIV/0!
B33: ='CPU 1'!B33 -> E08 | C33: ='CPU 1'!C33 -> Caixa dágua 500L | D33: ='CPU 1'!D33 -> pç | E33: ='CPU 1'!E33 -> 250 | I33: ='CPU 1'!AG33+'CPU 2'!O33+'CPU 3'!AA33+'CPU 4'!AA33+'CPU 5'!U33 -> 0 | J33: =I33/$I$162 -> #DIV/0!
B34: ='CPU 1'!B34 -> E09 | C34: ='CPU 1'!C34 -> Caminhão munck | D34: ='CPU 1'!D34 -> vb/mês | E34: ='CPU 1'!E34 -> 40000 | I34: ='CPU 1'!AG34+'CPU 2'!O34+'CPU 3'!AA34+'CPU 4'!AA34+'CPU 5'!U34 -> 0 | J34: =I34/$I$162 -> #DIV/0!
B35: ='CPU 1'!B35 -> E10 | C35: ='CPU 1'!C35 -> Carro de mão | D35: ='CPU 1'!D35 -> pç | E35: ='CPU 1'!E35 -> 450 | I35: ='CPU 1'!AG35+'CPU 2'!O35+'CPU 3'!AA35+'CPU 4'!AA35+'CPU 5'!U35 -> 0 | J35: =I35/$I$162 -> #DIV/0!
B36: ='CPU 1'!B36 -> E11 | C36: ='CPU 1'!C36 -> Carro plataforma | D36: ='CPU 1'!D36 -> pç | E36: ='CPU 1'!E36 -> 1200 | I36: ='CPU 1'!AG36+'CPU 2'!O36+'CPU 3'!AA36+'CPU 4'!AA36+'CPU 5'!U36 -> 0 | J36: =I36/$I$162 -> #DIV/0!
B37: ='CPU 1'!B37 -> E12 | C37: ='CPU 1'!C37 -> Coletor de resíduo com pedal - 50L (V,V,A,A) | D37: ='CPU 1'!D37 -> kit | E37: ='CPU 1'!E37 -> 1200 | I37: ='CPU 1'!AG37+'CPU 2'!O37+'CPU 3'!AA37+'CPU 4'!AA37+'CPU 5'!U37 -> 0 | J37: =I37/$I$162 -> #DIV/0!
... B79: ='CPU 1'!B79 -> E54 | C79: ='CPU 1'!C79 -> 0 | D79: ='CPU 1'!D79 -> 0 | E79: ='CPU 1'!E79 -> 0 | I79: ='CPU 1'!AG79+'CPU 2'!O79+'CPU 3'!AA79+'CPU 4'!AA79+'CPU 5'!U79 -> 0 | J79: =I79/$I$162 -> #DIV/0!
B80: B - Custo Total de Equipamentos e Ferramentas: | E80: =SUM(#REF!) -> #REF! | I80: =SUM(I26:I79) -> 0
B81: C – Materiais
B82: Cód. | C82: Discriminação | D82: Unid | E82: P.Unit | G82: Quant | H82: F.utiliz | I82: Custo
B83: ='CPU 1'!B83 -> M01 | C83: ='CPU 1'!C83 -> Aço CA-50, (ferro 8.0) | D83: ='CPU 1'!D83 -> kg | E83: ='CPU 1'!E83 -> 12.5 | I83: ='CPU 1'!AG83+'CPU 2'!O83+'CPU 3'!AA83+'CPU 4'!AA83+'CPU 5'!U83 -> 0 | J83: =I83/$I$162 -> #DIV/0!
B84: ='CPU 1'!B84 -> M02 | C84: ='CPU 1'!C84 -> Agua Mineral | D84: ='CPU 1'!D84 -> litro | E84: ='CPU 1'!E84 -> 1 | I84: ='CPU 1'!AG84+'CPU 2'!O84+'CPU 3'!AA84+'CPU 4'!AA84+'CPU 5'!U84 -> 0 | J84: =I84/$I$162 -> #DIV/0!
B85: ='CPU 1'!B85 -> M03 | C85: ='CPU 1'!C85 -> Arame ovalado zincado | D85: ='CPU 1'!D85 -> m | E85: ='CPU 1'!E85 -> 1 | I85: ='CPU 1'!AG85+'CPU 2'!O85+'CPU 3'!AA85+'CPU 4'!AA85+'CPU 5'!U85 -> 0 | J85: =I85/$I$162 -> #DIV/0!
B86: ='CPU 1'!B86 -> M04 | C86: ='CPU 1'!C86 -> Areia | D86: ='CPU 1'!D86 -> m³ | E86: ='CPU 1'!E86 -> 120 | I86: ='CPU 1'!AG86+'CPU 2'!O86+'CPU 3'!AA86+'CPU 4'!AA86+'CPU 5'!U86 -> 0 | J86: =I86/$I$162 -> #DIV/0!
...

Sheet QQP
C1: PROJETA CONSULTORIA E SERVIÇOS LTDA | E1: PRO-000-24 | H1: =G44 -> 0
C2: PROPOSTA COMERCIAL | E2: CLIENTE: | F2: XXXXXXXXXXXXXX
C3: PLANILHA DE QUANTIDADES E PREÇOS | E3: REV. 0 | F3: DATA: | G3: 45292
B4: OBJETO: | C4: XXXXXXXXXXXXXXXXXXXXXXXXXXXXXXXXXXX
B6: ITEM | C6: DESCRIÇÃO | D6: UNID. | E6: QUANT. | F6: P.UNITARIO | G6: P.TOTAL
A7: CPU 1 | B7: 1 | C7: XXXXXXXXXXXXXXXXXXXX
B8: 1.1 | C8: XXXXXXXXXXXXXXXXXXXXXXXXXXXXXXXXXXXXXXXXXX | D8: xx | E8: 1 | F8: =_xlfn.XLOOKUP(B8,'CPU 1'!$F$1:$CI$1,'CPU 1'!$F$182:$CI$182) -> 0 | G8: =F8*E8 -> 0 | H8: =G8/$G$44 -> #DIV/0!
B9: 1.2 | C9: XXXXXXXXXXXXXXXXXXXXXXXXXXXXXXXXXXXXXXXXXX | D9: xx | E9: 1 | F9: =_xlfn.XLOOKUP(B9,'CPU 1'!$F$1:$CI$1,'CPU 1'!$F$182:$CI$182) -> 0 | G9: =F9*E9 -> 0 | H9: =G9/$G$44 -> #DIV/0!
B10: 1.3 | C10: XXXXXXXXXXXXXXXXXXXXXXXXXXXXXXXXXXXXXXXXXX | D10: xx | E10: 1 | F10: =_xlfn.XLOOKUP(B10,'CPU 1'!$F$1:$CI$1,'CPU 1'!$F$182:$CI$182) -> 0 | G10: =F10*E10 -> 0 | H10: =G10/$G$44 -> #DIV/0!
B11: 1.4 | C11: XXXXXXXXXXXXXXXXXXXXXXXXXXXXXXXXXXXXXXXXXX | D11: xx | E11: 1 | F11: =_xlfn.XLOOKUP(B11,'CPU 1'!$F$1:$CI$1,'CPU 1'!$F$182:$CI$182) -> 0 | G11: =F11*E11 -> 0 | H11: =G11/$G$44 -> #DIV/0!
B12: 1.5 | C12: XXXXXXXXXXXXXXXXXXXXXXXXXXXXXXXXXXXXXXXXXX | D12: xx | E12: 1 | F12: =_xlfn.XLOOKUP(B12,'CPU 1'!$F$1:$CI$1,'CPU 1'!$F$182:$CI$182) -> 0 | G12: =F12*E12 -> 0 | H12: =G12/$G$44 -> #DIV/0!
B13: 1.6 | C13: XXXXXXXXXXXXXXXXXXXXXXXXXXXXXXXXXXXXXXXXXX | D13: xx | E13: 1 | F13: =_xlfn.XLOOKUP(B13,'CPU 1'!$F$1:$CI$1,'CPU 1'!$F$182:$CI$182) -> 0 | G13: =F13*E13 -> 0 | H13: =G13/$G$44 -> #DIV/0!
B14: 1.7 | C14: XXXXXXXXXXXXXXXXXXXXXXXXXXXXXXXXXXXXXXXXXX | D14: xx | E14: 1 | F14: =_xlfn.XLOOKUP(B14,'CPU 1'!$F$1:$CI$1,'CPU 1'!$F$182:$CI$182) -> 0 | G14: =F14*E14 -> 0 | H14: =G14/$G$44 -> #DIV/0!
B15: 1.8 | C15: XXXXXXXXXXXXXXXXXXXXXXXXXXXXXXXXXXXXXXXXXX | D15: xx | E15: 1 | F15: =_xlfn.XLOOKUP(B15,'CPU 1'!$F$1:$CI$1,'CPU 1'!$F$182:$CI$182) -> 0 | G15: =F15*E15 -> 0 | H15: =G15/$G$44 -> #DIV/0!
A16: CPU 2 | B16: 2 | C16: XXXXXXXXXXXXXXXXXXXX
B17: 2.1 | C17: XXXXXXXXXXXXXXXXXXXXXX | H17: =G17/$G$44 -> #DIV/0!
B18: 2.1.1 | C18: XXXXXXXXXXXXXXXXXXXXXXXXXXXXXXXXXXXXXXXXXX | D18: xx | E18: 1 | F18: =_xlfn.XLOOKUP(B18,'CPU 2'!$F$1:$CF$1,'CPU 2'!$F$182:$CF$182) -> 0 | G18: =F18*E18 -> 0 | H18: =G18/$G$44 -> #DIV/0!
B19: 2.1.2 | C19: XXXXXXXXXXXXXXXXXXXXXXXXXXXXXXXXXXXXXXXXXX | D19: xx | E19: 1 | F19: =_xlfn.XLOOKUP(B19,'CPU 2'!$F$1:$CF$1,'CPU 2'!$F$182:$CF$182) -> 0 | G19: =F19*E19 -> 0 | H19: =G19/$G$44 -> #DIV/0!
A20: CPU 3 | B20: 2.2 | C20: XXXXXXXXXXXXXXXXXXXXXX | H20: =G20/$G$44 -> #DIV/0!
B21: 2.2.1 | C21: XXXXXXXXXXXXXXXXXXXXXXXXXXXXXXXXXXXXXXXXXX | D21: xx | E21: 1 | F21: =_xlfn.XLOOKUP(B21,'CPU 3'!$F$1:$CL$1,'CPU 3'!$F$182:$CL$182) -> 0 | G21: =F21*E21 -> 0 | H21: =G21/$G$44 -> #DIV/0!
B22: 2.2.2 | C22: XXXXXXXXXXXXXXXXXXXXXXXXXXXXXXXXXXXXXXXXXX | D22: xx | E22: 1 | F22: =_xlfn.XLOOKUP(B22,'CPU 3'!$F$1:$CL$1,'CPU 3'!$F$182:$CL$182) -> 0 | G22: =F22*E22 -> 0 | H22: =G22/$G$44 -> #DIV/0!
B23: 2.2.3 | C23: XXXXXXXXXXXXXXXXXXXXXXXXXXXXXXXXXXXXXXXXXX | D23: xx | E23: 1 | F23: =_xlfn.XLOOKUP(B23,'CPU 3'!$F$1:$CL$1,'CPU 3'!$F$182:$CL$182) -> 0 | G23: =F23*E23 -> 0 | H23: =G23/$G$44 -> #DIV/0!
B24: 2.2.4 | C24: XXXXXXXXXXXXXXXXXXXXXXXXXXXXXXXXXXXXXXXXXX | D24: xx | E24: 1 | F24: =_xlfn.XLOOKUP(B24,'CPU 3'!$F$1:$CL$1,'CPU 3'!$F$182:$CL$182) -> 0 | G24: =F24*E24 -> 0 | H24: =G24/$G$44 -> #DIV/0!
B25: 2.3 | C25: XXXXXXXXXXXXXXXXXXXXXX | H25: =G25/$G$44 -> #DIV/0!
B26: 2.3.1 | C26: XXXXXXXXXXXXXXXXXXXXXXXXXXXXXXXXXXXXXXXXXX | D26: xx | E26: 1 | F26: =_xlfn.XLOOKUP(B26,'CPU 3'!$F$1:$CL$1,'CPU 3'!$F$182:$CL$182) -> 0 | G26: =F26*E26 -> 0 | H26: =G26/$G$44 -> #DIV/0!
B27: 2.3.2 | C27: XXXXXXXXXXXXXXXXXXXXXXXXXXXXXXXXXXXXXXXXXX | D27: xx | E27: 1 | F27: =_xlfn.XLOOKUP(B27,'CPU 3'!$F$1:$CL$1,'CPU 3'!$F$182:$CL$182) -> 0 | G27: =F27*E27 -> 0 | H27: =G27/$G$44 -> #DIV/0!
A28: CPU 4 | B28: 2.4 | C28: XXXXXXXXXXXXXXXXXXXXXX | H28: =G28/$G$44 -> #DIV/0!
B29: 2.4.1 | C29: XXXXXXXXXXXXXXXXXXXXXXXXXXXXXXXXXXXXXXXXXX | D29: xx | E29: 1 | F29: =_xlfn.XLOOKUP(B29,'CPU 4'!$F$1:$CL$1,'CPU 4'!$F$182:$CL$182) -> 0 | G29: =F29*E29 -> 0 | H29: =G29/$G$44 -> #DIV/0!
B30: 2.4.2 | C30: XXXXXXXXXXXXXXXXXXXXXXXXXXXXXXXXXXXXXXXXXX | D30: xx | E30: 1 | F30: =_xlfn.XLOOKUP(B30,'CPU 4'!$F$1:$CL$1,'CPU 4'!$F$182:$CL$182) -> 0 | G30: =F30*E30 -> 0 | H30: =G30/$G$44 -> #DIV/0!
B31: 2.4.3 | C31: XXXXXXXXXXXXXXXXXXXXXXXXXXXXXXXXXXXXXXXXXX | D31: xx | E31: 1 | F31: =_xlfn.XLOOKUP(B31,'CPU 4'!$F$1:$CL$1,'CPU 4'!$F$182:$CL$182) -> 0 | G31: =F31*E31 -> 0 | H31: =G31/$G$44 -> #DIV/0!
B32: 2.4.4 | C32: XXXXXXXXXXXXXXXXXXXXXXXXXXXXXXXXXXXXXXXXXX | D32: xx | E32: 1 | F32: =_xlfn.XLOOKUP(B32,'CPU 4'!$F$1:$CL$1,'CPU 4'!$F$182:$CL$182) -> 0 | G32: =F32*E32 -> 0 | H32: =G32/$G$44 -> #DIV/0!
B33: 2.5 | C33: XXXXXXXXXXXXXXXXXXXXXX | H33: =G33/$G$44 -> #DIV/0!
B34: 2.5.1 | C34: XXXXXXXXXXXXXXXXXXXXXXXXXXXXXXXXXXXXXXXXXX | D34: xx | E34: 1 | F34: =_xlfn.XLOOKUP(B34,'CPU 4'!$F$1:$CL$1,'CPU 4'!$F$182:$CL$182) -> 0 | G34: =F34*E34 -> 0 | H34: =G34/$G$44 -> #DIV/0!
B35: 2.5.2 | C35: XXXXXXXXXXXXXXXXXXXXXXXXXXXXXXXXXXXXXXXXXX | D35: xx | E35: 1 | F35: =_xlfn.XLOOKUP(B35,'CPU 4'!$F$1:$CL$1,'CPU 4'!$F$182:$CL$182) -> 0 | G35: =F35*E35 -> 0 | H35: =G35/$G$44 -> #DIV/0!
A36: CPU 5 | B36: 2.6 | C36: XXXXXXXXXXXXXXXXXXXXXX | H36: =G36/$G$44 -> #DIV/0!
B37: 2.6.1 | C37: XXXXXXXXXXXXXXXXXXXXXXXXXXXXXXXXXXXXXXXXXX | D37: xx | E37: 1 | F37: =_xlfn.XLOOKUP(B37,'CPU 5'!$F$1:$CC$1,'CPU 5'!$F$182:$CC$182) -> 0 | G37: =F37*E37 -> 0 | H37: =G37/$G$44 -> #DIV/0!
B38: 2.7 | C38: XXXXXXXXXXXXXXXXXXXXXX | H38: =G38/$G$44 -> #DIV/0!
B39: 2.7.1 | C39: XXXXXXXXXXXXXXXXXXXXXXXXXXXXXXXXXXXXXXXXXX | D39: xx | E39: 1 | F39: =_xlfn.XLOOKUP(B39,'CPU 5'!$F$1:$CC$1,'CPU 5'!$F$182:$CC$182) -> 0 | G39: =F39*E39 -> 0 | H39: =G39/$G$44 -> #DIV/0!
B40: 2.8 | C40: XXXXXXXXXXXXXXXXXXXXXX | H40: =G40/$G$44 -> #DIV/0!
B41: 2.8.1 | C41: XXXXXXXXXXXXXXXXXXXXXXXXXXXXXXXXXXXXXXXXXX | D41: xx | E41: 1 | F41: =_xlfn.XLOOKUP(B41,'CPU 5'!$F$1:$CC$1,'CPU 5'!$F$182:$CC$182) -> 0 | G41: =F41*E41 -> 0 | H41: =G41/$G$44 -> #DIV/0!
...

Sheet CPU  1
B1: =QQP!G44 -> 0 | D1: CPU | E1: 1 | F1: =QQP!B8 -> 1.1 | G1: =H182 -> 0 | I1: =QQP!B9 -> 1.2 | J1: =K182 -> 0 | L1: =QQP!B10 -> 1.3 | M1: =N182 -> 0 | O1: =QQP!B11 -> 1.4 | P1: =Q182 -> 0 | R1: =QQP!B12 -> 1.5 | S1: =T182 -> 0 | U1: =QQP!B13 -> 1.6 | V1: =W182 -> 0 | X1: =QQP!B14 -> 1.7 | Y1: =Z182 -> 0 | AA1: =QQP!B15 -> 1.8 | AB1: =AC182 -> 0
B2: Composição de Preços Unitários | F2: =_xlfn.XLOOKUP(F1,QQP!$B$8:$B$43,QQP!$C$8:$C$43) -> XXXXXXXXXXXXXXXXXXXXXXXXXXXXXXXXXXXXXXXXXX | I2: =_xlfn.XLOOKUP(I1,QQP!$B$8:$B$43,QQP!$C$8:$C$43) -> XXXXXXXXXXXXXXXXXXXXXXXXXXXXXXXXXXXXXXXXXX | L2: =_xlfn.XLOOKUP(L1,QQP!$B$8:$B$43,QQP!$C$8:$C$43) -> XXXXXXXXXXXXXXXXXXXXXXXXXXXXXXXXXXXXXXXXXX | O2: =_xlfn.XLOOKUP(O1,QQP!$B$8:$B$43,QQP!$C$8:$C$43) -> XXXXXXXXXXXXXXXXXXXXXXXXXXXXXXXXXXXXXXXXXX | R2: =_xlfn.XLOOKUP(R1,QQP!$B$8:$B$43,QQP!$C$8:$C$43) -> XXXXXXXXXXXXXXXXXXXXXXXXXXXXXXXXXXXXXXXXXX | U2: =_xlfn.XLOOKUP(U1,QQP!$B$8:$B$43,QQP!$C$8:$C$43) -> XXXXXXXXXXXXXXXXXXXXXXXXXXXXXXXXXXXXXXXXXX | X2: =_xlfn.XLOOKUP(X1,QQP!$B$8:$B$43,QQP!$C$8:$C$43) -> XXXXXXXXXXXXXXXXXXXXXXXXXXXXXXXXXXXXXXXXXX | AA2: =_xlfn.XLOOKUP(AA1,QQP!$B$8:$B$43,QQP!$C$8:$C$43) -> XXXXXXXXXXXXXXXXXXXXXXXXXXXXXXXXXXXXXXXXXX | AE2: CHECK
G3: =_xlfn.XLOOKUP(F1,QQP!$B$8:$B$43,QQP!$D$8:$D$43) -> xx | H3: =_xlfn.XLOOKUP(F1,QQP!$B$8:$B$43,QQP!$E$8:$E$43) -> 1 | J3: =_xlfn.XLOOKUP(I1,QQP!$B$8:$B$43,QQP!$D$8:$D$43) -> xx | K3: =_xlfn.XLOOKUP(I1,QQP!$B$8:$B$43,QQP!$E$8:$E$43) -> 1 | M3: =_xlfn.XLOOKUP(L1,QQP!$B$8:$B$43,QQP!$D$8:$D$43) -> xx | N3: =_xlfn.XLOOKUP(L1,QQP!$B$8:$B$43,QQP!$E$8:$E$43) -> 1 | P3: =_xlfn.XLOOKUP(O1,QQP!$B$8:$B$43,QQP!$D$8:$D$43) -> xx | Q3: =_xlfn.XLOOKUP(O1,QQP!$B$8:$B$43,QQP!$E$8:$E$43) -> 1 | S3: =_xlfn.XLOOKUP(R1,QQP!$B$8:$B$43,QQP!$D$8:$D$43) -> xx | T3: =_xlfn.XLOOKUP(R1,QQP!$B$8:$B$43,QQP!$E$8:$E$43) -> 1 | V3: =_xlfn.XLOOKUP(U1,QQP!$B$8:$B$43,QQP!$D$8:$D$43) -> xx | W3: =_xlfn.XLOOKUP(U1,QQP!$B$8:$B$43,QQP!$E$8:$E$43) -> 1 | Y3: =_xlfn.XLOOKUP(X1,QQP!$B$8:$B$43,QQP!$D$8:$D$43) -> xx | Z3: =_xlfn.XLOOKUP(X1,QQP!$B$8:$B$43,QQP!$E$8:$E$43) -> 1 | AB3: =_xlfn.XLOOKUP(AA1,QQP!$B$8:$B$43,QQP!$D$8:$D$43) -> xx | AC3: =_xlfn.XLOOKUP(AA1,QQP!$B$8:$B$43,QQP!$E$8:$E$43) -> 1
B5: A - Mão de Obra + Encargos
B6: Cód. | C6: Discriminação | D6: Unid | E6: P.Unit | F6: Quant | G6: F.utiliz | H6: Custo | I6: Quant | J6: F.utiliz | K6: Custo | L6: Quant | M6: F.utiliz | N6: Custo | O6: Quant | P6: F.utiliz | Q6: Custo | R6: Quant | S6: F.utiliz | T6: Custo | U6: Quant | V6: F.utiliz | W6: Custo | X6: Quant | Y6: F.utiliz | Z6: Custo | AA6: Quant | AB6: F.utiliz | AC6: Custo | AE6: Quant | AF6: F.utiliz | AG6: Custo
B7: =MO!B3 -> P01 | C7: =MO!C3 -> Supervisor | D7: hh | E7: =MO!K3 -> 75.068182 | H7: =G7*F7*$E7 -> 0 | K7: =J7*I7*$E7 -> 0 | N7: =M7*L7*$E7 -> 0 | Q7: =P7*O7*$E7 -> 0 | T7: =S7*R7*$E7 -> 0 | W7: =V7*U7*$E7 -> 0 | Z7: =Y7*X7*$E7 -> 0 | AC7: =AB7*AA7*$E7 -> 0 | AG7: =K7*$K$3+Z7*$Z$3+H7*$H$3+N7*$N$3+Q7*$Q$3+T7*$T$3+W7*$W$3+AC7*$AC$3 -> 0 | AH7: =AG7/$AG$162 -> #DIV/0!
B8: =MO!B4 -> P02 | C8: =MO!C4 -> Encarregado | D8: hh | E8: =MO!K4 -> 40.036364 | H8: =G8*F8*$E8 -> 0 | K8: =J8*I8*$E8 -> 0 | N8: =M8*L8*$E8 -> 0 | Q8: =P8*O8*$E8 -> 0 | T8: =S8*R8*$E8 -> 0 | W8: =V8*U8*$E8 -> 0 | Z8: =Y8*X8*$E8 -> 0 | AC8: =AB8*AA8*$E8 -> 0 | AG8: =K8*$K$3+Z8*$Z$3+H8*$H$3+N8*$N$3+Q8*$Q$3+T8*$T$3+W8*$W$3+AC8*$AC$3 -> 0 | AH8: =AG8/$AG$162 -> #DIV/0!
B9: =MO!B5 -> P03 | C9: =MO!C5 -> Técnico SSMA | D9: hh | E9: =MO!K5 -> 40.036364 | H9: =G9*F9*$E9 -> 0 | K9: =J9*I9*$E9 -> 0 | N9: =M9*L9*$E9 -> 0 | Q9: =P9*O9*$E9 -> 0 | T9: =S9*R9*$E9 -> 0 | W9: =V9*U9*$E9 -> 0 | Z9: =Y9*X9*$E9 -> 0 | AC9: =AB9*AA9*$E9 -> 0 | AG9: =K9*$K$3+Z9*$Z$3+H9*$H$3+N9*$N$3+Q9*$Q$3+T9*$T$3+W9*$W$3+AC9*$AC$3 -> 0 | AH9: =AG9/$AG$162 -> #DIV/0!
B10: =MO!B6 -> P04 | C10: =MO!C6 -> Pedreiro | D10: hh | E10: =MO!K6 -> 19.767955 | H10: =G10*F10*$E10 -> 0 | K10: =J10*I10*$E10 -> 0 | N10: =M10*L10*$E10 -> 0 | Q10: =P10*O10*$E10 -> 0 | T10: =S10*R10*$E10 -> 0 | W10: =V10*U10*$E10 -> 0 | Z10: =Y10*X10*$E10 -> 0 | AC10: =AB10*AA10*$E10 -> 0 | AG10: =K10*$K$3+Z10*$Z$3+H10*$H$3+N10*$N$3+Q10*$Q$3+T10*$T$3+W10*$W$3+AC10*$AC$3 -> 0 | AH10: =AG10/$AG$162 -> #DIV/0!
B11: =MO!B7 -> P05 | C11: =MO!C7 -> Carpinteiro | D11: hh | E11: =MO!K7 -> 19.767955 | H11: =G11*F11*$E11 -> 0 | K11: =J11*I11*$E11 -> 0 | N11: =M11*L11*$E11 -> 0 | Q11: =P11*O11*$E11 -> 0 | T11: =S11*R11*$E11 -> 0 | W11: =V11*U11*$E11 -> 0 | Z11: =Y11*X11*$E11 -> 0 | AC11: =AB11*AA11*$E11 -> 0 | AG11: =K11*$K$3+Z11*$Z$3+H11*$H$3+N11*$N$3+Q11*$Q$3+T11*$T$3+W11*$W$3+AC11*$AC$3 -> 0 | AH11: =AG11/$AG$162 -> #DIV/0!
B12: =MO!B8 -> P06 | C12: =MO!C8 -> Eletricista | D12: hh | E12: =MO!K8 -> 26.023636 | H12: =G12*F12*$E12 -> 0 | K12: =J12*I12*$E12 -> 0 | N12: =M12*L12*$E12 -> 0 | Q12: =P12*O12*$E12 -> 0 | T12: =S12*R12*$E12 -> 0 | W12: =V12*U12*$E12 -> 0 | Z12: =Y12*X12*$E12 -> 0 | AC12: =AB12*AA12*$E12 -> 0 | AG12: =K12*$K$3+Z12*$Z$3+H12*$H$3+N12*$N$3+Q12*$Q$3+T12*$T$3+W12*$W$3+AC12*$AC$3 -> 0 | AH12: =AG12/$AG$162 -> #DIV/0!
B13: =MO!B9 -> P07 | C13: =MO!C9 -> Ajudante | D13: hh | E13: =MO!K9 -> 13.962682 | H13: =G13*F13*$E13 -> 0 | K13: =J13*I13*$E13 -> 0 | N13: =M13*L13*$E13 -> 0 | Q13: =P13*O13*$E13 -> 0 | T13: =S13*R13*$E13 -> 0 | W13: =V13*U13*$E13 -> 0 | Z13: =Y13*X13*$E13 -> 0 | AC13: =AB13*AA13*$E13 -> 0 | AG13: =K13*$K$3+Z13*$Z$3+H13*$H$3+N13*$N$3+Q13*$Q$3+T13*$T$3+W13*$W$3+AC13*$AC$3 -> 0 | AH13: =AG13/$AG$162 -> #DIV/0!
B14: =MO!B10 -> P08 | C14: =MO!C10 -> Armador | D14: hh | E14: =MO!K10 -> 19.767955 | H14: =G14*F14*$E14 -> 0 | K14: =J14*I14*$E14 -> 0 | N14: =M14*L14*$E14 -> 0 | Q14: =P14*O14*$E14 -> 0 | T14: =S14*R14*$E14 -> 0 | W14: =V14*U14*$E14 -> 0 | Z14: =Y14*X14*$E14 -> 0 | AC14: =AB14*AA14*$E14 -> 0 | AG14: =K14*$K$3+Z14*$Z$3+H14*$H$3+N14*$N$3+Q14*$Q$3+T14*$T$3+W14*$W$3+AC14*$AC$3 -> 0 | AH14: =AG14/$AG$162 -> #DIV/0!
B15: =MO!B11 -> P09 | C15: =MO!C11 -> Engenheiro | D15: hh | E15: =MO!K11 -> 112.302 | H15: =G15*F15*$E15 -> 0 | K15: =J15*I15*$E15 -> 0 | N15: =M15*L15*$E15 -> 0 | Q15: =P15*O15*$E15 -> 0 | T15: =S15*R15*$E15 -> 0 | W15: =V15*U15*$E15 -> 0 | Z15: =Y15*X15*$E15 -> 0 | AC15: =AB15*AA15*$E15 -> 0 | AG15: =K15*$K$3+Z15*$Z$3+H15*$H$3+N15*$N$3+Q15*$Q$3+T15*$T$3+W15*$W$3+AC15*$AC$3 -> 0 | AH15: =AG15/$AG$162 -> #DIV/0!
B16: =MO!B12 -> P10 | C16: =MO!C12 -> Planejador | D16: hh | E16: =MO!K12 -> 60.054545 | H16: =G16*F16*$E16 -> 0 | K16: =J16*I16*$E16 -> 0 | N16: =M16*L16*$E16 -> 0 | Q16: =P16*O16*$E16 -> 0 | T16: =S16*R16*$E16 -> 0 | W16: =V16*U16*$E16 -> 0 | Z16: =Y16*X16*$E16 -> 0 | AC16: =AB16*AA16*$E16 -> 0 | AG16: =K16*$K$3+Z16*$Z$3+H16*$H$3+N16*$N$3+Q16*$Q$3+T16*$T$3+W16*$W$3+AC16*$AC$3 -> 0 | AH16: =AG16/$AG$162 -> #DIV/0!
B17: =MO!B13 -> P11 | C17: =MO!C13 -> Tópografo | D17: hh | E17: =MO!K13 -> 38.034545 | H17: =G17*F17*$E17 -> 0 | K17: =J17*I17*$E17 -> 0 | N17: =M17*L17*$E17 -> 0 | Q17: =P17*O17*$E17 -> 0 | T17: =S17*R17*$E17 -> 0 | W17: =V17*U17*$E17 -> 0 | Z17: =Y17*X17*$E17 -> 0 | AC17: =AB17*AA17*$E17 -> 0 | AG17: =K17*$K$3+Z17*$Z$3+H17*$H$3+N17*$N$3+Q17*$Q$3+T17*$T$3+W17*$W$3+AC17*$AC$3 -> 0 | AH17: =AG17/$AG$162 -> #DIV/0!
B18: =MO!B14 -> P12 | C18: =MO!C14 -> Auxiliar de Topografia | D18: hh | E18: =MO!K14 -> 17.015455 | H18: =G18*F18*$E18 -> 0 | K18: =J18*I18*$E18 -> 0 | N18: =M18*L18*$E18 -> 0 | Q18: =P18*O18*$E18 -> 0 | T18: =S18*R18*$E18 -> 0 | W18: =V18*U18*$E18 -> 0 | Z18: =Y18*X18*$E18 -> 0 | AC18: =AB18*AA18*$E18 -> 0 | AG18: =K18*$K$3+Z18*$Z$3+H18*$H$3+N18*$N$3+Q18*$Q$3+T18*$T$3+W18*$W$3+AC18*$AC$3 -> 0 | AH18: =AG18/$AG$162 -> #DIV/0!
... B22: =MO!B18 -> P16 | C22: =MO!C18 -> 0 | D22: hh | E22: =MO!K18 -> 0 | H22: =G22*F22*$E22 -> 0 | K22: =J22*I22*$E22 -> 0 | N22: =M22*L22*$E22 -> 0 | Q22: =P22*O22*$E22 -> 0 | T22: =S22*R22*$E22 -> 0 | W22: =V22*U22*$E22 -> 0 | Z22: =Y22*X22*$E22 -> 0 | AC22: =AB22*AA22*$E22 -> 0 | AG22: =K22*$K$3+Z22*$Z$3+H22*$H$3+N22*$N$3+Q22*$Q$3+T22*$T$3+W22*$W$3+AC22*$AC$3 -> 0 | AH22: =AG22/$AG$162 -> #DIV/0!
B23: A - Custo Total de Mão de Obra: | F23: =SUM(F7:F22) -> 0 | G23: =SUM(G7:G22) -> 0 | H23: =SUM(H7:H22) -> 0 | I23: =SUM(I7:I22) -> 0 | J23: =SUM(J7:J22) -> 0 | K23: =SUM(K7:K22) -> 0 | L23: =SUM(L7:L22) -> 0 | M23: =SUM(M7:M22) -> 0 | ... AC23: =SUM(AC7:AC22) -> 0 | AE23: =SUM(AE7:AE22) -> 0 | AF23: =SUM(AF7:AF22) -> 0 | AG23: =SUM(AG7:AG22) -> 0
B24: B – Equipamentos e Ferramentas
B25: Cód. | C25: Discriminação | D25: Unid | E25: P.Unit | F25: Quant | G25: F.utiliz | H25: Custo | I25: Quant | J25: F.utiliz | K25: Custo | L25: Quant | M25: F.utiliz | N25: Custo | O25: Quant | P25: F.utiliz | Q25: Custo | R25: Quant | S25: F.utiliz | T25: Custo | U25: Quant | V25: F.utiliz | W25: Custo | X25: Quant | Y25: F.utiliz | Z25: Custo | AA25: Quant | AB25: F.utiliz | AC25: Custo | AE25: Quant | AF25: F.utiliz | AG25: Custo
B26: E01 | C26: Alavanca, picareta, enxada, cavador, pá | D26: vb | E26: =250+110+60+120+250 -> 790 | H26: =G26*F26*$E26 -> 0 | K26: =J26*I26*$E26 -> 0 | N26: =M26*L26*$E26 -> 0 | Q26: =P26*O26*$E26 -> 0 | T26: =S26*R26*$E26 -> 0 | W26: =V26*U26*$E26 -> 0 | Z26: =Y26*X26*$E26 -> 0 | AC26: =AB26*AA26*$E26 -> 0 | AG26: =K26*$K$3+Z26*$Z$3+H26*$H$3+N26*$N$3+Q26*$Q$3+T26*$T$3+W26*$W$3+AC26*$AC$3 -> 0 | AH26: =AG26/$AG$162 -> #DIV/0!
B27: E02 | C27: Banheiro hidraulico - locação | D27: vb/mês | E27: 4000 | H27: =G27*F27*$E27 -> 0 | K27: =J27*I27*$E27 -> 0 | N27: =M27*L27*$E27 -> 0 | Q27: =P27*O27*$E27 -> 0 | T27: =S27*R27*$E27 -> 0 | W27: =V27*U27*$E27 -> 0 | Z27: =Y27*X27*$E27 -> 0 | AC27: =AB27*AA27*$E27 -> 0 | AG27: =K27*$K$3+Z27*$Z$3+H27*$H$3+N27*$N$3+Q27*$Q$3+T27*$T$3+W27*$W$3+AC27*$AC$3 -> 0 | AH27: =AG27/$AG$162 -> #DIV/0!
B28: E03 | C28: Barreira física metalica | D28: pç | E28: 350 | H28: =G28*F28*$E28 -> 0 | K28: =J28*I28*$E28 -> 0 | N28: =M28*L28*$E28 -> 0 | Q28: =P28*O28*$E28 -> 0 | T28: =S28*R28*$E28 -> 0 | W28: =V28*U28*$E28 -> 0 | Z28: =Y28*X28*$E28 -> 0 | AC28: =AB28*AA28*$E28 -> 0 | AG28: =K28*$K$3+Z28*$Z$3+H28*$H$3+N28*$N$3+Q28*$Q$3+T28*$T$3+W28*$W$3+AC28*$AC$3 -> 0 | AH28: =AG28/$AG$162 -> #DIV/0!
B29: E04 | C29: Bebedouro 4 torneiras 50L | D29: unid | E29: 3500 | H29: =G29*F29*$E29 -> 0 | K29: =J29*I29*$E29 -> 0 | N29: =M29*L29*$E29 -> 0 | Q29: =P29*O29*$E29 -> 0 | T29: =S29*R29*$E29 -> 0 | W29: =V29*U29*$E29 -> 0 | Z29: =Y29*X29*$E29 -> 0 | AC29: =AB29*AA29*$E29 -> 0 | AG29: =K29*$K$3+Z29*$Z$3+H29*$H$3+N29*$N$3+Q29*$Q$3+T29*$T$3+W29*$W$3+AC29*$AC$3 -> 0 | AH29: =AG29/$AG$162 -> #DIV/0!
B30: E05 | C30: Caçamba de entulho 4m³ | D30: Vb/mês | E30: 800 | H30: =G30*F30*$E30 -> 0 | K30: =J30*I30*$E30 -> 0 | N30: =M30*L30*$E30 -> 0 | Q30: =P30*O30*$E30 -> 0 | T30: =S30*R30*$E30 -> 0 | W30: =V30*U30*$E30 -> 0 | Z30: =Y30*X30*$E30 -> 0 | AC30: =AB30*AA30*$E30 -> 0 | AG30: =K30*$K$3+Z30*$Z$3+H30*$H$3+N30*$N$3+Q30*$Q$3+T30*$T$3+W30*$W$3+AC30*$AC$3 -> 0 | AH30: =AG30/$AG$162 -> #DIV/0!
B31: E06 | C31: Cadinho solda exotermica | D31: pç | E31: 420 | H31: =G31*F31*$E31 -> 0 | K31: =J31*I31*$E31 -> 0 | N31: =M31*L31*$E31 -> 0 | Q31: =P31*O31*$E31 -> 0 | T31: =S31*R31*$E31 -> 0 | W31: =V31*U31*$E31 -> 0 | Z31: =Y31*X31*$E31 -> 0 | AC31: =AB31*AA31*$E31 -> 0 | AG31: =K31*$K$3+Z31*$Z$3+H31*$H$3+N31*$N$3+Q31*$Q$3+T31*$T$3+W31*$W$3+AC31*$AC$3 -> 0 | AH31: =AG31/$AG$162 -> #DIV/0!
B32: E07 | C32: Caixa dágua 1000L | D32: pç | E32: 480 | H32: =G32*F32*$E32 -> 0 | K32: =J32*I32*$E32 -> 0 | N32: =M32*L32*$E32 -> 0 | Q32: =P32*O32*$E32 -> 0 | T32: =S32*R32*$E32 -> 0 | W32: =V32*U32*$E32 -> 0 | Z32: =Y32*X32*$E32 -> 0 | AC32: =AB32*AA32*$E32 -> 0 | AG32: =K32*$K$3+Z32*$Z$3+H32*$H$3+N32*$N$3+Q32*$Q$3+T32*$T$3+W32*$W$3+AC32*$AC$3 -> 0 | AH32: =AG32/$AG$162 -> #DIV/0!
B33: E08 | C33: Caixa dágua 500L | D33: pç | E33: 250 | H33: =G33*F33*$E33 -> 0 | K33: =J33*I33*$E33 -> 0 | N33: =M33*L33*$E33 -> 0 | Q33: =P33*O33*$E33 -> 0 | T33: =S33*R33*$E33 -> 0 | W33: =V33*U33*$E33 -> 0 | Z33: =Y33*X33*$E33 -> 0 | AC33: =AB33*AA33*$E33 -> 0 | AG33: =K33*$K$3+Z33*$Z$3+H33*$H$3+N33*$N$3+Q33*$Q$3+T33*$T$3+W33*$W$3+AC33*$AC$3 -> 0 | AH33: =AG33/$AG$162 -> #DIV/0!
B34: E09 | C34: Caminhão munck | D34: vb/mês | E34: 40000 | H34: =G34*F34*$E34 -> 0 | K34: =J34*I34*$E34 -> 0 | N34: =M34*L34*$E34 -> 0 | Q34: =P34*O34*$E34 -> 0 | T34: =S34*R34*$E34 -> 0 | W34: =V34*U34*$E34 -> 0 | Z34: =Y34*X34*$E34 -> 0 | AC34: =AB34*AA34*$E34 -> 0 | AG34: =K34*$K$3+Z34*$Z$3+H34*$H$3+N34*$N$3+Q34*$Q$3+T34*$T$3+W34*$W$3+AC34*$AC$3 -> 0 | AH34: =AG34/$AG$162 -> #DIV/0!
B35: E10 | C35: Carro de mão | D35: pç | E35: 450 | H35: =G35*F35*$E35 -> 0 | K35: =J35*I35*$E35 -> 0 | N35: =M35*L35*$E35 -> 0 | Q35: =P35*O35*$E35 -> 0 | T35: =S35*R35*$E35 -> 0 | W35: =V35*U35*$E35 -> 0 | Z35: =Y35*X35*$E35 -> 0 | AC35: =AB35*AA35*$E35 -> 0 | AG35: =K35*$K$3+Z35*$Z$3+H35*$H$3+N35*$N$3+Q35*$Q$3+T35*$T$3+W35*$W$3+AC35*$AC$3 -> 0 | AH35: =AG35/$AG$162 -> #DIV/0!
B36: E11 | C36: Carro plataforma | D36: pç | E36: 1200 | H36: =G36*F36*$E36 -> 0 | K36: =J36*I36*$E36 -> 0 | N36: =M36*L36*$E36 -> 0 | Q36: =P36*O36*$E36 -> 0 | T36: =S36*R36*$E36 -> 0 | W36: =V36*U36*$E36 -> 0 | Z36: =Y36*X36*$E36 -> 0 | AC36: =AB36*AA36*$E36 -> 0 | AG36: =K36*$K$3+Z36*$Z$3+H36*$H$3+N36*$N$3+Q36*$Q$3+T36*$T$3+W36*$W$3+AC36*$AC$3 -> 0 | AH36: =AG36/$AG$162 -> #DIV/0!
B37: E12 | C37: Coletor de resíduo com pedal - 50L (V,V,A,A) | D37: kit | E37: 1200 | H37: =G37*F37*$E37 -> 0 | K37: =J37*I37*$E37 -> 0 | N37: =M37*L37*$E37 -> 0 | Q37: =P37*O37*$E37 -> 0 | T37: =S37*R37*$E37 -> 0 | W37: =V37*U37*$E37 -> 0 | Z37: =Y37*X37*$E37 -> 0 | AC37: =AB37*AA37*$E37 -> 0 | AG37: =K37*$K$3+Z37*$Z$3+H37*$H$3+N37*$N$3+Q37*$Q$3+T37*$T$3+W37*$W$3+AC37*$AC$3 -> 0 | AH37: =AG37/$AG$162 -> #DIV/0!
B38: E13 | C38: Compactador de solo manual | D38: vb | E38: 180 | H38: =G38*F38*$E38 -> 0 | K38: =J38*I38*$E38 -> 0 | N38: =M38*L38*$E38 -> 0 | Q38: =P38*O38*$E38 -> 0 | T38: =S38*R38*$E38 -> 0 | W38: =V38*U38*$E38 -> 0 | Z38: =Y38*X38*$E38 -> 0 | AC38: =AB38*AA38*$E38 -> 0 | AG38: =K38*$K$3+Z38*$Z$3+H38*$H$3+N38*$N$3+Q38*$Q$3+T38*$T$3+W38*$W$3+AC38*$AC$3 -> 0 | AH38: =AG38/$AG$162 -> #DIV/0!
... B41: E16 | C41: Container escritorio | D41: vb/mês | E41: 900 | H41: =G41*F41*$E41 -> 0 | K41: =J41*I41*$E41 -> 0 | N41: =M41*L41*$E41 -> 0 | Q41: =P41*O41*$E41 -> 0 | T41: =S41*R41*$E41 -> 0 | W41: =V41*U41*$E41 -> 0 | Z41: =Y41*X41*$E41 -> 0 | AC41: =AB41*AA41*$E41 -> 0 | AG41: =K41*$K$3+Z41*$Z$3+H41*$H$3+N41*$N$3+Q41*$Q$3+T41*$T$3+W41*$W$3+AC41*$AC$3 -> 0 | AH41: =AG41/$AG$162 -> #DIV/0!
B42: E17 | C42: EPIs | D42: vb/mês | E42: =EPIs!F22 -> 328.76667 | H42: =G42*F42*$E42 -> 0 | K42: =J42*I42*$E42 -> 0 | N42: =M42*L42*$E42 -> 0 | Q42: =P42*O42*$E42 -> 0 | T42: =S42*R42*$E42 -> 0 | W42: =V42*U42*$E42 -> 0 | Z42: =Y42*X42*$E42 -> 0 | AC42: =AB42*AA42*$E42 -> 0 | AG42: =K42*$K$3+Z42*$Z$3+H42*$H$3+N42*$N$3+Q42*$Q$3+T42*$T$3+W42*$W$3+AC42*$AC$3 -> 0 | AH42: =AG42/$AG$162 -> #DIV/0!
B43: E18 | C43: Esmerilhadeira 4-1/2" | D43: und | E43: 2000 | H43: =G43*F43*$E43 -> 0 | K43: =J43*I43*$E43 -> 0 | N43: =M43*L43*$E43 -> 0 | Q43: =P43*O43*$E43 -> 0 | T43: =S43*R43*$E43 -> 0 | W43: =V43*U43*$E43 -> 0 | Z43: =Y43*X43*$E43 -> 0 | AC43: =AB43*AA43*$E43 -> 0 | AG43: =K43*$K$3+Z43*$Z$3+H43*$H$3+N43*$N$3+Q43*$Q$3+T43*$T$3+W43*$W$3+AC43*$AC$3 -> 0 | AH43: =AG43/$AG$162 -> #DIV/0!
B44: E19 | C44: Estação total (com acessorios) | D44: vb/mês | E44: 1350 | H44: =G44*F44*$E44 -> 0 | K44: =J44*I44*$E44 -> 0 | N44: =M44*L44*$E44 -> 0 | Q44: =P44*O44*$E44 -> 0 | T44: =S44*R44*$E44 -> 0 | W44: =V44*U44*$E44 -> 0 | Z44: =Y44*X44*$E44 -> 0 | AC44: =AB44*AA44*$E44 -> 0 | AG44: =K44*$K$3+Z44*$Z$3+H44*$H$3+N44*$N$3+Q44*$Q$3+T44*$T$3+W44*$W$3+AC44*$AC$3 -> 0 | AH44: =AG44/$AG$162 -> #DIV/0!
B45: E20 | C45: Extensões eletricas (plug steck + DJ + DR) 40m | D45: vb | E45: =(40*12.5)+327.8+150+50+60 -> 1087.8 | H45: =G45*F45*$E45 -> 0 | K45: =J45*I45*$E45 -> 0 | N45: =M45*L45*$E45 -> 0 | Q45: =P45*O45*$E45 -> 0 | T45: =S45*R45*$E45 -> 0 | W45: =V45*U45*$E45 -> 0 | Z45: =Y45*X45*$E45 -> 0 | AC45: =AB45*AA45*$E45 -> 0 | AG45: =K45*$K$3+Z45*$Z$3+H45*$H$3+N45*$N$3+Q45*$Q$3+T45*$T$3+W45*$W$3+AC45*$AC$3 -> 0 | AH45: =AG45/$AG$162 -> #DIV/0!
B46: E21 | C46: Ferramentas gerais para obra | D46: vb | E46: 5000 | H46: =G46*F46*$E46 -> 0 | K46: =J46*I46*$E46 -> 0 | N46: =M46*L46*$E46 -> 0 | Q46: =P46*O46*$E46 -> 0 | T46: =S46*R46*$E46 -> 0 | W46: =V46*U46*$E46 -> 0 | Z46: =Y46*X46*$E46 -> 0 | AC46: =AB46*AA46*$E46 -> 0 | AG46: =K46*$K$3+Z46*$Z$3+H46*$H$3+N46*$N$3+Q46*$Q$3+T46*$T$3+W46*$W$3+AC46*$AC$3 -> 0 | AH46: =AG46/$AG$162 -> #DIV/0!
...

Sheet CPU  2
B1: =QQP!G44 -> 0 | D1: CPU | E1: 2 | F1: =QQP!B18 -> 2.1.1 | G1: =H182 -> 0 | I1: =QQP!B19 -> 2.1.2 | J1: =K182 -> 0
B2: Composição de Preços Unitários | F2: =_xlfn.XLOOKUP(F1,QQP!$B$8:$B$43,QQP!$C$8:$C$43) -> XXXXXXXXXXXXXXXXXXXXXXXXXXXXXXXXXXXXXXXXXX | I2: =_xlfn.XLOOKUP(I1,QQP!$B$8:$B$43,QQP!$C$8:$C$43) -> XXXXXXXXXXXXXXXXXXXXXXXXXXXXXXXXXXXXXXXXXX | M2: CHECK
G3: =_xlfn.XLOOKUP(F1,QQP!$B$8:$B$43,QQP!$D$8:$D$43) -> xx | H3: =_xlfn.XLOOKUP(F1,QQP!$B$8:$B$43,QQP!$E$8:$E$43) -> 1 | J3: =_xlfn.XLOOKUP(I1,QQP!$B$8:$B$43,QQP!$D$8:$D$43) -> xx | K3: =_xlfn.XLOOKUP(I1,QQP!$B$8:$B$43,QQP!$E$8:$E$43) -> 1
G4: 22 | H4: dias | J4: =22*3 -> 66 | K4: dias
B5: A - Mão de Obra + Encargos
B6: Cód. | C6: Discriminação | D6: Unid | E6: P.Unit | F6: Quant | G6: F.utiliz | H6: Custo | I6: Quant | J6: F.utiliz | K6: Custo | M6: Quant | N6: F.utiliz | O6: Custo
B7: ='CPU 1'!B7 -> P01 | C7: ='CPU 1'!C7 -> Supervisor | D7: ='CPU 1'!D7 -> hh | E7: ='CPU 1'!E7 -> 75.068182 | H7: =G7*F7*$E7 -> 0 | K7: =J7*I7*$E7 -> 0 | O7: =K7*$K$3+H7*$H$3 -> 0 | P7: =O7/$O$162 -> #DIV/0!
B8: ='CPU 1'!B8 -> P02 | C8: ='CPU 1'!C8 -> Encarregado | D8: ='CPU 1'!D8 -> hh | E8: ='CPU 1'!E8 -> 40.036364 | H8: =G8*F8*$E8 -> 0 | K8: =J8*I8*$E8 -> 0 | O8: =K8*$K$3+H8*$H$3 -> 0 | P8: =O8/$O$162 -> #DIV/0!
B9: ='CPU 1'!B9 -> P03 | C9: ='CPU 1'!C9 -> Técnico SSMA | D9: ='CPU 1'!D9 -> hh | E9: ='CPU 1'!E9 -> 40.036364 | H9: =G9*F9*$E9 -> 0 | K9: =J9*I9*$E9 -> 0 | O9: =K9*$K$3+H9*$H$3 -> 0 | P9: =O9/$O$162 -> #DIV/0!
B10: ='CPU 1'!B10 -> P04 | C10: ='CPU 1'!C10 -> Pedreiro | D10: ='CPU 1'!D10 -> hh | E10: ='CPU 1'!E10 -> 19.767955 | H10: =G10*F10*$E10 -> 0 | K10: =J10*I10*$E10 -> 0 | O10: =K10*$K$3+H10*$H$3 -> 0 | P10: =O10/$O$162 -> #DIV/0!
B11: ='CPU 1'!B11 -> P05 | C11: ='CPU 1'!C11 -> Carpinteiro | D11: ='CPU 1'!D11 -> hh | E11: ='CPU 1'!E11 -> 19.767955 | H11: =G11*F11*$E11 -> 0 | K11: =J11*I11*$E11 -> 0 | O11: =K11*$K$3+H11*$H$3 -> 0 | P11: =O11/$O$162 -> #DIV/0!
B12: ='CPU 1'!B12 -> P06 | C12: ='CPU 1'!C12 -> Eletricista | D12: ='CPU 1'!D12 -> hh | E12: ='CPU 1'!E12 -> 26.023636 | H12: =G12*F12*$E12 -> 0 | K12: =J12*I12*$E12 -> 0 | O12: =K12*$K$3+H12*$H$3 -> 0 | P12: =O12/$O$162 -> #DIV/0!
B13: ='CPU 1'!B13 -> P07 | C13: ='CPU 1'!C13 -> Ajudante | D13: ='CPU 1'!D13 -> hh | E13: ='CPU 1'!E13 -> 13.962682 | H13: =G13*F13*$E13 -> 0 | K13: =J13*I13*$E13 -> 0 | O13: =K13*$K$3+H13*$H$3 -> 0 | P13: =O13/$O$162 -> #DIV/0!
B14: ='CPU 1'!B14 -> P08 | C14: ='CPU 1'!C14 -> Armador | D14: ='CPU 1'!D14 -> hh | E14: ='CPU 1'!E14 -> 19.767955 | H14: =G14*F14*$E14 -> 0 | K14: =J14*I14*$E14 -> 0 | O14: =K14*$K$3+H14*$H$3 -> 0 | P14: =O14/$O$162 -> #DIV/0!
B15: ='CPU 1'!B15 -> P09 | C15: ='CPU 1'!C15 -> Engenheiro | D15: ='CPU 1'!D15 -> hh | E15: ='CPU 1'!E15 -> 112.302 | H15: =G15*F15*$E15 -> 0 | K15: =J15*I15*$E15 -> 0 | O15: =K15*$K$3+H15*$H$3 -> 0 | P15: =O15/$O$162 -> #DIV/0!
B16: ='CPU 1'!B16 -> P10 | C16: ='CPU 1'!C16 -> Planejador | D16: ='CPU 1'!D16 -> hh | E16: ='CPU 1'!E16 -> 60.054545 | H16: =G16*F16*$E16 -> 0 | K16: =J16*I16*$E16 -> 0 | O16: =K16*$K$3+H16*$H$3 -> 0 | P16: =O16/$O$162 -> #DIV/0!
B17: ='CPU 1'!B17 -> P11 | C17: ='CPU 1'!C17 -> Tópografo | D17: ='CPU 1'!D17 -> hh | E17: ='CPU 1'!E17 -> 38.034545 | H17: =G17*F17*$E17 -> 0 | K17: =J17*I17*$E17 -> 0 | O17: =K17*$K$3+H17*$H$3 -> 0 | P17: =O17/$O$162 -> #DIV/0!
B18: ='CPU 1'!B18 -> P12 | C18: ='CPU 1'!C18 -> Auxiliar de Topografia | D18: ='CPU 1'!D18 -> hh | E18: ='CPU 1'!E18 -> 17.015455 | H18: =G18*F18*$E18 -> 0 | K18: =J18*I18*$E18 -> 0 | O18: =K18*$K$3+H18*$H$3 -> 0 | P18: =O18/$O$162 -> #DIV/0!
... B22: ='CPU 1'!B22 -> P16 | C22: ='CPU 1'!C22 -> 0 | D22: ='CPU 1'!D22 -> hh | E22: ='CPU 1'!E22 -> 0 | H22: =G22*F22*$E22 -> 0 | K22: =J22*I22*$E22 -> 0 | O22: =K22*$K$3+H22*$H$3 -> 0 | P22: =O22/$O$162 -> #DIV/0!
B23: A - Custo Total de Mão de Obra: | F23: =SUM(F7:F22) -> 0 | G23: =SUM(G7:G22) -> 0 | H23: =SUM(H7:H22) -> 0 | I23: =SUM(I7:I22) -> 0 | J23: =SUM(J7:J22) -> 0 | K23: =SUM(K7:K22) -> 0 | M23: =SUM(M7:M22) -> 0 | N23: =SUM(N7:N22) -> 0 | O23: =SUM(O7:O22) -> 0
B24: B – Equipamentos e Ferramentas
B25: Cód. | C25: Discriminação | D25: Unid | E25: P.Unit | F25: Quant | G25: F.utiliz | H25: Custo | I25: Quant | J25: F.utiliz | K25: Custo | M25: Quant | N25: F.utiliz | O25: Custo
B26: ='CPU 1'!B26 -> E01 | C26: ='CPU 1'!C26 -> Alavanca, picareta, enxada, cavador, pá | D26: ='CPU 1'!D26 -> vb | E26: ='CPU 1'!E26 -> 790 | H26: =G26*F26*$E26 -> 0 | K26: =J26*I26*$E26 -> 0 | O26: =K26*$K$3+H26*$H$3 -> 0 | P26: =O26/$O$162 -> #DIV/0!
B27: ='CPU 1'!B27 -> E02 | C27: ='CPU 1'!C27 -> Banheiro hidraulico - locação | D27: ='CPU 1'!D27 -> vb/mês | E27: ='CPU 1'!E27 -> 4000 | H27: =G27*F27*$E27 -> 0 | K27: =J27*I27*$E27 -> 0 | O27: =K27*$K$3+H27*$H$3 -> 0 | P27: =O27/$O$162 -> #DIV/0!
B28: ='CPU 1'!B28 -> E03 | C28: ='CPU 1'!C28 -> Barreira física metalica | D28: ='CPU 1'!D28 -> pç | E28: ='CPU 1'!E28 -> 350 | H28: =G28*F28*$E28 -> 0 | K28: =J28*I28*$E28 -> 0 | O28: =K28*$K$3+H28*$H$3 -> 0 | P28: =O28/$O$162 -> #DIV/0!
B29: ='CPU 1'!B29 -> E04 | C29: ='CPU 1'!C29 -> Bebedouro 4 torneiras 50L | D29: ='CPU 1'!D29 -> unid | E29: ='CPU 1'!E29 -> 3500 | H29: =G29*F29*$E29 -> 0 | K29: =J29*I29*$E29 -> 0 | O29: =K29*$K$3+H29*$H$3 -> 0 | P29: =O29/$O$162 -> #DIV/0!
B30: ='CPU 1'!B30 -> E05 | C30: ='CPU 1'!C30 -> Caçamba de entulho 4m³ | D30: ='CPU 1'!D30 -> Vb/mês | E30: ='CPU 1'!E30 -> 800 | H30: =G30*F30*$E30 -> 0 | K30: =J30*I30*$E30 -> 0 | O30: =K30*$K$3+H30*$H$3 -> 0 | P30: =O30/$O$162 -> #DIV/0!
B31: ='CPU 1'!B31 -> E06 | C31: ='CPU 1'!C31 -> Cadinho solda exotermica | D31: ='CPU 1'!D31 -> pç | E31: ='CPU 1'!E31 -> 420 | H31: =G31*F31*$E31 -> 0 | K31: =J31*I31*$E31 -> 0 | O31: =K31*$K$3+H31*$H$3 -> 0 | P31: =O31/$O$162 -> #DIV/0!
B32: ='CPU 1'!B32 -> E07 | C32: ='CPU 1'!C32 -> Caixa dágua 1000L | D32: ='CPU 1'!D32 -> pç | E32: ='CPU 1'!E32 -> 480 | H32: =G32*F32*$E32 -> 0 | K32: =J32*I32*$E32 -> 0 | O32: =K32*$K$3+H32*$H$3 -> 0 | P32: =O32/$O$162 -> #DIV/0!
B33: ='CPU 1'!B33 -> E08 | C33: ='CPU 1'!C33 -> Caixa dágua 500L | D33: ='CPU 1'!D33 -> pç | E33: ='CPU 1'!E33 -> 250 | H33: =G33*F33*$E33 -> 0 | K33: =J33*I33*$E33 -> 0 | O33: =K33*$K$3+H33*$H$3 -> 0 | P33: =O33/$O$162 -> #DIV/0!
B34: ='CPU 1'!B34 -> E09 | C34: ='CPU 1'!C34 -> Caminhão munck | D34: ='CPU 1'!D34 -> vb/mês | E34: ='CPU 1'!E34 -> 40000 | H34: =G34*F34*$E34 -> 0 | K34: =J34*I34*$E34 -> 0 | O34: =K34*$K$3+H34*$H$3 -> 0 | P34: =O34/$O$162 -> #DIV/0!
B35: ='CPU 1'!B35 -> E10 | C35: ='CPU 1'!C35 -> Carro de mão | D35: ='CPU 1'!D35 -> pç | E35: ='CPU 1'!E35 -> 450 | H35: =G35*F35*$E35 -> 0 | K35: =J35*I35*$E35 -> 0 | O35: =K35*$K$3+H35*$H$3 -> 0 | P35: =O35/$O$162 -> #DIV/0!
B36: ='CPU 1'!B36 -> E11 | C36: ='CPU 1'!C36 -> Carro plataforma | D36: ='CPU 1'!D36 -> pç | E36: ='CPU 1'!E36 -> 1200 | H36: =G36*F36*$E36 -> 0 | K36: =J36*I36*$E36 -> 0 | O36: =K36*$K$3+H36*$H$3 -> 0 | P36: =O36/$O$162 -> #DIV/0!
B37: ='CPU 1'!B37 -> E12 | C37: ='CPU 1'!C37 -> Coletor de resíduo com pedal - 50L (V,V,A,A) | D37: ='CPU 1'!D37 -> kit | E37: ='CPU 1'!E37 -> 1200 | H37: =G37*F37*$E37 -> 0 | K37: =J37*I37*$E37 -> 0 | O37: =K37*$K$3+H37*$H$3 -> 0 | P37: =O37/$O$162 -> #DIV/0!
... B79: ='CPU 1'!B79 -> E54 | C79: ='CPU 1'!C79 -> 0 | D79: ='CPU 1'!D79 -> 0 | E79: ='CPU 1'!E79 -> 0 | H79: =G79*F79*$E79 -> 0 | K79: =J79*I79*$E79 -> 0 | O79: =K79*$K$3+H79*$H$3 -> 0 | P79: =O79/$O$162 -> #DIV/0!
B80: B - Custo Total de Equipamentos e Ferramentas: | E80: =SUM(#REF!) -> #REF! | H80: =SUM(H26:H79) -> 0 | K80: =SUM(K26:K79) -> 0 | O80: =SUM(O26:O79) -> 0
B81: C – Materiais
B82: Cód. | C82: Discriminação | D82: Unid | E82: P.Unit | F82: Quant | G82: F.utiliz | H82: Custo | I82: Quant | J82: F.utiliz | K82: Custo | M82: Quant | N82: F.utiliz | O82: Custo
B83: ='CPU 1'!B83 -> M01 | C83: ='CPU 1'!C83 -> Aço CA-50, (ferro 8.0) | D83: ='CPU 1'!D83 -> kg | E83: ='CPU 1'!E83 -> 12.5 | H83: =G83*F83*$E83 -> 0 | K83: =J83*I83*$E83 -> 0 | O83: =K83*$K$3+H83*$H$3 -> 0 | P83: =O83/$O$162 -> #DIV/0!
B84: ='CPU 1'!B84 -> M02 | C84: ='CPU 1'!C84 -> Agua Mineral | D84: ='CPU 1'!D84 -> litro | E84: ='CPU 1'!E84 -> 1 | H84: =G84*F84*$E84 -> 0 | K84: =J84*I84*$E84 -> 0 | O84: =K84*$K$3+H84*$H$3 -> 0 | P84: =O84/$O$162 -> #DIV/0!
...

Sheet CPU  3
B1: =QQP!G44 -> 0 | D1: CPU | E1: 3 | F1: =QQP!B21 -> 2.2.1 | G1: =H182 -> 0 | I1: =QQP!B22 -> 2.2.2 | J1: =K182 -> 0 | L1: =QQP!B23 -> 2.2.3 | M1: =N182 -> 0 | O1: =QQP!B24 -> 2.2.4 | P1: =Q182 -> 0 | R1: =QQP!B26 -> 2.3.1 | S1: =T182 -> 0 | U1: =QQP!B27 -> 2.3.2 | V1: =W182 -> 0
B2: Composição de Preços Unitários | F2: =_xlfn.XLOOKUP(F1,QQP!$B$8:$B$43,QQP!$C$8:$C$43) -> XXXXXXXXXXXXXXXXXXXXXXXXXXXXXXXXXXXXXXXXXX | I2: =_xlfn.XLOOKUP(I1,QQP!$B$8:$B$43,QQP!$C$8:$C$43) -> XXXXXXXXXXXXXXXXXXXXXXXXXXXXXXXXXXXXXXXXXX | L2: =_xlfn.XLOOKUP(L1,QQP!$B$8:$B$43,QQP!$C$8:$C$43) -> XXXXXXXXXXXXXXXXXXXXXXXXXXXXXXXXXXXXXXXXXX | O2: =_xlfn.XLOOKUP(O1,QQP!$B$8:$B$43,QQP!$C$8:$C$43) -> XXXXXXXXXXXXXXXXXXXXXXXXXXXXXXXXXXXXXXXXXX | R2: =_xlfn.XLOOKUP(R1,QQP!$B$8:$B$43,QQP!$C$8:$C$43) -> XXXXXXXXXXXXXXXXXXXXXXXXXXXXXXXXXXXXXXXXXX | U2: =_xlfn.XLOOKUP(U1,QQP!$B$8:$B$43,QQP!$C$8:$C$43) -> XXXXXXXXXXXXXXXXXXXXXXXXXXXXXXXXXXXXXXXXXX | Y2: CHECK
G3: =_xlfn.XLOOKUP(F1,QQP!$B$8:$B$43,QQP!$D$8:$D$43) -> xx | H3: =_xlfn.XLOOKUP(F1,QQP!$B$8:$B$43,QQP!$E$8:$E$43) -> 1 | J3: =_xlfn.XLOOKUP(I1,QQP!$B$8:$B$43,QQP!$D$8:$D$43) -> xx | K3: =_xlfn.XLOOKUP(I1,QQP!$B$8:$B$43,QQP!$E$8:$E$43) -> 1 | M3: =_xlfn.XLOOKUP(L1,QQP!$B$8:$B$43,QQP!$D$8:$D$43) -> xx | N3: =_xlfn.XLOOKUP(L1,QQP!$B$8:$B$43,QQP!$E$8:$E$43) -> 1 | P3: =_xlfn.XLOOKUP(O1,QQP!$B$8:$B$43,QQP!$D$8:$D$43) -> xx | Q3: =_xlfn.XLOOKUP(O1,QQP!$B$8:$B$43,QQP!$E$8:$E$43) -> 1 | S3: =_xlfn.XLOOKUP(R1,QQP!$B$8:$B$43,QQP!$D$8:$D$43) -> xx | T3: =_xlfn.XLOOKUP(R1,QQP!$B$8:$B$43,QQP!$E$8:$E$43) -> 1 | V3: =_xlfn.XLOOKUP(U1,QQP!$B$8:$B$43,QQP!$D$8:$D$43) -> xx | W3: =_xlfn.XLOOKUP(U1,QQP!$B$8:$B$43,QQP!$E$8:$E$43) -> 1
B5: A - Mão de Obra + Encargos
B6: Cód. | C6: Discriminação | D6: Unid | E6: P.Unit | F6: Quant | G6: F.utiliz | H6: Custo | I6: Quant | J6: F.utiliz | K6: Custo | L6: Quant | M6: F.utiliz | N6: Custo | O6: Quant | P6: F.utiliz | Q6: Custo | R6: Quant | S6: F.utiliz | T6: Custo | U6: Quant | V6: F.utiliz | W6: Custo | Y6: Quant | Z6: F.utiliz | AA6: Custo
B7: ='CPU 1'!B7 -> P01 | C7: ='CPU 1'!C7 -> Supervisor | D7: ='CPU 1'!D7 -> hh | E7: ='CPU 1'!E7 -> 75.068182 | H7: =G7*F7*$E7 -> 0 | K7: =J7*I7*$E7 -> 0 | N7: =M7*L7*$E7 -> 0 | Q7: =P7*O7*$E7 -> 0 | T7: =S7*R7*$E7 -> 0 | W7: =V7*U7*$E7 -> 0 | AA7: =K7*$K$3+N7*$N$3+Q7*$Q$3+H7*$H$3+T7*$T$3+W7*$W$3 -> 0 | AB7: =AA7/$AA$162 -> #DIV/0!
B8: ='CPU 1'!B8 -> P02 | C8: ='CPU 1'!C8 -> Encarregado | D8: ='CPU 1'!D8 -> hh | E8: ='CPU 1'!E8 -> 40.036364 | H8: =G8*F8*$E8 -> 0 | K8: =J8*I8*$E8 -> 0 | N8: =M8*L8*$E8 -> 0 | Q8: =P8*O8*$E8 -> 0 | T8: =S8*R8*$E8 -> 0 | W8: =V8*U8*$E8 -> 0 | AA8: =K8*$K$3+N8*$N$3+Q8*$Q$3+H8*$H$3+T8*$T$3+W8*$W$3 -> 0 | AB8: =AA8/$AA$162 -> #DIV/0!
B9: ='CPU 1'!B9 -> P03 | C9: ='CPU 1'!C9 -> Técnico SSMA | D9: ='CPU 1'!D9 -> hh | E9: ='CPU 1'!E9 -> 40.036364 | H9: =G9*F9*$E9 -> 0 | K9: =J9*I9*$E9 -> 0 | N9: =M9*L9*$E9 -> 0 | Q9: =P9*O9*$E9 -> 0 | T9: =S9*R9*$E9 -> 0 | W9: =V9*U9*$E9 -> 0 | AA9: =K9*$K$3+N9*$N$3+Q9*$Q$3+H9*$H$3+T9*$T$3+W9*$W$3 -> 0 | AB9: =AA9/$AA$162 -> #DIV/0!
B10: ='CPU 1'!B10 -> P04 | C10: ='CPU 1'!C10 -> Pedreiro | D10: ='CPU 1'!D10 -> hh | E10: ='CPU 1'!E10 -> 19.767955 | H10: =G10*F10*$E10 -> 0 | K10: =J10*I10*$E10 -> 0 | N10: =M10*L10*$E10 -> 0 | Q10: =P10*O10*$E10 -> 0 | T10: =S10*R10*$E10 -> 0 | W10: =V10*U10*$E10 -> 0 | AA10: =K10*$K$3+N10*$N$3+Q10*$Q$3+H10*$H$3+T10*$T$3+W10*$W$3 -> 0 | AB10: =AA10/$AA$162 -> #DIV/0!
B11: ='CPU 1'!B11 -> P05 | C11: ='CPU 1'!C11 -> Carpinteiro | D11: ='CPU 1'!D11 -> hh | E11: ='CPU 1'!E11 -> 19.767955 | H11: =G11*F11*$E11 -> 0 | K11: =J11*I11*$E11 -> 0 | N11: =M11*L11*$E11 -> 0 | Q11: =P11*O11*$E11 -> 0 | T11: =S11*R11*$E11 -> 0 | W11: =V11*U11*$E11 -> 0 | AA11: =K11*$K$3+N11*$N$3+Q11*$Q$3+H11*$H$3+T11*$T$3+W11*$W$3 -> 0 | AB11: =AA11/$AA$162 -> #DIV/0!
B12: ='CPU 1'!B12 -> P06 | C12: ='CPU 1'!C12 -> Eletricista | D12: ='CPU 1'!D12 -> hh | E12: ='CPU 1'!E12 -> 26.023636 | H12: =G12*F12*$E12 -> 0 | K12: =J12*I12*$E12 -> 0 | N12: =M12*L12*$E12 -> 0 | Q12: =P12*O12*$E12 -> 0 | T12: =S12*R12*$E12 -> 0 | W12: =V12*U12*$E12 -> 0 | AA12: =K12*$K$3+N12*$N$3+Q12*$Q$3+H12*$H$3+T12*$T$3+W12*$W$3 -> 0 | AB12: =AA12/$AA$162 -> #DIV/0!
B13: ='CPU 1'!B13 -> P07 | C13: ='CPU 1'!C13 -> Ajudante | D13: ='CPU 1'!D13 -> hh | E13: ='CPU 1'!E13 -> 13.962682 | H13: =G13*F13*$E13 -> 0 | K13: =J13*I13*$E13 -> 0 | N13: =M13*L13*$E13 -> 0 | Q13: =P13*O13*$E13 -> 0 | T13: =S13*R13*$E13 -> 0 | W13: =V13*U13*$E13 -> 0 | AA13: =K13*$K$3+N13*$N$3+Q13*$Q$3+H13*$H$3+T13*$T$3+W13*$W$3 -> 0 | AB13: =AA13/$AA$162 -> #DIV/0!
B14: ='CPU 1'!B14 -> P08 | C14: ='CPU 1'!C14 -> Armador | D14: ='CPU 1'!D14 -> hh | E14: ='CPU 1'!E14 -> 19.767955 | H14: =G14*F14*$E14 -> 0 | K14: =J14*I14*$E14 -> 0 | N14: =M14*L14*$E14 -> 0 | Q14: =P14*O14*$E14 -> 0 | T14: =S14*R14*$E14 -> 0 | W14: =V14*U14*$E14 -> 0 | AA14: =K14*$K$3+N14*$N$3+Q14*$Q$3+H14*$H$3+T14*$T$3+W14*$W$3 -> 0 | AB14: =AA14/$AA$162 -> #DIV/0!
B15: ='CPU 1'!B15 -> P09 | C15: ='CPU 1'!C15 -> Engenheiro | D15: ='CPU 1'!D15 -> hh | E15: ='CPU 1'!E15 -> 112.302 | H15: =G15*F15*$E15 -> 0 | K15: =J15*I15*$E15 -> 0 | N15: =M15*L15*$E15 -> 0 | Q15: =P15*O15*$E15 -> 0 | T15: =S15*R15*$E15 -> 0 | W15: =V15*U15*$E15 -> 0 | AA15: =K15*$K$3+N15*$N$3+Q15*$Q$3+H15*$H$3+T15*$T$3+W15*$W$3 -> 0 | AB15: =AA15/$AA$162 -> #DIV/0!
B16: ='CPU 1'!B16 -> P10 | C16: ='CPU 1'!C16 -> Planejador | D16: ='CPU 1'!D16 -> hh | E16: ='CPU 1'!E16 -> 60.054545 | H16: =G16*F16*$E16 -> 0 | K16: =J16*I16*$E16 -> 0 | N16: =M16*L16*$E16 -> 0 | Q16: =P16*O16*$E16 -> 0 | T16: =S16*R16*$E16 -> 0 | W16: =V16*U16*$E16 -> 0 | AA16: =K16*$K$3+N16*$N$3+Q16*$Q$3+H16*$H$3+T16*$T$3+W16*$W$3 -> 0 | AB16: =AA16/$AA$162 -> #DIV/0!
B17: ='CPU 1'!B17 -> P11 | C17: ='CPU 1'!C17 -> Tópografo | D17: ='CPU 1'!D17 -> hh | E17: ='CPU 1'!E17 -> 38.034545 | H17: =G17*F17*$E17 -> 0 | K17: =J17*I17*$E17 -> 0 | N17: =M17*L17*$E17 -> 0 | Q17: =P17*O17*$E17 -> 0 | T17: =S17*R17*$E17 -> 0 | W17: =V17*U17*$E17 -> 0 | AA17: =K17*$K$3+N17*$N$3+Q17*$Q$3+H17*$H$3+T17*$T$3+W17*$W$3 -> 0 | AB17: =AA17/$AA$162 -> #DIV/0!
B18: ='CPU 1'!B18 -> P12 | C18: ='CPU 1'!C18 -> Auxiliar de Topografia | D18: ='CPU 1'!D18 -> hh | E18: ='CPU 1'!E18 -> 17.015455 | H18: =G18*F18*$E18 -> 0 | K18: =J18*I18*$E18 -> 0 | N18: =M18*L18*$E18 -> 0 | Q18: =P18*O18*$E18 -> 0 | T18: =S18*R18*$E18 -> 0 | W18: =V18*U18*$E18 -> 0 | AA18: =K18*$K$3+N18*$N$3+Q18*$Q$3+H18*$H$3+T18*$T$3+W18*$W$3 -> 0 | AB18: =AA18/$AA$162 -> #DIV/0!
... B22: ='CPU 1'!B22 -> P16 | C22: ='CPU 1'!C22 -> 0 | D22: ='CPU 1'!D22 -> hh | E22: ='CPU 1'!E22 -> 0 | H22: =G22*F22*$E22 -> 0 | K22: =J22*I22*$E22 -> 0 | N22: =M22*L22*$E22 -> 0 | Q22: =P22*O22*$E22 -> 0 | T22: =S22*R22*$E22 -> 0 | W22: =V22*U22*$E22 -> 0 | AA22: =K22*$K$3+N22*$N$3+Q22*$Q$3+H22*$H$3+T22*$T$3+W22*$W$3 -> 0 | AB22: =AA22/$AA$162 -> #DIV/0!
B23: A - Custo Total de Mão de Obra: | F23: =SUM(F7:F22) -> 0 | G23: =SUM(G7:G22)*H3 -> 0 | H23: =SUM(H7:H22) -> 0 | I23: =SUM(I7:I22) -> 0 | J23: =SUM(J7:J22)*K3 -> 0 | K23: =SUM(K7:K22) -> 0 | L23: =SUM(L7:L22) -> 0 | M23: =SUM(M7:M22)*N3 -> 0 | N23: =SUM(N7:N22) -> 0 | O23: =SUM(O7:O22) -> 0 | P23: =SUM(P7:P22)*Q3 -> 0 | Q23: =SUM(Q7:Q22) -> 0 | R23: =SUM(R7:R22) -> 0 | S23: =SUM(S7:S22)*T3 -> 0 | T23: =SUM(T7:T22) -> 0 | U23: =SUM(U7:U22) -> 0 | V23: =SUM(V7:V22)*W3 -> 0 | W23: =SUM(W7:W22) -> 0 | Y23: =SUM(Y7:Y22) -> 0 | Z23: =SUM(Z7:Z22) -> 0 | AA23: =SUM(AA7:AA22) -> 0
B24: B – Equipamentos e Ferramentas
B25: Cód. | C25: Discriminação | D25: Unid | E25: P.Unit | F25: Quant | G25: F.utiliz | H25: Custo | I25: Quant | J25: F.utiliz | K25: Custo | L25: Quant | M25: F.utiliz | N25: Custo | O25: Quant | P25: F.utiliz | Q25: Custo | R25: Quant | S25: F.utiliz | T25: Custo | U25: Quant | V25: F.utiliz | W25: Custo | Y25: Quant | Z25: F.utiliz | AA25: Custo
B26: ='CPU 1'!B26 -> E01 | C26: ='CPU 1'!C26 -> Alavanca, picareta, enxada, cavador, pá | D26: ='CPU 1'!D26 -> vb | E26: ='CPU 1'!E26 -> 790 | H26: =G26*F26*$E26 -> 0 | K26: =J26*I26*$E26 -> 0 | N26: =M26*L26*$E26 -> 0 | Q26: =P26*O26*$E26 -> 0 | T26: =S26*R26*$E26 -> 0 | W26: =V26*U26*$E26 -> 0 | AA26: =K26*$K$3+N26*$N$3+Q26*$Q$3+H26*$H$3+T26*$T$3+W26*$W$3 -> 0 | AB26: =AA26/$AA$162 -> #DIV/0!
B27: ='CPU 1'!B27 -> E02 | C27: ='CPU 1'!C27 -> Banheiro hidraulico - locação | D27: ='CPU 1'!D27 -> vb/mês | E27: ='CPU 1'!E27 -> 4000 | H27: =G27*F27*$E27 -> 0 | K27: =J27*I27*$E27 -> 0 | N27: =M27*L27*$E27 -> 0 | Q27: =P27*O27*$E27 -> 0 | T27: =S27*R27*$E27 -> 0 | W27: =V27*U27*$E27 -> 0 | AA27: =K27*$K$3+N27*$N$3+Q27*$Q$3+H27*$H$3+T27*$T$3+W27*$W$3 -> 0 | AB27: =AA27/$AA$162 -> #DIV/0!
B28: ='CPU 1'!B28 -> E03 | C28: ='CPU 1'!C28 -> Barreira física metalica | D28: ='CPU 1'!D28 -> pç | E28: ='CPU 1'!E28 -> 350 | H28: =G28*F28*$E28 -> 0 | K28: =J28*I28*$E28 -> 0 | N28: =M28*L28*$E28 -> 0 | Q28: =P28*O28*$E28 -> 0 | T28: =S28*R28*$E28 -> 0 | W28: =V28*U28*$E28 -> 0 | AA28: =K28*$K$3+N28*$N$3+Q28*$Q$3+H28*$H$3+T28*$T$3+W28*$W$3 -> 0 | AB28: =AA28/$AA$162 -> #DIV/0!
B29: ='CPU 1'!B29 -> E04 | C29: ='CPU 1'!C29 -> Bebedouro 4 torneiras 50L | D29: ='CPU 1'!D29 -> unid | E29: ='CPU 1'!E29 -> 3500 | H29: =G29*F29*$E29 -> 0 | K29: =J29*I29*$E29 -> 0 | N29: =M29*L29*$E29 -> 0 | Q29: =P29*O29*$E29 -> 0 | T29: =S29*R29*$E29 -> 0 | W29: =V29*U29*$E29 -> 0 | AA29: =K29*$K$3+N29*$N$3+Q29*$Q$3+H29*$H$3+T29*$T$3+W29*$W$3 -> 0 | AB29: =AA29/$AA$162 -> #DIV/0!
B30: ='CPU 1'!B30 -> E05 | C30: ='CPU 1'!C30 -> Caçamba de entulho 4m³ | D30: ='CPU 1'!D30 -> Vb/mês | E30: ='CPU 1'!E30 -> 800 | H30: =G30*F30*$E30 -> 0 | K30: =J30*I30*$E30 -> 0 | N30: =M30*L30*$E30 -> 0 | Q30: =P30*O30*$E30 -> 0 | T30: =S30*R30*$E30 -> 0 | W30: =V30*U30*$E30 -> 0 | AA30: =K30*$K$3+N30*$N$3+Q30*$Q$3+H30*$H$3+T30*$T$3+W30*$W$3 -> 0 | AB30: =AA30/$AA$162 -> #DIV/0!
B31: ='CPU 1'!B31 -> E06 | C31: ='CPU 1'!C31 -> Cadinho solda exotermica | D31: ='CPU 1'!D31 -> pç | E31: ='CPU 1'!E31 -> 420 | H31: =G31*F31*$E31 -> 0 | K31: =J31*I31*$E31 -> 0 | N31: =M31*L31*$E31 -> 0 | Q31: =P31*O31*$E31 -> 0 | T31: =S31*R31*$E31 -> 0 | W31: =V31*U31*$E31 -> 0 | AA31: =K31*$K$3+N31*$N$3+Q31*$Q$3+H31*$H$3+T31*$T$3+W31*$W$3 -> 0 | AB31: =AA31/$AA$162 -> #DIV/0!
B32: ='CPU 1'!B32 -> E07 | C32: ='CPU 1'!C32 -> Caixa dágua 1000L | D32: ='CPU 1'!D32 -> pç | E32: ='CPU 1'!E32 -> 480 | H32: =G32*F32*$E32 -> 0 | K32: =J32*I32*$E32 -> 0 | N32: =M32*L32*$E32 -> 0 | Q32: =P32*O32*$E32 -> 0 | T32: =S32*R32*$E32 -> 0 | W32: =V32*U32*$E32 -> 0 | AA32: =K32*$K$3+N32*$N$3+Q32*$Q$3+H32*$H$3+T32*$T$3+W32*$W$3 -> 0 | AB32: =AA32/$AA$162 -> #DIV/0!
